{
  "version": 8,
  "blockIdVersion": 11,
  "anchorX": 0,
  "anchorY": 0,
  "anchorZ": 0,
  "blocks": [
    {
      "x": -2,
      "y": 1,
      "z": -8,
      "name": "Plant_Leaves_Banyan",
      "support": 15
    },
    {
      "x": -2,
      "y": 1,
      "z": -7,
      "name": "Plant_Leaves_Banyan",
      "support": 15
    },
    {
      "x": -2,
      "y": 2,
      "z": -6,
      "name": "Plant_Leaves_Banyan",
      "support": 15
    },
    {
      "x": -1,
      "y": 1,
      "z": -9,
      "name": "Plant_Leaves_Banyan",
      "support": 15
    },
    {
      "x": -1,
      "y": 1,
      "z": -8,
      "name": "Plant_Leaves_Banyan",
      "support": 15
    },
    {
      "x": -1,
      "y": 0,
      "z": -7,
      "name": "Plant_Leaves_Banyan",
      "support": 15
    },
    {
      "x": -1,
      "y": 1,
      "z": -7,
      "name": "Wood_Jungle_Branch_Long",
      "support": 15,
      "rotation": 5
    },
    {
      "x": -1,
      "y": 2,
      "z": -7,
      "name": "Plant_Leaves_Banyan",
      "support": 15
    },
    {
      "x": -1,
      "y": 1,
      "z": -6,
      "name": "Plant_Leaves_Banyan",
      "support": 15
    },
    {
      "x": -1,
      "y": 2,
      "z": -6,
      "name": "Wood_Jungle_Branch_Long",
      "support": 15,
      "rotation": 5
    },
    {
      "x": -1,
      "y": 3,
      "z": -6,
      "name": "Plant_Leaves_Banyan",
      "support": 15
    },
    {
      "x": -1,
      "y": 0,
      "z": -5,
      "name": "Plant_Leaves_Banyan",
      "support": 15
    },
    {
      "x": -1,
      "y": 1,
      "z": -5,
      "name": "Plant_Leaves_Banyan",
      "support": 15
    },
    {
      "x": -1,
      "y": 2,
      "z": -5,
      "name": "Plant_Fruit_Mango"
    },
    {
      "x": 0,
      "y": 2,
      "z": -10,
      "name": "Plant_Leaves_Banyan",
      "support": 15
    },
    {
      "x": 0,
      "y": 3,
      "z": -10,
      "name": "Plant_Leaves_Banyan",
      "support": 15
    },
    {
      "x": 0,
      "y": 1,
      "z": -9,
      "name": "Plant_Leaves_Banyan",
      "support": 15
    },
    {
      "x": 0,
      "y": 2,
      "z": -9,
      "name": "Plant_Leaves_Banyan",
      "support": 15
    },
    {
      "x": 0,
      "y": 3,
      "z": -9,
      "name": "Plant_Leaves_Banyan",
      "support": 15
    },
    {
      "x": 0,
      "y": 0,
      "z": -8,
      "name": "Plant_Leaves_Banyan",
      "support": 15
    },
    {
      "x": 0,
      "y": 1,
      "z": -8,
      "name": "Plant_Leaves_Banyan",
      "support": 15
    },
    {
      "x": 0,
      "y": 2,
      "z": -8,
      "name": "Plant_Leaves_Banyan",
      "support": 15
    },
    {
      "x": 0,
      "y": 3,
      "z": -8,
      "name": "Plant_Leaves_Banyan",
      "support": 15
    },
    {
      "x": 0,
      "y": 0,
      "z": -7,
      "name": "Plant_Leaves_Banyan",
      "support": 15
    },
    {
      "x": 0,
      "y": 1,
      "z": -7,
      "name": "Wood_Jungle_Trunk_Full",
      "support": 15,
      "rotation": 4
    },
    {
      "x": 0,
      "y": 2,
      "z": -7,
      "name": "Plant_Leaves_Banyan",
      "support": 15
    },
    {
      "x": 0,
      "y": 3,
      "z": -7,
      "name": "Plant_Leaves_Banyan",
      "support": 15
    },
    {
      "x": 0,
      "y": 4,
      "z": -7,
      "name": "Plant_Leaves_Banyan",
      "support": 15
    },
    {
      "x": 0,
      "y": -1,
      "z": -6,
      "name": "Plant_Leaves_Banyan",
      "support": 15
    },
    {
      "x": 0,
      "y": 0,
      "z": -6,
      "name": "Plant_Leaves_Banyan",
      "support": 15
    },
    {
      "x": 0,
      "y": 1,
      "z": -6,
      "name": "Wood_Jungle_Trunk_Full",
      "support": 15,
      "rotation": 4
    },
    {
      "x": 0,
      "y": 2,
      "z": -6,
      "name": "Wood_Jungle_Branch_Corner",
      "support": 15,
      "rotation": 11
    },
    {
      "x": 0,
      "y": 0,
      "z": -5,
      "name": "Plant_Leaves_Banyan",
      "support": 15
    },
    {
      "x": 0,
      "y": 1,
      "z": -5,
      "name": "Wood_Jungle_Trunk_Full",
      "support": 15,
      "rotation": 4
    },
    {
      "x": 0,
      "y": 2,
      "z": -5,
      "name": "Plant_Leaves_Banyan",
      "support": 15
    },
    {
      "x": 0,
      "y": 3,
      "z": -5,
      "name": "Plant_Leaves_Banyan",
      "support": 15
    },
    {
      "x": 0,
      "y": -1,
      "z": -4,
      "name": "Plant_Leaves_Banyan",
      "support": 15
    },
    {
      "x": 0,
      "y": 0,
      "z": -4,
      "name": "Wood_Jungle_Trunk_Full",
      "support": 15,
      "rotation": 4
    },
    {
      "x": 0,
      "y": 1,
      "z": -4,
      "name": "Wood_Jungle_Trunk_Full",
      "support": 15,
      "rotation": 4
    },
    {
      "x": 0,
      "y": 0,
      "z": -3,
      "name": "Wood_Jungle_Trunk_Full",
      "support": 15,
      "rotation": 4
    },
    {
      "x": 0,
      "y": 0,
      "z": -2,
      "name": "Wood_Jungle_Trunk_Full",
      "support": 15,
      "rotation": 4
    },
    {
      "x": 0,
      "y": 0,
      "z": -1,
      "name": "Wood_Jungle_Trunk_Full",
      "support": 15,
      "rotation": 4
    },
    {
      "x": 0,
      "y": 0,
      "z": 0,
      "name": "Wood_Jungle_Trunk_Full",
      "support": 15,
      "rotation": 4
    },
    {
      "x": 1,
      "y": 2,
      "z": -9,
      "name": "Plant_Leaves_Banyan",
      "support": 15
    },
    {
      "x": 1,
      "y": 1,
      "z": -8,
      "name": "Plant_Leaves_Banyan",
      "support": 15
    },
    {
      "x": 1,
      "y": 2,
      "z": -8,
      "name": "Plant_Leaves_Banyan",
      "support": 15
    },
    {
      "x": 1,
      "y": 0,
      "z": -7,
      "name": "Plant_Leaves_Banyan",
      "support": 15
    },
    {
      "x": 1,
      "y": 1,
      "z": -7,
      "name": "Plant_Leaves_Banyan",
      "support": 15
    },
    {
      "x": 1,
      "y": 3,
      "z": -7,
      "name": "Plant_Leaves_Banyan",
      "support": 15
    },
    {
      "x": 1,
      "y": 4,
      "z": -7,
      "name": "Plant_Leaves_Banyan",
      "support": 15
    },
    {
      "x": 1,
      "y": 0,
      "z": -6,
      "name": "Plant_Leaves_Banyan",
      "support": 15
    },
    {
      "x": 1,
      "y": 1,
      "z": -6,
      "name": "Wood_Jungle_Branch_Long",
      "support": 15,
      "rotation": 5
    },
    {
      "x": 1,
      "y": 2,
      "z": -6,
      "name": "Plant_Leaves_Banyan",
      "support": 15
    },
    {
      "x": 1,
      "y": 3,
      "z": -6,
      "name": "Plant_Fruit_Mango"
    },
    {
      "x": 1,
      "y": 0,
      "z": -5,
      "name": "Plant_Leaves_Banyan",
      "support": 15
    },
    {
      "x": 1,
      "y": 1,
      "z": -5,
      "name": "Plant_Leaves_Banyan",
      "support": 15
    },
    {
      "x": 1,
      "y": 2,
      "z": -5,
      "name": "Plant_Leaves_Banyan",
      "support": 15
    },
    {
      "x": 2,
      "y": 1,
      "z": -7,
      "name": "Plant_Leaves_Banyan",
      "support": 15
    },
    {
      "x": 2,
      "y": 2,
      "z": -7,
      "name": "Plant_Leaves_Banyan",
      "support": 15
    },
    {
      "x": 2,
      "y": 1,
      "z": -6,
      "name": "Wood_Jungle_Branch_Long",
      "support": 15,
      "rotation": 5
    },
    {
      "x": 2,
      "y": 2,
      "z": -6,
      "name": "Plant_Leaves_Banyan",
      "support": 15
    },
    {
      "x": 2,
      "y": 1,
      "z": -5,
      "name": "Plant_Leaves_Banyan",
      "support": 15
    },
    {
      "x": 3,
      "y": 1,
      "z": -6,
      "name": "Plant_Leaves_Banyan",
      "support": 15
    }
  ]
}