{
  "version": 8,
  "blockIdVersion": 11,
  "anchorX": 3,
  "anchorY": 1,
  "anchorZ": -4,
  "blocks": [
    {
      "x": 0,
      "y": 1,
      "z": -3,
      "name": "Rock_Stone"
    },
    {
      "x": 0,
      "y": 2,
      "z": -3,
      "name": "Rock_Stone"
    },
    {
      "x": 0,
      "y": 1,
      "z": -2,
      "name": "Rock_Stone"
    },
    {
      "x": 0,
      "y": 2,
      "z": -2,
      "name": "Rock_Stone"
    },
    {
      "x": 0,
      "y": 3,
      "z": -2,
      "name": "Rock_Stone"
    },
    {
      "x": 0,
      "y": 1,
      "z": -1,
      "name": "Rock_Stone"
    },
    {
      "x": 0,
      "y": 2,
      "z": -1,
      "name": "Rock_Stone"
    },
    {
      "x": 0,
      "y": 3,
      "z": -1,
      "name": "Rock_Stone"
    },
    {
      "x": 0,
      "y": 4,
      "z": -1,
      "name": "Rock_Stone"
    },
    {
      "x": 0,
      "y": 5,
      "z": -1,
      "name": "Rock_Stone"
    },
    {
      "x": 0,
      "y": 1,
      "z": 0,
      "name": "Rock_Stone"
    },
    {
      "x": 0,
      "y": 2,
      "z": 0,
      "name": "Rock_Stone"
    },
    {
      "x": 0,
      "y": 3,
      "z": 0,
      "name": "Rock_Stone"
    },
    {
      "x": 0,
      "y": 4,
      "z": 0,
      "name": "Rock_Stone"
    },
    {
      "x": 0,
      "y": 5,
      "z": 0,
      "name": "Rock_Stone"
    },
    {
      "x": 0,
      "y": 1,
      "z": 1,
      "name": "Rock_Stone"
    },
    {
      "x": 0,
      "y": 2,
      "z": 1,
      "name": "Rock_Stone"
    },
    {
      "x": 0,
      "y": 3,
      "z": 1,
      "name": "Rock_Stone"
    },
    {
      "x": 0,
      "y": 1,
      "z": 2,
      "name": "Rock_Stone"
    },
    {
      "x": 1,
      "y": 1,
      "z": -4,
      "name": "Rock_Stone"
    },
    {
      "x": 1,
      "y": 1,
      "z": -3,
      "name": "Rock_Stone"
    },
    {
      "x": 1,
      "y": 2,
      "z": -3,
      "name": "Rock_Stone"
    },
    {
      "x": 1,
      "y": 3,
      "z": -3,
      "name": "Rock_Stone"
    },
    {
      "x": 1,
      "y": 1,
      "z": -2,
      "name": "Rock_Stone"
    },
    {
      "x": 1,
      "y": 2,
      "z": -2,
      "name": "Rock_Stone"
    },
    {
      "x": 1,
      "y": 3,
      "z": -2,
      "name": "Rock_Stone"
    },
    {
      "x": 1,
      "y": 4,
      "z": -2,
      "name": "Rock_Stone"
    },
    {
      "x": 1,
      "y": 5,
      "z": -2,
      "name": "Rock_Stone"
    },
    {
      "x": 1,
      "y": 1,
      "z": -1,
      "name": "Rock_Stone"
    },
    {
      "x": 1,
      "y": 2,
      "z": -1,
      "name": "Rock_Stone"
    },
    {
      "x": 1,
      "y": 3,
      "z": -1,
      "name": "Rock_Stone"
    },
    {
      "x": 1,
      "y": 4,
      "z": -1,
      "name": "Rock_Stone"
    },
    {
      "x": 1,
      "y": 5,
      "z": -1,
      "name": "Rock_Stone"
    },
    {
      "x": 1,
      "y": 6,
      "z": -1,
      "name": "Rock_Stone"
    },
    {
      "x": 1,
      "y": 7,
      "z": -1,
      "name": "Soil_Grass"
    },
    {
      "x": 1,
      "y": 8,
      "z": -1,
      "name": "Plant_Moss_Rug_Green_Dark",
      "support": 15
    },
    {
      "x": 1,
      "y": 1,
      "z": 0,
      "name": "Rock_Stone"
    },
    {
      "x": 1,
      "y": 2,
      "z": 0,
      "name": "Rock_Stone"
    },
    {
      "x": 1,
      "y": 3,
      "z": 0,
      "name": "Rock_Stone"
    },
    {
      "x": 1,
      "y": 4,
      "z": 0,
      "name": "Rock_Stone"
    },
    {
      "x": 1,
      "y": 5,
      "z": 0,
      "name": "Rock_Stone"
    },
    {
      "x": 1,
      "y": 6,
      "z": 0,
      "name": "Rock_Stone"
    },
    {
      "x": 1,
      "y": 1,
      "z": 1,
      "name": "Rock_Stone"
    },
    {
      "x": 1,
      "y": 2,
      "z": 1,
      "name": "Rock_Stone"
    },
    {
      "x": 1,
      "y": 3,
      "z": 1,
      "name": "Rock_Stone"
    },
    {
      "x": 1,
      "y": 4,
      "z": 1,
      "name": "Rock_Stone"
    },
    {
      "x": 1,
      "y": 1,
      "z": 2,
      "name": "Rock_Stone"
    },
    {
      "x": 1,
      "y": 2,
      "z": 2,
      "name": "Rock_Stone"
    },
    {
      "x": 1,
      "y": 3,
      "z": 2,
      "name": "Rock_Stone"
    },
    {
      "x": 1,
      "y": 1,
      "z": 3,
      "name": "Rock_Stone"
    },
    {
      "x": 2,
      "y": 1,
      "z": -4,
      "name": "Rock_Stone"
    },
    {
      "x": 2,
      "y": 2,
      "z": -4,
      "name": "Rock_Stone"
    },
    {
      "x": 2,
      "y": 3,
      "z": -4,
      "name": "Rock_Stone"
    },
    {
      "x": 2,
      "y": 4,
      "z": -4,
      "name": "Rock_Stone"
    },
    {
      "x": 2,
      "y": 1,
      "z": -3,
      "name": "Rock_Stone"
    },
    {
      "x": 2,
      "y": 2,
      "z": -3,
      "name": "Rock_Stone"
    },
    {
      "x": 2,
      "y": 3,
      "z": -3,
      "name": "Rock_Stone"
    },
    {
      "x": 2,
      "y": 4,
      "z": -3,
      "name": "Rock_Stone"
    },
    {
      "x": 2,
      "y": 5,
      "z": -3,
      "name": "Rock_Stone"
    },
    {
      "x": 2,
      "y": 1,
      "z": -2,
      "name": "Rock_Stone"
    },
    {
      "x": 2,
      "y": 2,
      "z": -2,
      "name": "Rock_Stone"
    },
    {
      "x": 2,
      "y": 3,
      "z": -2,
      "name": "Rock_Stone"
    },
    {
      "x": 2,
      "y": 4,
      "z": -2,
      "name": "Rock_Stone"
    },
    {
      "x": 2,
      "y": 5,
      "z": -2,
      "name": "Rock_Stone"
    },
    {
      "x": 2,
      "y": 6,
      "z": -2,
      "name": "Rock_Stone"
    },
    {
      "x": 2,
      "y": 7,
      "z": -2,
      "name": "Rock_Stone"
    },
    {
      "x": 2,
      "y": 8,
      "z": -2,
      "name": "Soil_Grass"
    },
    {
      "x": 2,
      "y": 9,
      "z": -2,
      "name": "Plant_Moss_Rug_Green_Dark",
      "support": 15
    },
    {
      "x": 2,
      "y": 1,
      "z": -1,
      "name": "Rock_Stone"
    },
    {
      "x": 2,
      "y": 2,
      "z": -1,
      "name": "Rock_Stone"
    },
    {
      "x": 2,
      "y": 3,
      "z": -1,
      "name": "Rock_Stone"
    },
    {
      "x": 2,
      "y": 4,
      "z": -1,
      "name": "Rock_Stone"
    },
    {
      "x": 2,
      "y": 5,
      "z": -1,
      "name": "Rock_Stone"
    },
    {
      "x": 2,
      "y": 6,
      "z": -1,
      "name": "Rock_Stone"
    },
    {
      "x": 2,
      "y": 7,
      "z": -1,
      "name": "Rock_Stone"
    },
    {
      "x": 2,
      "y": 8,
      "z": -1,
      "name": "Soil_Grass"
    },
    {
      "x": 2,
      "y": 9,
      "z": -1,
      "name": "Plant_Moss_Rug_Green_Dark",
      "support": 15
    },
    {
      "x": 2,
      "y": 1,
      "z": 0,
      "name": "Rock_Stone"
    },
    {
      "x": 2,
      "y": 2,
      "z": 0,
      "name": "Rock_Stone"
    },
    {
      "x": 2,
      "y": 3,
      "z": 0,
      "name": "Rock_Stone"
    },
    {
      "x": 2,
      "y": 4,
      "z": 0,
      "name": "Rock_Stone"
    },
    {
      "x": 2,
      "y": 5,
      "z": 0,
      "name": "Rock_Stone"
    },
    {
      "x": 2,
      "y": 6,
      "z": 0,
      "name": "Rock_Stone"
    },
    {
      "x": 2,
      "y": 7,
      "z": 0,
      "name": "Rock_Stone"
    },
    {
      "x": 2,
      "y": 8,
      "z": 0,
      "name": "Rock_Stone"
    },
    {
      "x": 2,
      "y": 9,
      "z": 0,
      "name": "Soil_Grass"
    },
    {
      "x": 2,
      "y": 1,
      "z": 1,
      "name": "Rock_Stone"
    },
    {
      "x": 2,
      "y": 2,
      "z": 1,
      "name": "Rock_Stone"
    },
    {
      "x": 2,
      "y": 3,
      "z": 1,
      "name": "Rock_Stone"
    },
    {
      "x": 2,
      "y": 4,
      "z": 1,
      "name": "Rock_Stone"
    },
    {
      "x": 2,
      "y": 5,
      "z": 1,
      "name": "Rock_Stone"
    },
    {
      "x": 2,
      "y": 6,
      "z": 1,
      "name": "Rock_Stone"
    },
    {
      "x": 2,
      "y": 7,
      "z": 1,
      "name": "Rock_Stone"
    },
    {
      "x": 2,
      "y": 8,
      "z": 1,
      "name": "Rock_Stone"
    },
    {
      "x": 2,
      "y": 9,
      "z": 1,
      "name": "Soil_Grass"
    },
    {
      "x": 2,
      "y": 10,
      "z": 1,
      "name": "Plant_Moss_Rug_Green_Dark",
      "support": 15
    },
    {
      "x": 2,
      "y": 1,
      "z": 2,
      "name": "Rock_Stone"
    },
    {
      "x": 2,
      "y": 2,
      "z": 2,
      "name": "Rock_Stone"
    },
    {
      "x": 2,
      "y": 3,
      "z": 2,
      "name": "Rock_Stone"
    },
    {
      "x": 2,
      "y": 4,
      "z": 2,
      "name": "Rock_Stone"
    },
    {
      "x": 2,
      "y": 5,
      "z": 2,
      "name": "Rock_Stone"
    },
    {
      "x": 2,
      "y": 1,
      "z": 3,
      "name": "Rock_Stone"
    },
    {
      "x": 3,
      "y": 1,
      "z": -4,
      "name": "Rock_Stone"
    },
    {
      "x": 3,
      "y": 2,
      "z": -4,
      "name": "Rock_Stone"
    },
    {
      "x": 3,
      "y": 3,
      "z": -4,
      "name": "Rock_Stone"
    },
    {
      "x": 3,
      "y": 4,
      "z": -4,
      "name": "Rock_Stone"
    },
    {
      "x": 3,
      "y": 5,
      "z": -4,
      "name": "Rock_Stone"
    },
    {
      "x": 3,
      "y": 1,
      "z": -3,
      "name": "Rock_Stone"
    },
    {
      "x": 3,
      "y": 2,
      "z": -3,
      "name": "Rock_Stone"
    },
    {
      "x": 3,
      "y": 3,
      "z": -3,
      "name": "Rock_Stone"
    },
    {
      "x": 3,
      "y": 4,
      "z": -3,
      "name": "Rock_Stone"
    },
    {
      "x": 3,
      "y": 5,
      "z": -3,
      "name": "Rock_Stone"
    },
    {
      "x": 3,
      "y": 6,
      "z": -3,
      "name": "Rock_Stone"
    },
    {
      "x": 3,
      "y": 7,
      "z": -3,
      "name": "Rock_Stone"
    },
    {
      "x": 3,
      "y": 1,
      "z": -2,
      "name": "Rock_Stone"
    },
    {
      "x": 3,
      "y": 2,
      "z": -2,
      "name": "Rock_Stone"
    },
    {
      "x": 3,
      "y": 3,
      "z": -2,
      "name": "Rock_Stone"
    },
    {
      "x": 3,
      "y": 4,
      "z": -2,
      "name": "Rock_Stone"
    },
    {
      "x": 3,
      "y": 5,
      "z": -2,
      "name": "Rock_Stone"
    },
    {
      "x": 3,
      "y": 6,
      "z": -2,
      "name": "Rock_Stone"
    },
    {
      "x": 3,
      "y": 7,
      "z": -2,
      "name": "Rock_Stone"
    },
    {
      "x": 3,
      "y": 8,
      "z": -2,
      "name": "Soil_Grass"
    },
    {
      "x": 3,
      "y": 1,
      "z": -1,
      "name": "Rock_Stone"
    },
    {
      "x": 3,
      "y": 2,
      "z": -1,
      "name": "Rock_Stone"
    },
    {
      "x": 3,
      "y": 3,
      "z": -1,
      "name": "Rock_Stone"
    },
    {
      "x": 3,
      "y": 4,
      "z": -1,
      "name": "Rock_Stone"
    },
    {
      "x": 3,
      "y": 5,
      "z": -1,
      "name": "Rock_Stone"
    },
    {
      "x": 3,
      "y": 6,
      "z": -1,
      "name": "Rock_Stone"
    },
    {
      "x": 3,
      "y": 7,
      "z": -1,
      "name": "Rock_Stone"
    },
    {
      "x": 3,
      "y": 8,
      "z": -1,
      "name": "Soil_Grass"
    },
    {
      "x": 3,
      "y": 9,
      "z": -1,
      "name": "Plant_Crop_Mushroom_Glowing_Blue"
    },
    {
      "x": 3,
      "y": 1,
      "z": 0,
      "name": "Rock_Stone"
    },
    {
      "x": 3,
      "y": 2,
      "z": 0,
      "name": "Rock_Stone"
    },
    {
      "x": 3,
      "y": 3,
      "z": 0,
      "name": "Rock_Stone"
    },
    {
      "x": 3,
      "y": 5,
      "z": 0,
      "name": "Rock_Stone"
    },
    {
      "x": 3,
      "y": 6,
      "z": 0,
      "name": "Rock_Stone"
    },
    {
      "x": 3,
      "y": 7,
      "z": 0,
      "name": "Rock_Stone"
    },
    {
      "x": 3,
      "y": 8,
      "z": 0,
      "name": "Rock_Stone"
    },
    {
      "x": 3,
      "y": 9,
      "z": 0,
      "name": "Soil_Grass"
    },
    {
      "x": 3,
      "y": 10,
      "z": 0,
      "name": "Plant_Fern_Forest",
      "support": 15
    },
    {
      "x": 3,
      "y": 1,
      "z": 1,
      "name": "Rock_Stone"
    },
    {
      "x": 3,
      "y": 2,
      "z": 1,
      "name": "Rock_Stone"
    },
    {
      "x": 3,
      "y": 3,
      "z": 1,
      "name": "Rock_Stone"
    },
    {
      "x": 3,
      "y": 4,
      "z": 1,
      "name": "Rock_Stone"
    },
    {
      "x": 3,
      "y": 5,
      "z": 1,
      "name": "Rock_Stone"
    },
    {
      "x": 3,
      "y": 6,
      "z": 1,
      "name": "Rock_Stone"
    },
    {
      "x": 3,
      "y": 7,
      "z": 1,
      "name": "Rock_Stone"
    },
    {
      "x": 3,
      "y": 8,
      "z": 1,
      "name": "Rock_Stone"
    },
    {
      "x": 3,
      "y": 9,
      "z": 1,
      "name": "Soil_Grass"
    },
    {
      "x": 3,
      "y": 1,
      "z": 2,
      "name": "Rock_Stone"
    },
    {
      "x": 3,
      "y": 2,
      "z": 2,
      "name": "Rock_Stone"
    },
    {
      "x": 3,
      "y": 3,
      "z": 2,
      "name": "Rock_Stone"
    },
    {
      "x": 3,
      "y": 4,
      "z": 2,
      "name": "Rock_Stone"
    },
    {
      "x": 3,
      "y": 5,
      "z": 2,
      "name": "Rock_Stone"
    },
    {
      "x": 3,
      "y": 6,
      "z": 2,
      "name": "Rock_Stone"
    },
    {
      "x": 3,
      "y": 1,
      "z": 3,
      "name": "Rock_Stone"
    },
    {
      "x": 3,
      "y": 2,
      "z": 3,
      "name": "Rock_Stone"
    },
    {
      "x": 4,
      "y": 1,
      "z": -4,
      "name": "Rock_Stone"
    },
    {
      "x": 4,
      "y": 2,
      "z": -4,
      "name": "Rock_Stone"
    },
    {
      "x": 4,
      "y": 3,
      "z": -4,
      "name": "Rock_Stone"
    },
    {
      "x": 4,
      "y": 4,
      "z": -4,
      "name": "Rock_Stone"
    },
    {
      "x": 4,
      "y": 5,
      "z": -4,
      "name": "Rock_Stone"
    },
    {
      "x": 4,
      "y": 1,
      "z": -3,
      "name": "Rock_Stone"
    },
    {
      "x": 4,
      "y": 2,
      "z": -3,
      "name": "Rock_Stone"
    },
    {
      "x": 4,
      "y": 3,
      "z": -3,
      "name": "Rock_Stone"
    },
    {
      "x": 4,
      "y": 4,
      "z": -3,
      "name": "Rock_Stone"
    },
    {
      "x": 4,
      "y": 5,
      "z": -3,
      "name": "Rock_Stone"
    },
    {
      "x": 4,
      "y": 6,
      "z": -3,
      "name": "Rock_Stone"
    },
    {
      "x": 4,
      "y": 7,
      "z": -3,
      "name": "Rock_Stone"
    },
    {
      "x": 4,
      "y": 1,
      "z": -2,
      "name": "Rock_Stone"
    },
    {
      "x": 4,
      "y": 2,
      "z": -2,
      "name": "Rock_Stone"
    },
    {
      "x": 4,
      "y": 3,
      "z": -2,
      "name": "Rock_Stone"
    },
    {
      "x": 4,
      "y": 4,
      "z": -2,
      "name": "Rock_Stone"
    },
    {
      "x": 4,
      "y": 5,
      "z": -2,
      "name": "Rock_Stone"
    },
    {
      "x": 4,
      "y": 6,
      "z": -2,
      "name": "Rock_Stone"
    },
    {
      "x": 4,
      "y": 7,
      "z": -2,
      "name": "Rock_Stone"
    },
    {
      "x": 4,
      "y": 8,
      "z": -2,
      "name": "Soil_Grass"
    },
    {
      "x": 4,
      "y": 1,
      "z": -1,
      "name": "Rock_Stone"
    },
    {
      "x": 4,
      "y": 2,
      "z": -1,
      "name": "Rock_Stone"
    },
    {
      "x": 4,
      "y": 3,
      "z": -1,
      "name": "Rock_Stone"
    },
    {
      "x": 4,
      "y": 4,
      "z": -1,
      "name": "Rock_Stone"
    },
    {
      "x": 4,
      "y": 5,
      "z": -1,
      "name": "Rock_Stone"
    },
    {
      "x": 4,
      "y": 6,
      "z": -1,
      "name": "Rock_Stone"
    },
    {
      "x": 4,
      "y": 7,
      "z": -1,
      "name": "Rock_Stone"
    },
    {
      "x": 4,
      "y": 8,
      "z": -1,
      "name": "Soil_Grass"
    },
    {
      "x": 4,
      "y": 1,
      "z": 0,
      "name": "Rock_Stone"
    },
    {
      "x": 4,
      "y": 2,
      "z": 0,
      "name": "Rock_Stone"
    },
    {
      "x": 4,
      "y": 3,
      "z": 0,
      "name": "Rock_Stone"
    },
    {
      "x": 4,
      "y": 4,
      "z": 0,
      "name": "Rock_Stone"
    },
    {
      "x": 4,
      "y": 5,
      "z": 0,
      "name": "Rock_Stone"
    },
    {
      "x": 4,
      "y": 6,
      "z": 0,
      "name": "Rock_Stone"
    },
    {
      "x": 4,
      "y": 7,
      "z": 0,
      "name": "Rock_Stone"
    },
    {
      "x": 4,
      "y": 8,
      "z": 0,
      "name": "Soil_Grass"
    },
    {
      "x": 4,
      "y": 9,
      "z": 0,
      "name": "Rock_Crystal_Blue_Small"
    },
    {
      "x": 4,
      "y": 1,
      "z": 1,
      "name": "Rock_Stone"
    },
    {
      "x": 4,
      "y": 2,
      "z": 1,
      "name": "Rock_Stone"
    },
    {
      "x": 4,
      "y": 3,
      "z": 1,
      "name": "Rock_Stone"
    },
    {
      "x": 4,
      "y": 4,
      "z": 1,
      "name": "Rock_Stone"
    },
    {
      "x": 4,
      "y": 5,
      "z": 1,
      "name": "Rock_Stone"
    },
    {
      "x": 4,
      "y": 6,
      "z": 1,
      "name": "Rock_Stone"
    },
    {
      "x": 4,
      "y": 7,
      "z": 1,
      "name": "Rock_Stone"
    },
    {
      "x": 4,
      "y": 8,
      "z": 1,
      "name": "Soil_Grass"
    },
    {
      "x": 4,
      "y": 9,
      "z": 1,
      "name": "Plant_Fern_Forest",
      "support": 15
    },
    {
      "x": 4,
      "y": 1,
      "z": 2,
      "name": "Rock_Stone"
    },
    {
      "x": 4,
      "y": 2,
      "z": 2,
      "name": "Rock_Stone"
    },
    {
      "x": 4,
      "y": 3,
      "z": 2,
      "name": "Rock_Stone"
    },
    {
      "x": 4,
      "y": 4,
      "z": 2,
      "name": "Rock_Stone"
    },
    {
      "x": 4,
      "y": 5,
      "z": 2,
      "name": "Rock_Stone"
    },
    {
      "x": 4,
      "y": 6,
      "z": 2,
      "name": "Rock_Stone"
    },
    {
      "x": 4,
      "y": 7,
      "z": 2,
      "name": "Plant_Moss_Rug_Green_Dark",
      "support": 15
    },
    {
      "x": 4,
      "y": 1,
      "z": 3,
      "name": "Rock_Stone"
    },
    {
      "x": 4,
      "y": 2,
      "z": 3,
      "name": "Rock_Stone"
    },
    {
      "x": 4,
      "y": 3,
      "z": 3,
      "name": "Rock_Stone"
    },
    {
      "x": 4,
      "y": 4,
      "z": 3,
      "name": "Rock_Stone"
    },
    {
      "x": 4,
      "y": 5,
      "z": 3,
      "name": "Rock_Stone"
    },
    {
      "x": 5,
      "y": 1,
      "z": -4,
      "name": "Rock_Stone"
    },
    {
      "x": 5,
      "y": 2,
      "z": -4,
      "name": "Rock_Stone"
    },
    {
      "x": 5,
      "y": 3,
      "z": -4,
      "name": "Rock_Stone"
    },
    {
      "x": 5,
      "y": 4,
      "z": -4,
      "name": "Rock_Stone"
    },
    {
      "x": 5,
      "y": 1,
      "z": -3,
      "name": "Rock_Stone"
    },
    {
      "x": 5,
      "y": 2,
      "z": -3,
      "name": "Rock_Stone"
    },
    {
      "x": 5,
      "y": 3,
      "z": -3,
      "name": "Rock_Stone"
    },
    {
      "x": 5,
      "y": 4,
      "z": -3,
      "name": "Rock_Stone"
    },
    {
      "x": 5,
      "y": 5,
      "z": -3,
      "name": "Rock_Stone"
    },
    {
      "x": 5,
      "y": 6,
      "z": -3,
      "name": "Rock_Stone"
    },
    {
      "x": 5,
      "y": 1,
      "z": -2,
      "name": "Rock_Stone"
    },
    {
      "x": 5,
      "y": 2,
      "z": -2,
      "name": "Rock_Stone"
    },
    {
      "x": 5,
      "y": 3,
      "z": -2,
      "name": "Rock_Stone"
    },
    {
      "x": 5,
      "y": 4,
      "z": -2,
      "name": "Rock_Stone"
    },
    {
      "x": 5,
      "y": 5,
      "z": -2,
      "name": "Rock_Stone"
    },
    {
      "x": 5,
      "y": 6,
      "z": -2,
      "name": "Rock_Stone"
    },
    {
      "x": 5,
      "y": 7,
      "z": -2,
      "name": "Rock_Stone"
    },
    {
      "x": 5,
      "y": 8,
      "z": -2,
      "name": "Soil_Grass"
    },
    {
      "x": 5,
      "y": 9,
      "z": -2,
      "name": "Plant_Moss_Rug_Green_Dark",
      "support": 15
    },
    {
      "x": 5,
      "y": 1,
      "z": -1,
      "name": "Rock_Stone"
    },
    {
      "x": 5,
      "y": 2,
      "z": -1,
      "name": "Rock_Stone"
    },
    {
      "x": 5,
      "y": 3,
      "z": -1,
      "name": "Rock_Stone"
    },
    {
      "x": 5,
      "y": 4,
      "z": -1,
      "name": "Rock_Stone"
    },
    {
      "x": 5,
      "y": 5,
      "z": -1,
      "name": "Rock_Stone"
    },
    {
      "x": 5,
      "y": 6,
      "z": -1,
      "name": "Rock_Stone"
    },
    {
      "x": 5,
      "y": 7,
      "z": -1,
      "name": "Rock_Stone"
    },
    {
      "x": 5,
      "y": 8,
      "z": -1,
      "name": "Soil_Grass"
    },
    {
      "x": 5,
      "y": 1,
      "z": 0,
      "name": "Rock_Stone"
    },
    {
      "x": 5,
      "y": 2,
      "z": 0,
      "name": "Rock_Stone"
    },
    {
      "x": 5,
      "y": 3,
      "z": 0,
      "name": "Rock_Stone"
    },
    {
      "x": 5,
      "y": 4,
      "z": 0,
      "name": "Rock_Stone"
    },
    {
      "x": 5,
      "y": 5,
      "z": 0,
      "name": "Rock_Stone"
    },
    {
      "x": 5,
      "y": 6,
      "z": 0,
      "name": "Rock_Stone"
    },
    {
      "x": 5,
      "y": 7,
      "z": 0,
      "name": "Rock_Stone"
    },
    {
      "x": 5,
      "y": 8,
      "z": 0,
      "name": "Soil_Grass"
    },
    {
      "x": 5,
      "y": 1,
      "z": 1,
      "name": "Rock_Stone"
    },
    {
      "x": 5,
      "y": 2,
      "z": 1,
      "name": "Rock_Stone"
    },
    {
      "x": 5,
      "y": 3,
      "z": 1,
      "name": "Rock_Stone"
    },
    {
      "x": 5,
      "y": 4,
      "z": 1,
      "name": "Rock_Stone"
    },
    {
      "x": 5,
      "y": 5,
      "z": 1,
      "name": "Rock_Stone"
    },
    {
      "x": 5,
      "y": 6,
      "z": 1,
      "name": "Rock_Stone"
    },
    {
      "x": 5,
      "y": 7,
      "z": 1,
      "name": "Rock_Stone"
    },
    {
      "x": 5,
      "y": 8,
      "z": 1,
      "name": "Soil_Grass"
    },
    {
      "x": 5,
      "y": 9,
      "z": 1,
      "name": "Plant_Moss_Rug_Green_Dark",
      "support": 15
    },
    {
      "x": 5,
      "y": 1,
      "z": 2,
      "name": "Rock_Stone"
    },
    {
      "x": 5,
      "y": 2,
      "z": 2,
      "name": "Rock_Stone"
    },
    {
      "x": 5,
      "y": 3,
      "z": 2,
      "name": "Rock_Stone"
    },
    {
      "x": 5,
      "y": 4,
      "z": 2,
      "name": "Rock_Stone"
    },
    {
      "x": 5,
      "y": 5,
      "z": 2,
      "name": "Rock_Stone"
    },
    {
      "x": 5,
      "y": 1,
      "z": 3,
      "name": "Rock_Stone"
    },
    {
      "x": 5,
      "y": 2,
      "z": 3,
      "name": "Rock_Stone"
    },
    {
      "x": 5,
      "y": 3,
      "z": 3,
      "name": "Rock_Stone"
    },
    {
      "x": 5,
      "y": 4,
      "z": 3,
      "name": "Rock_Stone"
    },
    {
      "x": 6,
      "y": 1,
      "z": -4,
      "name": "Rock_Stone"
    },
    {
      "x": 6,
      "y": 1,
      "z": -3,
      "name": "Rock_Stone"
    },
    {
      "x": 6,
      "y": 2,
      "z": -3,
      "name": "Rock_Stone"
    },
    {
      "x": 6,
      "y": 3,
      "z": -3,
      "name": "Rock_Stone"
    },
    {
      "x": 6,
      "y": 4,
      "z": -3,
      "name": "Rock_Stone"
    },
    {
      "x": 6,
      "y": 1,
      "z": -2,
      "name": "Rock_Stone"
    },
    {
      "x": 6,
      "y": 2,
      "z": -2,
      "name": "Rock_Stone"
    },
    {
      "x": 6,
      "y": 3,
      "z": -2,
      "name": "Rock_Stone"
    },
    {
      "x": 6,
      "y": 4,
      "z": -2,
      "name": "Rock_Stone"
    },
    {
      "x": 6,
      "y": 5,
      "z": -2,
      "name": "Rock_Stone"
    },
    {
      "x": 6,
      "y": 1,
      "z": -1,
      "name": "Rock_Stone"
    },
    {
      "x": 6,
      "y": 2,
      "z": -1,
      "name": "Rock_Stone"
    },
    {
      "x": 6,
      "y": 3,
      "z": -1,
      "name": "Rock_Stone"
    },
    {
      "x": 6,
      "y": 4,
      "z": -1,
      "name": "Rock_Stone"
    },
    {
      "x": 6,
      "y": 5,
      "z": -1,
      "name": "Rock_Stone"
    },
    {
      "x": 6,
      "y": 6,
      "z": -1,
      "name": "Soil_Grass"
    },
    {
      "x": 6,
      "y": 1,
      "z": 0,
      "name": "Rock_Stone"
    },
    {
      "x": 6,
      "y": 2,
      "z": 0,
      "name": "Rock_Stone"
    },
    {
      "x": 6,
      "y": 3,
      "z": 0,
      "name": "Rock_Stone"
    },
    {
      "x": 6,
      "y": 4,
      "z": 0,
      "name": "Rock_Stone"
    },
    {
      "x": 6,
      "y": 5,
      "z": 0,
      "name": "Rock_Stone"
    },
    {
      "x": 6,
      "y": 6,
      "z": 0,
      "name": "Rock_Stone"
    },
    {
      "x": 6,
      "y": 7,
      "z": 0,
      "name": "Rock_Stone"
    },
    {
      "x": 6,
      "y": 8,
      "z": 0,
      "name": "Soil_Grass"
    },
    {
      "x": 6,
      "y": 9,
      "z": 0,
      "name": "Plant_Moss_Rug_Green_Dark",
      "support": 15
    },
    {
      "x": 6,
      "y": 1,
      "z": 1,
      "name": "Rock_Stone"
    },
    {
      "x": 6,
      "y": 2,
      "z": 1,
      "name": "Rock_Stone"
    },
    {
      "x": 6,
      "y": 3,
      "z": 1,
      "name": "Rock_Stone"
    },
    {
      "x": 6,
      "y": 4,
      "z": 1,
      "name": "Rock_Stone"
    },
    {
      "x": 6,
      "y": 5,
      "z": 1,
      "name": "Rock_Stone"
    },
    {
      "x": 6,
      "y": 6,
      "z": 1,
      "name": "Rock_Stone"
    },
    {
      "x": 6,
      "y": 7,
      "z": 1,
      "name": "Soil_Grass"
    },
    {
      "x": 6,
      "y": 1,
      "z": 2,
      "name": "Rock_Stone"
    },
    {
      "x": 6,
      "y": 2,
      "z": 2,
      "name": "Rock_Stone"
    },
    {
      "x": 6,
      "y": 3,
      "z": 2,
      "name": "Rock_Stone"
    },
    {
      "x": 6,
      "y": 4,
      "z": 2,
      "name": "Rock_Stone"
    },
    {
      "x": 6,
      "y": 5,
      "z": 2,
      "name": "Rock_Stone"
    },
    {
      "x": 6,
      "y": 1,
      "z": 3,
      "name": "Rock_Stone"
    },
    {
      "x": 7,
      "y": 1,
      "z": -3,
      "name": "Rock_Stone"
    },
    {
      "x": 7,
      "y": 2,
      "z": -3,
      "name": "Rock_Stone"
    },
    {
      "x": 7,
      "y": 1,
      "z": -2,
      "name": "Rock_Stone"
    },
    {
      "x": 7,
      "y": 2,
      "z": -2,
      "name": "Rock_Stone"
    },
    {
      "x": 7,
      "y": 3,
      "z": -2,
      "name": "Rock_Stone"
    },
    {
      "x": 7,
      "y": 4,
      "z": -2,
      "name": "Rock_Stone"
    },
    {
      "x": 7,
      "y": 1,
      "z": -1,
      "name": "Rock_Stone"
    },
    {
      "x": 7,
      "y": 2,
      "z": -1,
      "name": "Rock_Stone"
    },
    {
      "x": 7,
      "y": 3,
      "z": -1,
      "name": "Rock_Stone"
    },
    {
      "x": 7,
      "y": 4,
      "z": -1,
      "name": "Rock_Stone"
    },
    {
      "x": 7,
      "y": 1,
      "z": 0,
      "name": "Rock_Stone"
    },
    {
      "x": 7,
      "y": 2,
      "z": 0,
      "name": "Rock_Stone"
    },
    {
      "x": 7,
      "y": 3,
      "z": 0,
      "name": "Rock_Stone"
    },
    {
      "x": 7,
      "y": 4,
      "z": 0,
      "name": "Rock_Stone"
    },
    {
      "x": 7,
      "y": 1,
      "z": 1,
      "name": "Rock_Stone"
    },
    {
      "x": 7,
      "y": 2,
      "z": 1,
      "name": "Rock_Stone"
    },
    {
      "x": 7,
      "y": 3,
      "z": 1,
      "name": "Rock_Stone"
    },
    {
      "x": 7,
      "y": 4,
      "z": 1,
      "name": "Rock_Stone"
    },
    {
      "x": 7,
      "y": 1,
      "z": 2,
      "name": "Rock_Stone"
    },
    {
      "x": 7,
      "y": 2,
      "z": 2,
      "name": "Rock_Stone"
    },
    {
      "x": 7,
      "y": 3,
      "z": 2,
      "name": "Rock_Stone"
    },
    {
      "x": 7,
      "y": 1,
      "z": 3,
      "name": "Rock_Stone"
    },
    {
      "x": 8,
      "y": 1,
      "z": -3,
      "name": "Rock_Stone"
    },
    {
      "x": 8,
      "y": 1,
      "z": -2,
      "name": "Rock_Stone"
    },
    {
      "x": 8,
      "y": 2,
      "z": -2,
      "name": "Rock_Stone"
    },
    {
      "x": 8,
      "y": 1,
      "z": -1,
      "name": "Rock_Stone"
    },
    {
      "x": 8,
      "y": 2,
      "z": -1,
      "name": "Rock_Stone"
    },
    {
      "x": 8,
      "y": 3,
      "z": -1,
      "name": "Rock_Stone"
    },
    {
      "x": 8,
      "y": 1,
      "z": 0,
      "name": "Rock_Stone"
    },
    {
      "x": 8,
      "y": 2,
      "z": 0,
      "name": "Rock_Stone"
    },
    {
      "x": 8,
      "y": 3,
      "z": 0,
      "name": "Rock_Stone"
    },
    {
      "x": 8,
      "y": 1,
      "z": 1,
      "name": "Rock_Stone"
    },
    {
      "x": 8,
      "y": 2,
      "z": 1,
      "name": "Rock_Stone"
    },
    {
      "x": 8,
      "y": 1,
      "z": 2,
      "name": "Rock_Stone"
    }
  ]
}