{
  "version": 8,
  "blockIdVersion": 11,
  "anchorX": 2,
  "anchorY": 1,
  "anchorZ": 0,
  "blocks": [
    {
      "x": 0,
      "y": 1,
      "z": -3,
      "name": "Rock_Stone_Brick"
    },
    {
      "x": 0,
      "y": 2,
      "z": -3,
      "name": "Rock_Stone_Brick"
    },
    {
      "x": 0,
      "y": 3,
      "z": -3,
      "name": "Rock_Stone_Brick_Mossy"
    },
    {
      "x": 0,
      "y": 0,
      "z": -2,
      "name": "Rock_Stone_Brick_Mossy"
    },
    {
      "x": 0,
      "y": 1,
      "z": -2,
      "name": "Empty"
    },
    {
      "x": 0,
      "y": 2,
      "z": -2,
      "name": "Empty"
    },
    {
      "x": 0,
      "y": 3,
      "z": -2,
      "name": "Plant_Moss_Cave_Green_Dark",
      "support": 15,
      "rotation": 8
    },
    {
      "x": 0,
      "y": 4,
      "z": -2,
      "name": "Rock_Stone_Brick_Mossy"
    },
    {
      "x": 0,
      "y": 1,
      "z": -1,
      "name": "Empty"
    },
    {
      "x": 0,
      "y": 2,
      "z": -1,
      "name": "Empty"
    },
    {
      "x": 0,
      "y": 3,
      "z": -1,
      "name": "Empty"
    },
    {
      "x": 0,
      "y": 4,
      "z": -1,
      "name": "Plant_Moss_Cave_Green_Dark",
      "support": 15,
      "rotation": 8
    },
    {
      "x": 0,
      "y": 5,
      "z": -1,
      "name": "Rock_Stone_Brick"
    },
    {
      "x": 0,
      "y": 1,
      "z": 0,
      "name": "Empty"
    },
    {
      "x": 0,
      "y": 2,
      "z": 0,
      "name": "Empty"
    },
    {
      "x": 0,
      "y": 3,
      "z": 0,
      "name": "Empty"
    },
    {
      "x": 0,
      "y": 4,
      "z": 0,
      "name": "Empty"
    },
    {
      "x": 0,
      "y": 5,
      "z": 0,
      "name": "Rock_Stone_Brick_Mossy"
    },
    {
      "x": 0,
      "y": 1,
      "z": 1,
      "name": "Empty"
    },
    {
      "x": 0,
      "y": 2,
      "z": 1,
      "name": "Empty"
    },
    {
      "x": 0,
      "y": 3,
      "z": 1,
      "name": "Empty"
    },
    {
      "x": 0,
      "y": 4,
      "z": 1,
      "name": "Empty"
    },
    {
      "x": 0,
      "y": 5,
      "z": 1,
      "name": "Rock_Stone_Brick"
    },
    {
      "x": 0,
      "y": 0,
      "z": 2,
      "name": "Rock_Stone_Brick"
    },
    {
      "x": 0,
      "y": 1,
      "z": 2,
      "name": "Empty"
    },
    {
      "x": 0,
      "y": 2,
      "z": 2,
      "name": "Empty"
    },
    {
      "x": 0,
      "y": 3,
      "z": 2,
      "name": "Plant_Moss_Cave_Green_Dark",
      "support": 15,
      "rotation": 8
    },
    {
      "x": 0,
      "y": 4,
      "z": 2,
      "name": "Rock_Stone_Brick"
    },
    {
      "x": 0,
      "y": 0,
      "z": 3,
      "name": "Rock_Stone"
    },
    {
      "x": 0,
      "y": 1,
      "z": 3,
      "name": "Rock_Stone_Brick"
    },
    {
      "x": 0,
      "y": 2,
      "z": 3,
      "name": "Rock_Stone_Brick_Mossy"
    },
    {
      "x": 0,
      "y": 3,
      "z": 3,
      "name": "Rock_Stone_Brick_Mossy"
    },
    {
      "x": 1,
      "y": 1,
      "z": -4,
      "name": "Rock_Stone"
    },
    {
      "x": 1,
      "y": 2,
      "z": -4,
      "name": "Rock_Stone"
    },
    {
      "x": 1,
      "y": 3,
      "z": -4,
      "name": "Rock_Stone_Mossy"
    },
    {
      "x": 1,
      "y": -1,
      "z": -3,
      "name": "Rock_Stone_Mossy"
    },
    {
      "x": 1,
      "y": 0,
      "z": -3,
      "name": "Rock_Stone"
    },
    {
      "x": 1,
      "y": 1,
      "z": -3,
      "name": "Rock_Stone"
    },
    {
      "x": 1,
      "y": 2,
      "z": -3,
      "name": "Rock_Stone"
    },
    {
      "x": 1,
      "y": 3,
      "z": -3,
      "name": "Rock_Stone"
    },
    {
      "x": 1,
      "y": 4,
      "z": -3,
      "name": "Rock_Stone"
    },
    {
      "x": 1,
      "y": -2,
      "z": -2,
      "name": "Rock_Stone"
    },
    {
      "x": 1,
      "y": -1,
      "z": -2,
      "name": "Rock_Stone"
    },
    {
      "x": 1,
      "y": 0,
      "z": -2,
      "name": "Rock_Stone"
    },
    {
      "x": 1,
      "y": 1,
      "z": -2,
      "name": "Plant_Crop_Mushroom_Glowing_Blue"
    },
    {
      "x": 1,
      "y": 2,
      "z": -2,
      "name": "Empty"
    },
    {
      "x": 1,
      "y": 3,
      "z": -2,
      "name": "Empty"
    },
    {
      "x": 1,
      "y": 4,
      "z": -2,
      "name": "Rock_Stone"
    },
    {
      "x": 1,
      "y": 5,
      "z": -2,
      "name": "Rock_Stone"
    },
    {
      "x": 1,
      "y": -2,
      "z": -1,
      "name": "Rock_Stone"
    },
    {
      "x": 1,
      "y": -1,
      "z": -1,
      "name": "Rock_Stone"
    },
    {
      "x": 1,
      "y": 1,
      "z": -1,
      "name": "Empty"
    },
    {
      "x": 1,
      "y": 2,
      "z": -1,
      "name": "Empty"
    },
    {
      "x": 1,
      "y": 3,
      "z": -1,
      "name": "Empty"
    },
    {
      "x": 1,
      "y": 4,
      "z": -1,
      "name": "Empty"
    },
    {
      "x": 1,
      "y": 5,
      "z": -1,
      "name": "Rock_Stone"
    },
    {
      "x": 1,
      "y": 6,
      "z": -1,
      "name": "Rock_Stone"
    },
    {
      "x": 1,
      "y": -2,
      "z": 0,
      "name": "Rock_Stone"
    },
    {
      "x": 1,
      "y": -1,
      "z": 0,
      "name": "Rock_Stone"
    },
    {
      "x": 1,
      "y": 1,
      "z": 0,
      "name": "Empty"
    },
    {
      "x": 1,
      "y": 2,
      "z": 0,
      "name": "Empty"
    },
    {
      "x": 1,
      "y": 3,
      "z": 0,
      "name": "Empty"
    },
    {
      "x": 1,
      "y": 4,
      "z": 0,
      "name": "Empty"
    },
    {
      "x": 1,
      "y": 5,
      "z": 0,
      "name": "Rock_Stone"
    },
    {
      "x": 1,
      "y": 6,
      "z": 0,
      "name": "Rock_Stone"
    },
    {
      "x": 1,
      "y": -2,
      "z": 1,
      "name": "Rock_Stone_Mossy"
    },
    {
      "x": 1,
      "y": -1,
      "z": 1,
      "name": "Rock_Stone"
    },
    {
      "x": 1,
      "y": 1,
      "z": 1,
      "name": "Empty"
    },
    {
      "x": 1,
      "y": 2,
      "z": 1,
      "name": "Empty"
    },
    {
      "x": 1,
      "y": 3,
      "z": 1,
      "name": "Empty"
    },
    {
      "x": 1,
      "y": 4,
      "z": 1,
      "name": "Empty"
    },
    {
      "x": 1,
      "y": 5,
      "z": 1,
      "name": "Rock_Stone"
    },
    {
      "x": 1,
      "y": 6,
      "z": 1,
      "name": "Rock_Stone"
    },
    {
      "x": 1,
      "y": -2,
      "z": 2,
      "name": "Rock_Stone"
    },
    {
      "x": 1,
      "y": -1,
      "z": 2,
      "name": "Rock_Stone_Mossy"
    },
    {
      "x": 1,
      "y": 0,
      "z": 2,
      "name": "Rock_Stone"
    },
    {
      "x": 1,
      "y": 1,
      "z": 2,
      "name": "Empty"
    },
    {
      "x": 1,
      "y": 2,
      "z": 2,
      "name": "Empty"
    },
    {
      "x": 1,
      "y": 3,
      "z": 2,
      "name": "Empty"
    },
    {
      "x": 1,
      "y": 4,
      "z": 2,
      "name": "Rock_Stone"
    },
    {
      "x": 1,
      "y": 5,
      "z": 2,
      "name": "Rock_Stone"
    },
    {
      "x": 1,
      "y": -1,
      "z": 3,
      "name": "Rock_Stone"
    },
    {
      "x": 1,
      "y": 0,
      "z": 3,
      "name": "Rock_Stone"
    },
    {
      "x": 1,
      "y": 1,
      "z": 3,
      "name": "Rock_Stone"
    },
    {
      "x": 1,
      "y": 2,
      "z": 3,
      "name": "Rock_Stone_Mossy"
    },
    {
      "x": 1,
      "y": 3,
      "z": 3,
      "name": "Rock_Stone"
    },
    {
      "x": 1,
      "y": 4,
      "z": 3,
      "name": "Rock_Stone"
    },
    {
      "x": 1,
      "y": 0,
      "z": 4,
      "name": "Rock_Stone"
    },
    {
      "x": 1,
      "y": 1,
      "z": 4,
      "name": "Rock_Stone"
    },
    {
      "x": 1,
      "y": 2,
      "z": 4,
      "name": "Rock_Stone"
    },
    {
      "x": 1,
      "y": 3,
      "z": 4,
      "name": "Rock_Stone"
    },
    {
      "x": 2,
      "y": -1,
      "z": -5,
      "name": "Rock_Stone"
    },
    {
      "x": 2,
      "y": 0,
      "z": -5,
      "name": "Rock_Stone"
    },
    {
      "x": 2,
      "y": 1,
      "z": -5,
      "name": "Rock_Stone_Mossy"
    },
    {
      "x": 2,
      "y": 2,
      "z": -5,
      "name": "Rock_Stone"
    },
    {
      "x": 2,
      "y": 3,
      "z": -5,
      "name": "Rock_Stone_Mossy"
    },
    {
      "x": 2,
      "y": -2,
      "z": -4,
      "name": "Rock_Stone"
    },
    {
      "x": 2,
      "y": -1,
      "z": -4,
      "name": "Rock_Stone"
    },
    {
      "x": 2,
      "y": 0,
      "z": -4,
      "name": "Rock_Stone"
    },
    {
      "x": 2,
      "y": 1,
      "z": -4,
      "name": "Rock_Stone"
    },
    {
      "x": 2,
      "y": 2,
      "z": -4,
      "name": "Rock_Stone"
    },
    {
      "x": 2,
      "y": 3,
      "z": -4,
      "name": "Rock_Stone"
    },
    {
      "x": 2,
      "y": 4,
      "z": -4,
      "name": "Rock_Stone"
    },
    {
      "x": 2,
      "y": -3,
      "z": -3,
      "name": "Rock_Stone"
    },
    {
      "x": 2,
      "y": -2,
      "z": -3,
      "name": "Rock_Stone"
    },
    {
      "x": 2,
      "y": -1,
      "z": -3,
      "name": "Rock_Stone"
    },
    {
      "x": 2,
      "y": 0,
      "z": -3,
      "name": "Rock_Stone"
    },
    {
      "x": 2,
      "y": 1,
      "z": -3,
      "name": "Rock_Stone"
    },
    {
      "x": 2,
      "y": 2,
      "z": -3,
      "name": "Rock_Stone"
    },
    {
      "x": 2,
      "y": 3,
      "z": -3,
      "name": "Rock_Stone"
    },
    {
      "x": 2,
      "y": 4,
      "z": -3,
      "name": "Rock_Stone_Mossy"
    },
    {
      "x": 2,
      "y": 5,
      "z": -3,
      "name": "Rock_Stone"
    },
    {
      "x": 2,
      "y": -3,
      "z": -2,
      "name": "Rock_Stone"
    },
    {
      "x": 2,
      "y": -2,
      "z": -2,
      "name": "Rock_Stone"
    },
    {
      "x": 2,
      "y": -1,
      "z": -2,
      "name": "Rock_Stone_Mossy"
    },
    {
      "x": 2,
      "y": 0,
      "z": -2,
      "name": "Rock_Stone"
    },
    {
      "x": 2,
      "y": 1,
      "z": -2,
      "name": "Empty"
    },
    {
      "x": 2,
      "y": 2,
      "z": -2,
      "name": "Empty"
    },
    {
      "x": 2,
      "y": 3,
      "z": -2,
      "name": "Empty"
    },
    {
      "x": 2,
      "y": 4,
      "z": -2,
      "name": "Rock_Stone"
    },
    {
      "x": 2,
      "y": 5,
      "z": -2,
      "name": "Rock_Stone"
    },
    {
      "x": 2,
      "y": 6,
      "z": -2,
      "name": "Rock_Stone_Mossy"
    },
    {
      "x": 2,
      "y": -3,
      "z": -1,
      "name": "Rock_Stone"
    },
    {
      "x": 2,
      "y": -2,
      "z": -1,
      "name": "Rock_Stone"
    },
    {
      "x": 2,
      "y": -1,
      "z": -1,
      "name": "Rock_Stone"
    },
    {
      "x": 2,
      "y": 1,
      "z": -1,
      "name": "Empty"
    },
    {
      "x": 2,
      "y": 2,
      "z": -1,
      "name": "Empty"
    },
    {
      "x": 2,
      "y": 3,
      "z": -1,
      "name": "Empty"
    },
    {
      "x": 2,
      "y": 4,
      "z": -1,
      "name": "Empty"
    },
    {
      "x": 2,
      "y": 5,
      "z": -1,
      "name": "Rock_Stone"
    },
    {
      "x": 2,
      "y": 6,
      "z": -1,
      "name": "Rock_Stone"
    },
    {
      "x": 2,
      "y": 7,
      "z": -1,
      "name": "Rock_Stone"
    },
    {
      "x": 2,
      "y": -3,
      "z": 0,
      "name": "Rock_Stone_Mossy"
    },
    {
      "x": 2,
      "y": -2,
      "z": 0,
      "name": "Rock_Stone"
    },
    {
      "x": 2,
      "y": -1,
      "z": 0,
      "name": "Rock_Stone"
    },
    {
      "x": 2,
      "y": 1,
      "z": 0,
      "name": "Empty"
    },
    {
      "x": 2,
      "y": 2,
      "z": 0,
      "name": "Empty"
    },
    {
      "x": 2,
      "y": 3,
      "z": 0,
      "name": "Empty"
    },
    {
      "x": 2,
      "y": 4,
      "z": 0,
      "name": "Empty"
    },
    {
      "x": 2,
      "y": 5,
      "z": 0,
      "name": "Rock_Stone"
    },
    {
      "x": 2,
      "y": 6,
      "z": 0,
      "name": "Rock_Stone_Mossy"
    },
    {
      "x": 2,
      "y": 7,
      "z": 0,
      "name": "Rock_Stone"
    },
    {
      "x": 2,
      "y": -3,
      "z": 1,
      "name": "Rock_Stone"
    },
    {
      "x": 2,
      "y": -2,
      "z": 1,
      "name": "Rock_Stone"
    },
    {
      "x": 2,
      "y": -1,
      "z": 1,
      "name": "Rock_Stone"
    },
    {
      "x": 2,
      "y": 1,
      "z": 1,
      "name": "Empty"
    },
    {
      "x": 2,
      "y": 2,
      "z": 1,
      "name": "Empty"
    },
    {
      "x": 2,
      "y": 3,
      "z": 1,
      "name": "Empty"
    },
    {
      "x": 2,
      "y": 4,
      "z": 1,
      "name": "Empty"
    },
    {
      "x": 2,
      "y": 5,
      "z": 1,
      "name": "Rock_Stone"
    },
    {
      "x": 2,
      "y": 6,
      "z": 1,
      "name": "Rock_Stone_Mossy"
    },
    {
      "x": 2,
      "y": 7,
      "z": 1,
      "name": "Rock_Stone"
    },
    {
      "x": 2,
      "y": -3,
      "z": 2,
      "name": "Rock_Stone"
    },
    {
      "x": 2,
      "y": -2,
      "z": 2,
      "name": "Rock_Stone"
    },
    {
      "x": 2,
      "y": -1,
      "z": 2,
      "name": "Rock_Stone"
    },
    {
      "x": 2,
      "y": 0,
      "z": 2,
      "name": "Rock_Stone"
    },
    {
      "x": 2,
      "y": 1,
      "z": 2,
      "name": "Empty"
    },
    {
      "x": 2,
      "y": 2,
      "z": 2,
      "name": "Empty"
    },
    {
      "x": 2,
      "y": 3,
      "z": 2,
      "name": "Empty"
    },
    {
      "x": 2,
      "y": 4,
      "z": 2,
      "name": "Rock_Stone"
    },
    {
      "x": 2,
      "y": 5,
      "z": 2,
      "name": "Rock_Stone"
    },
    {
      "x": 2,
      "y": 6,
      "z": 2,
      "name": "Rock_Stone_Mossy"
    },
    {
      "x": 2,
      "y": -3,
      "z": 3,
      "name": "Rock_Stone"
    },
    {
      "x": 2,
      "y": -2,
      "z": 3,
      "name": "Rock_Stone"
    },
    {
      "x": 2,
      "y": -1,
      "z": 3,
      "name": "Rock_Stone"
    },
    {
      "x": 2,
      "y": 0,
      "z": 3,
      "name": "Rock_Stone_Mossy"
    },
    {
      "x": 2,
      "y": 1,
      "z": 3,
      "name": "Rock_Stone"
    },
    {
      "x": 2,
      "y": 2,
      "z": 3,
      "name": "Rock_Stone"
    },
    {
      "x": 2,
      "y": 3,
      "z": 3,
      "name": "Rock_Stone"
    },
    {
      "x": 2,
      "y": 4,
      "z": 3,
      "name": "Rock_Stone"
    },
    {
      "x": 2,
      "y": 5,
      "z": 3,
      "name": "Rock_Stone"
    },
    {
      "x": 2,
      "y": -2,
      "z": 4,
      "name": "Rock_Stone"
    },
    {
      "x": 2,
      "y": -1,
      "z": 4,
      "name": "Rock_Stone"
    },
    {
      "x": 2,
      "y": 0,
      "z": 4,
      "name": "Rock_Stone"
    },
    {
      "x": 2,
      "y": 1,
      "z": 4,
      "name": "Rock_Stone"
    },
    {
      "x": 2,
      "y": 2,
      "z": 4,
      "name": "Rock_Stone"
    },
    {
      "x": 2,
      "y": 3,
      "z": 4,
      "name": "Rock_Stone"
    },
    {
      "x": 2,
      "y": 4,
      "z": 4,
      "name": "Rock_Stone"
    },
    {
      "x": 2,
      "y": -1,
      "z": 5,
      "name": "Rock_Stone"
    },
    {
      "x": 2,
      "y": 0,
      "z": 5,
      "name": "Rock_Stone"
    },
    {
      "x": 2,
      "y": 1,
      "z": 5,
      "name": "Rock_Stone"
    },
    {
      "x": 2,
      "y": 2,
      "z": 5,
      "name": "Rock_Stone"
    },
    {
      "x": 2,
      "y": 3,
      "z": 5,
      "name": "Rock_Stone_Mossy"
    },
    {
      "x": 3,
      "y": -1,
      "z": -5,
      "name": "Rock_Stone"
    },
    {
      "x": 3,
      "y": 0,
      "z": -5,
      "name": "Rock_Stone"
    },
    {
      "x": 3,
      "y": 1,
      "z": -5,
      "name": "Rock_Stone_Mossy"
    },
    {
      "x": 3,
      "y": 2,
      "z": -5,
      "name": "Rock_Stone"
    },
    {
      "x": 3,
      "y": 3,
      "z": -5,
      "name": "Rock_Stone"
    },
    {
      "x": 3,
      "y": -2,
      "z": -4,
      "name": "Rock_Stone"
    },
    {
      "x": 3,
      "y": -1,
      "z": -4,
      "name": "Rock_Stone_Mossy"
    },
    {
      "x": 3,
      "y": 0,
      "z": -4,
      "name": "Rock_Stone_Mossy"
    },
    {
      "x": 3,
      "y": 1,
      "z": -4,
      "name": "Rock_Stone"
    },
    {
      "x": 3,
      "y": 2,
      "z": -4,
      "name": "Rock_Stone"
    },
    {
      "x": 3,
      "y": 3,
      "z": -4,
      "name": "Rock_Stone"
    },
    {
      "x": 3,
      "y": 4,
      "z": -4,
      "name": "Rock_Stone"
    },
    {
      "x": 3,
      "y": -3,
      "z": -3,
      "name": "Rock_Stone"
    },
    {
      "x": 3,
      "y": -2,
      "z": -3,
      "name": "Rock_Stone"
    },
    {
      "x": 3,
      "y": -1,
      "z": -3,
      "name": "Rock_Stone"
    },
    {
      "x": 3,
      "y": 0,
      "z": -3,
      "name": "Rock_Stone"
    },
    {
      "x": 3,
      "y": 1,
      "z": -3,
      "name": "Rock_Stone"
    },
    {
      "x": 3,
      "y": 2,
      "z": -3,
      "name": "Rock_Stone_Mossy"
    },
    {
      "x": 3,
      "y": 3,
      "z": -3,
      "name": "Rock_Stone"
    },
    {
      "x": 3,
      "y": 4,
      "z": -3,
      "name": "Rock_Stone"
    },
    {
      "x": 3,
      "y": 5,
      "z": -3,
      "name": "Rock_Stone"
    },
    {
      "x": 3,
      "y": -3,
      "z": -2,
      "name": "Rock_Stone"
    },
    {
      "x": 3,
      "y": -2,
      "z": -2,
      "name": "Rock_Stone"
    },
    {
      "x": 3,
      "y": -1,
      "z": -2,
      "name": "Rock_Stone"
    },
    {
      "x": 3,
      "y": 0,
      "z": -2,
      "name": "Rock_Stone"
    },
    {
      "x": 3,
      "y": 1,
      "z": -2,
      "name": "Empty"
    },
    {
      "x": 3,
      "y": 2,
      "z": -2,
      "name": "Empty"
    },
    {
      "x": 3,
      "y": 3,
      "z": -2,
      "name": "Empty"
    },
    {
      "x": 3,
      "y": 4,
      "z": -2,
      "name": "Rock_Stone"
    },
    {
      "x": 3,
      "y": 5,
      "z": -2,
      "name": "Rock_Stone"
    },
    {
      "x": 3,
      "y": 6,
      "z": -2,
      "name": "Rock_Stone"
    },
    {
      "x": 3,
      "y": -3,
      "z": -1,
      "name": "Rock_Stone"
    },
    {
      "x": 3,
      "y": -2,
      "z": -1,
      "name": "Rock_Stone"
    },
    {
      "x": 3,
      "y": -1,
      "z": -1,
      "name": "Rock_Stone"
    },
    {
      "x": 3,
      "y": 1,
      "z": -1,
      "name": "Empty"
    },
    {
      "x": 3,
      "y": 2,
      "z": -1,
      "name": "Empty"
    },
    {
      "x": 3,
      "y": 3,
      "z": -1,
      "name": "Empty"
    },
    {
      "x": 3,
      "y": 4,
      "z": -1,
      "name": "Empty"
    },
    {
      "x": 3,
      "y": 5,
      "z": -1,
      "name": "Rock_Stone"
    },
    {
      "x": 3,
      "y": 6,
      "z": -1,
      "name": "Rock_Stone"
    },
    {
      "x": 3,
      "y": 7,
      "z": -1,
      "name": "Rock_Stone"
    },
    {
      "x": 3,
      "y": -3,
      "z": 0,
      "name": "Rock_Stone"
    },
    {
      "x": 3,
      "y": -2,
      "z": 0,
      "name": "Rock_Stone"
    },
    {
      "x": 3,
      "y": -1,
      "z": 0,
      "name": "Rock_Stone_Mossy"
    },
    {
      "x": 3,
      "y": 1,
      "z": 0,
      "name": "Empty"
    },
    {
      "x": 3,
      "y": 2,
      "z": 0,
      "name": "Empty"
    },
    {
      "x": 3,
      "y": 3,
      "z": 0,
      "name": "Empty"
    },
    {
      "x": 3,
      "y": 4,
      "z": 0,
      "name": "Empty"
    },
    {
      "x": 3,
      "y": 5,
      "z": 0,
      "name": "Rock_Stone"
    },
    {
      "x": 3,
      "y": 6,
      "z": 0,
      "name": "Rock_Stone"
    },
    {
      "x": 3,
      "y": 7,
      "z": 0,
      "name": "Rock_Stone_Mossy"
    },
    {
      "x": 3,
      "y": -3,
      "z": 1,
      "name": "Rock_Stone"
    },
    {
      "x": 3,
      "y": -2,
      "z": 1,
      "name": "Rock_Stone"
    },
    {
      "x": 3,
      "y": -1,
      "z": 1,
      "name": "Rock_Stone_Mossy"
    },
    {
      "x": 3,
      "y": 1,
      "z": 1,
      "name": "Empty"
    },
    {
      "x": 3,
      "y": 2,
      "z": 1,
      "name": "Empty"
    },
    {
      "x": 3,
      "y": 3,
      "z": 1,
      "name": "Empty"
    },
    {
      "x": 3,
      "y": 4,
      "z": 1,
      "name": "Empty"
    },
    {
      "x": 3,
      "y": 5,
      "z": 1,
      "name": "Rock_Stone_Mossy"
    },
    {
      "x": 3,
      "y": 6,
      "z": 1,
      "name": "Rock_Stone"
    },
    {
      "x": 3,
      "y": 7,
      "z": 1,
      "name": "Rock_Stone"
    },
    {
      "x": 3,
      "y": -3,
      "z": 2,
      "name": "Rock_Stone"
    },
    {
      "x": 3,
      "y": -2,
      "z": 2,
      "name": "Rock_Stone"
    },
    {
      "x": 3,
      "y": -1,
      "z": 2,
      "name": "Rock_Stone"
    },
    {
      "x": 3,
      "y": 0,
      "z": 2,
      "name": "Rock_Stone"
    },
    {
      "x": 3,
      "y": 1,
      "z": 2,
      "name": "Empty"
    },
    {
      "x": 3,
      "y": 2,
      "z": 2,
      "name": "Empty"
    },
    {
      "x": 3,
      "y": 3,
      "z": 2,
      "name": "Empty"
    },
    {
      "x": 3,
      "y": 4,
      "z": 2,
      "name": "Rock_Stone"
    },
    {
      "x": 3,
      "y": 5,
      "z": 2,
      "name": "Rock_Stone"
    },
    {
      "x": 3,
      "y": 6,
      "z": 2,
      "name": "Rock_Stone"
    },
    {
      "x": 3,
      "y": -3,
      "z": 3,
      "name": "Rock_Stone"
    },
    {
      "x": 3,
      "y": -2,
      "z": 3,
      "name": "Rock_Stone"
    },
    {
      "x": 3,
      "y": -1,
      "z": 3,
      "name": "Rock_Stone"
    },
    {
      "x": 3,
      "y": 0,
      "z": 3,
      "name": "Rock_Stone"
    },
    {
      "x": 3,
      "y": 1,
      "z": 3,
      "name": "Rock_Stone"
    },
    {
      "x": 3,
      "y": 2,
      "z": 3,
      "name": "Rock_Stone"
    },
    {
      "x": 3,
      "y": 3,
      "z": 3,
      "name": "Rock_Stone"
    },
    {
      "x": 3,
      "y": 4,
      "z": 3,
      "name": "Rock_Stone_Mossy"
    },
    {
      "x": 3,
      "y": 5,
      "z": 3,
      "name": "Rock_Stone"
    },
    {
      "x": 3,
      "y": -2,
      "z": 4,
      "name": "Rock_Stone"
    },
    {
      "x": 3,
      "y": -1,
      "z": 4,
      "name": "Rock_Stone"
    },
    {
      "x": 3,
      "y": 0,
      "z": 4,
      "name": "Rock_Stone"
    },
    {
      "x": 3,
      "y": 1,
      "z": 4,
      "name": "Rock_Stone"
    },
    {
      "x": 3,
      "y": 2,
      "z": 4,
      "name": "Rock_Stone"
    },
    {
      "x": 3,
      "y": 3,
      "z": 4,
      "name": "Rock_Stone"
    },
    {
      "x": 3,
      "y": 4,
      "z": 4,
      "name": "Rock_Stone_Mossy"
    },
    {
      "x": 3,
      "y": -1,
      "z": 5,
      "name": "Rock_Stone"
    },
    {
      "x": 3,
      "y": 0,
      "z": 5,
      "name": "Rock_Stone"
    },
    {
      "x": 3,
      "y": 1,
      "z": 5,
      "name": "Rock_Stone"
    },
    {
      "x": 3,
      "y": 2,
      "z": 5,
      "name": "Rock_Stone"
    },
    {
      "x": 3,
      "y": 3,
      "z": 5,
      "name": "Rock_Stone"
    },
    {
      "x": 4,
      "y": -1,
      "z": -5,
      "name": "Rock_Stone"
    },
    {
      "x": 4,
      "y": 0,
      "z": -5,
      "name": "Rock_Stone"
    },
    {
      "x": 4,
      "y": 1,
      "z": -5,
      "name": "Rock_Stone"
    },
    {
      "x": 4,
      "y": 2,
      "z": -5,
      "name": "Rock_Stone_Mossy"
    },
    {
      "x": 4,
      "y": 3,
      "z": -5,
      "name": "Rock_Stone"
    },
    {
      "x": 4,
      "y": -2,
      "z": -4,
      "name": "Rock_Stone"
    },
    {
      "x": 4,
      "y": -1,
      "z": -4,
      "name": "Rock_Stone"
    },
    {
      "x": 4,
      "y": 0,
      "z": -4,
      "name": "Rock_Stone"
    },
    {
      "x": 4,
      "y": 1,
      "z": -4,
      "name": "Rock_Stone_Mossy"
    },
    {
      "x": 4,
      "y": 2,
      "z": -4,
      "name": "Rock_Stone"
    },
    {
      "x": 4,
      "y": 3,
      "z": -4,
      "name": "Rock_Stone"
    },
    {
      "x": 4,
      "y": 4,
      "z": -4,
      "name": "Rock_Stone"
    },
    {
      "x": 4,
      "y": -3,
      "z": -3,
      "name": "Rock_Stone"
    },
    {
      "x": 4,
      "y": -2,
      "z": -3,
      "name": "Rock_Stone"
    },
    {
      "x": 4,
      "y": -1,
      "z": -3,
      "name": "Rock_Stone_Mossy"
    },
    {
      "x": 4,
      "y": 0,
      "z": -3,
      "name": "Rock_Stone"
    },
    {
      "x": 4,
      "y": 1,
      "z": -3,
      "name": "Rock_Stone_Mossy"
    },
    {
      "x": 4,
      "y": 2,
      "z": -3,
      "name": "Rock_Stone"
    },
    {
      "x": 4,
      "y": 3,
      "z": -3,
      "name": "Rock_Stone"
    },
    {
      "x": 4,
      "y": 4,
      "z": -3,
      "name": "Rock_Stone"
    },
    {
      "x": 4,
      "y": 5,
      "z": -3,
      "name": "Rock_Stone"
    },
    {
      "x": 4,
      "y": -3,
      "z": -2,
      "name": "Rock_Stone"
    },
    {
      "x": 4,
      "y": -2,
      "z": -2,
      "name": "Rock_Stone"
    },
    {
      "x": 4,
      "y": -1,
      "z": -2,
      "name": "Rock_Stone_Mossy"
    },
    {
      "x": 4,
      "y": 0,
      "z": -2,
      "name": "Rock_Stone"
    },
    {
      "x": 4,
      "y": 1,
      "z": -2,
      "name": "Empty"
    },
    {
      "x": 4,
      "y": 2,
      "z": -2,
      "name": "Empty"
    },
    {
      "x": 4,
      "y": 3,
      "z": -2,
      "name": "Empty"
    },
    {
      "x": 4,
      "y": 4,
      "z": -2,
      "name": "Rock_Stone"
    },
    {
      "x": 4,
      "y": 5,
      "z": -2,
      "name": "Rock_Stone"
    },
    {
      "x": 4,
      "y": 6,
      "z": -2,
      "name": "Rock_Stone"
    },
    {
      "x": 4,
      "y": -3,
      "z": -1,
      "name": "Rock_Stone"
    },
    {
      "x": 4,
      "y": -2,
      "z": -1,
      "name": "Rock_Stone"
    },
    {
      "x": 4,
      "y": -1,
      "z": -1,
      "name": "Rock_Stone"
    },
    {
      "x": 4,
      "y": 1,
      "z": -1,
      "name": "Empty"
    },
    {
      "x": 4,
      "y": 2,
      "z": -1,
      "name": "Empty"
    },
    {
      "x": 4,
      "y": 3,
      "z": -1,
      "name": "Empty"
    },
    {
      "x": 4,
      "y": 4,
      "z": -1,
      "name": "Empty"
    },
    {
      "x": 4,
      "y": 5,
      "z": -1,
      "name": "Rock_Stone"
    },
    {
      "x": 4,
      "y": 6,
      "z": -1,
      "name": "Rock_Stone"
    },
    {
      "x": 4,
      "y": 7,
      "z": -1,
      "name": "Rock_Stone"
    },
    {
      "x": 4,
      "y": -3,
      "z": 0,
      "name": "Rock_Stone"
    },
    {
      "x": 4,
      "y": -2,
      "z": 0,
      "name": "Rock_Stone"
    },
    {
      "x": 4,
      "y": -1,
      "z": 0,
      "name": "Rock_Stone"
    },
    {
      "x": 4,
      "y": 1,
      "z": 0,
      "name": "Empty"
    },
    {
      "x": 4,
      "y": 2,
      "z": 0,
      "name": "Empty"
    },
    {
      "x": 4,
      "y": 3,
      "z": 0,
      "name": "Empty"
    },
    {
      "x": 4,
      "y": 4,
      "z": 0,
      "name": "Empty"
    },
    {
      "x": 4,
      "y": 5,
      "z": 0,
      "name": "Rock_Stone_Mossy"
    },
    {
      "x": 4,
      "y": 6,
      "z": 0,
      "name": "Rock_Stone"
    },
    {
      "x": 4,
      "y": 7,
      "z": 0,
      "name": "Rock_Stone"
    },
    {
      "x": 4,
      "y": -3,
      "z": 1,
      "name": "Rock_Stone"
    },
    {
      "x": 4,
      "y": -2,
      "z": 1,
      "name": "Rock_Stone"
    },
    {
      "x": 4,
      "y": -1,
      "z": 1,
      "name": "Rock_Stone"
    },
    {
      "x": 4,
      "y": 1,
      "z": 1,
      "name": "Empty"
    },
    {
      "x": 4,
      "y": 2,
      "z": 1,
      "name": "Empty"
    },
    {
      "x": 4,
      "y": 3,
      "z": 1,
      "name": "Empty"
    },
    {
      "x": 4,
      "y": 4,
      "z": 1,
      "name": "Empty"
    },
    {
      "x": 4,
      "y": 5,
      "z": 1,
      "name": "Rock_Stone"
    },
    {
      "x": 4,
      "y": 6,
      "z": 1,
      "name": "Rock_Stone_Mossy"
    },
    {
      "x": 4,
      "y": 7,
      "z": 1,
      "name": "Rock_Stone"
    },
    {
      "x": 4,
      "y": -3,
      "z": 2,
      "name": "Rock_Stone"
    },
    {
      "x": 4,
      "y": -2,
      "z": 2,
      "name": "Rock_Stone"
    },
    {
      "x": 4,
      "y": -1,
      "z": 2,
      "name": "Rock_Stone"
    },
    {
      "x": 4,
      "y": 0,
      "z": 2,
      "name": "Rock_Stone"
    },
    {
      "x": 4,
      "y": 1,
      "z": 2,
      "name": "Plant_Crop_Mushroom_Glowing_Blue"
    },
    {
      "x": 4,
      "y": 2,
      "z": 2,
      "name": "Empty"
    },
    {
      "x": 4,
      "y": 3,
      "z": 2,
      "name": "Empty"
    },
    {
      "x": 4,
      "y": 4,
      "z": 2,
      "name": "Rock_Stone_Mossy"
    },
    {
      "x": 4,
      "y": 5,
      "z": 2,
      "name": "Rock_Stone"
    },
    {
      "x": 4,
      "y": 6,
      "z": 2,
      "name": "Rock_Stone"
    },
    {
      "x": 4,
      "y": -3,
      "z": 3,
      "name": "Rock_Stone"
    },
    {
      "x": 4,
      "y": -2,
      "z": 3,
      "name": "Rock_Stone"
    },
    {
      "x": 4,
      "y": -1,
      "z": 3,
      "name": "Rock_Stone_Mossy"
    },
    {
      "x": 4,
      "y": 0,
      "z": 3,
      "name": "Rock_Stone_Mossy"
    },
    {
      "x": 4,
      "y": 1,
      "z": 3,
      "name": "Rock_Stone"
    },
    {
      "x": 4,
      "y": 2,
      "z": 3,
      "name": "Rock_Stone"
    },
    {
      "x": 4,
      "y": 3,
      "z": 3,
      "name": "Rock_Stone"
    },
    {
      "x": 4,
      "y": 4,
      "z": 3,
      "name": "Rock_Stone"
    },
    {
      "x": 4,
      "y": 5,
      "z": 3,
      "name": "Rock_Stone"
    },
    {
      "x": 4,
      "y": -2,
      "z": 4,
      "name": "Rock_Stone"
    },
    {
      "x": 4,
      "y": -1,
      "z": 4,
      "name": "Rock_Stone"
    },
    {
      "x": 4,
      "y": 0,
      "z": 4,
      "name": "Rock_Stone"
    },
    {
      "x": 4,
      "y": 1,
      "z": 4,
      "name": "Rock_Stone"
    },
    {
      "x": 4,
      "y": 2,
      "z": 4,
      "name": "Rock_Stone"
    },
    {
      "x": 4,
      "y": 3,
      "z": 4,
      "name": "Rock_Stone"
    },
    {
      "x": 4,
      "y": 4,
      "z": 4,
      "name": "Rock_Stone"
    },
    {
      "x": 4,
      "y": -1,
      "z": 5,
      "name": "Rock_Stone"
    },
    {
      "x": 4,
      "y": 0,
      "z": 5,
      "name": "Rock_Stone_Mossy"
    },
    {
      "x": 4,
      "y": 1,
      "z": 5,
      "name": "Rock_Stone"
    },
    {
      "x": 4,
      "y": 2,
      "z": 5,
      "name": "Rock_Stone"
    },
    {
      "x": 4,
      "y": 3,
      "z": 5,
      "name": "Rock_Stone"
    },
    {
      "x": 5,
      "y": -1,
      "z": -5,
      "name": "Rock_Stone_Mossy"
    },
    {
      "x": 5,
      "y": 0,
      "z": -5,
      "name": "Rock_Stone"
    },
    {
      "x": 5,
      "y": 1,
      "z": -5,
      "name": "Rock_Stone_Mossy"
    },
    {
      "x": 5,
      "y": 2,
      "z": -5,
      "name": "Rock_Stone"
    },
    {
      "x": 5,
      "y": 3,
      "z": -5,
      "name": "Rock_Stone"
    },
    {
      "x": 5,
      "y": -2,
      "z": -4,
      "name": "Rock_Stone"
    },
    {
      "x": 5,
      "y": -1,
      "z": -4,
      "name": "Rock_Stone"
    },
    {
      "x": 5,
      "y": 0,
      "z": -4,
      "name": "Rock_Stone"
    },
    {
      "x": 5,
      "y": 1,
      "z": -4,
      "name": "Rock_Stone"
    },
    {
      "x": 5,
      "y": 2,
      "z": -4,
      "name": "Rock_Stone_Mossy"
    },
    {
      "x": 5,
      "y": 3,
      "z": -4,
      "name": "Rock_Stone"
    },
    {
      "x": 5,
      "y": 4,
      "z": -4,
      "name": "Rock_Stone_Mossy"
    },
    {
      "x": 5,
      "y": -3,
      "z": -3,
      "name": "Rock_Stone"
    },
    {
      "x": 5,
      "y": -2,
      "z": -3,
      "name": "Rock_Stone"
    },
    {
      "x": 5,
      "y": -1,
      "z": -3,
      "name": "Rock_Stone"
    },
    {
      "x": 5,
      "y": 0,
      "z": -3,
      "name": "Rock_Stone"
    },
    {
      "x": 5,
      "y": 1,
      "z": -3,
      "name": "Rock_Stone"
    },
    {
      "x": 5,
      "y": 2,
      "z": -3,
      "name": "Rock_Stone_Mossy"
    },
    {
      "x": 5,
      "y": 3,
      "z": -3,
      "name": "Rock_Stone"
    },
    {
      "x": 5,
      "y": 4,
      "z": -3,
      "name": "Rock_Stone"
    },
    {
      "x": 5,
      "y": 5,
      "z": -3,
      "name": "Rock_Stone"
    },
    {
      "x": 5,
      "y": -3,
      "z": -2,
      "name": "Rock_Stone"
    },
    {
      "x": 5,
      "y": -2,
      "z": -2,
      "name": "Rock_Stone"
    },
    {
      "x": 5,
      "y": -1,
      "z": -2,
      "name": "Rock_Stone_Mossy"
    },
    {
      "x": 5,
      "y": 0,
      "z": -2,
      "name": "Rock_Stone_Mossy"
    },
    {
      "x": 5,
      "y": 1,
      "z": -2,
      "name": "Rock_Stone"
    },
    {
      "x": 5,
      "y": 2,
      "z": -2,
      "name": "Rock_Stone"
    },
    {
      "x": 5,
      "y": 3,
      "z": -2,
      "name": "Rock_Stone"
    },
    {
      "x": 5,
      "y": 4,
      "z": -2,
      "name": "Rock_Stone"
    },
    {
      "x": 5,
      "y": 5,
      "z": -2,
      "name": "Rock_Stone_Mossy"
    },
    {
      "x": 5,
      "y": 6,
      "z": -2,
      "name": "Rock_Stone"
    },
    {
      "x": 5,
      "y": -3,
      "z": -1,
      "name": "Rock_Stone"
    },
    {
      "x": 5,
      "y": -2,
      "z": -1,
      "name": "Rock_Stone"
    },
    {
      "x": 5,
      "y": -1,
      "z": -1,
      "name": "Rock_Stone"
    },
    {
      "x": 5,
      "y": 0,
      "z": -1,
      "name": "Rock_Stone"
    },
    {
      "x": 5,
      "y": 1,
      "z": -1,
      "name": "Rock_Stone"
    },
    {
      "x": 5,
      "y": 2,
      "z": -1,
      "name": "Rock_Stone"
    },
    {
      "x": 5,
      "y": 3,
      "z": -1,
      "name": "Rock_Stone_Mossy"
    },
    {
      "x": 5,
      "y": 4,
      "z": -1,
      "name": "Rock_Stone"
    },
    {
      "x": 5,
      "y": 5,
      "z": -1,
      "name": "Rock_Stone_Mossy"
    },
    {
      "x": 5,
      "y": 6,
      "z": -1,
      "name": "Rock_Stone"
    },
    {
      "x": 5,
      "y": 7,
      "z": -1,
      "name": "Rock_Stone"
    },
    {
      "x": 5,
      "y": -3,
      "z": 0,
      "name": "Rock_Stone"
    },
    {
      "x": 5,
      "y": -2,
      "z": 0,
      "name": "Rock_Stone"
    },
    {
      "x": 5,
      "y": -1,
      "z": 0,
      "name": "Rock_Stone"
    },
    {
      "x": 5,
      "y": 0,
      "z": 0,
      "name": "Rock_Stone"
    },
    {
      "x": 5,
      "y": 1,
      "z": 0,
      "name": "Rock_Stone"
    },
    {
      "x": 5,
      "y": 2,
      "z": 0,
      "name": "Rock_Stone"
    },
    {
      "x": 5,
      "y": 3,
      "z": 0,
      "name": "Rock_Stone"
    },
    {
      "x": 5,
      "y": 4,
      "z": 0,
      "name": "Rock_Stone"
    },
    {
      "x": 5,
      "y": 5,
      "z": 0,
      "name": "Rock_Stone"
    },
    {
      "x": 5,
      "y": 6,
      "z": 0,
      "name": "Rock_Stone"
    },
    {
      "x": 5,
      "y": 7,
      "z": 0,
      "name": "Rock_Stone_Mossy"
    },
    {
      "x": 5,
      "y": -3,
      "z": 1,
      "name": "Rock_Stone"
    },
    {
      "x": 5,
      "y": -2,
      "z": 1,
      "name": "Rock_Stone"
    },
    {
      "x": 5,
      "y": -1,
      "z": 1,
      "name": "Rock_Stone_Mossy"
    },
    {
      "x": 5,
      "y": 0,
      "z": 1,
      "name": "Rock_Stone"
    },
    {
      "x": 5,
      "y": 1,
      "z": 1,
      "name": "Rock_Stone"
    },
    {
      "x": 5,
      "y": 2,
      "z": 1,
      "name": "Rock_Stone"
    },
    {
      "x": 5,
      "y": 3,
      "z": 1,
      "name": "Rock_Stone"
    },
    {
      "x": 5,
      "y": 4,
      "z": 1,
      "name": "Rock_Stone"
    },
    {
      "x": 5,
      "y": 5,
      "z": 1,
      "name": "Rock_Stone"
    },
    {
      "x": 5,
      "y": 6,
      "z": 1,
      "name": "Rock_Stone"
    },
    {
      "x": 5,
      "y": 7,
      "z": 1,
      "name": "Rock_Stone"
    },
    {
      "x": 5,
      "y": -3,
      "z": 2,
      "name": "Rock_Stone"
    },
    {
      "x": 5,
      "y": -2,
      "z": 2,
      "name": "Rock_Stone"
    },
    {
      "x": 5,
      "y": -1,
      "z": 2,
      "name": "Rock_Stone"
    },
    {
      "x": 5,
      "y": 0,
      "z": 2,
      "name": "Rock_Stone"
    },
    {
      "x": 5,
      "y": 1,
      "z": 2,
      "name": "Rock_Stone"
    },
    {
      "x": 5,
      "y": 2,
      "z": 2,
      "name": "Rock_Stone_Mossy"
    },
    {
      "x": 5,
      "y": 3,
      "z": 2,
      "name": "Rock_Stone_Mossy"
    },
    {
      "x": 5,
      "y": 4,
      "z": 2,
      "name": "Rock_Stone"
    },
    {
      "x": 5,
      "y": 5,
      "z": 2,
      "name": "Rock_Stone"
    },
    {
      "x": 5,
      "y": 6,
      "z": 2,
      "name": "Rock_Stone_Mossy"
    },
    {
      "x": 5,
      "y": -3,
      "z": 3,
      "name": "Rock_Stone"
    },
    {
      "x": 5,
      "y": -2,
      "z": 3,
      "name": "Rock_Stone"
    },
    {
      "x": 5,
      "y": -1,
      "z": 3,
      "name": "Rock_Stone"
    },
    {
      "x": 5,
      "y": 0,
      "z": 3,
      "name": "Rock_Stone"
    },
    {
      "x": 5,
      "y": 1,
      "z": 3,
      "name": "Rock_Stone"
    },
    {
      "x": 5,
      "y": 2,
      "z": 3,
      "name": "Rock_Stone"
    },
    {
      "x": 5,
      "y": 3,
      "z": 3,
      "name": "Rock_Stone_Mossy"
    },
    {
      "x": 5,
      "y": 4,
      "z": 3,
      "name": "Rock_Stone"
    },
    {
      "x": 5,
      "y": 5,
      "z": 3,
      "name": "Rock_Stone"
    },
    {
      "x": 5,
      "y": -2,
      "z": 4,
      "name": "Rock_Stone"
    },
    {
      "x": 5,
      "y": -1,
      "z": 4,
      "name": "Rock_Stone"
    },
    {
      "x": 5,
      "y": 0,
      "z": 4,
      "name": "Rock_Stone"
    },
    {
      "x": 5,
      "y": 1,
      "z": 4,
      "name": "Rock_Stone"
    },
    {
      "x": 5,
      "y": 2,
      "z": 4,
      "name": "Rock_Stone"
    },
    {
      "x": 5,
      "y": 3,
      "z": 4,
      "name": "Rock_Stone"
    },
    {
      "x": 5,
      "y": 4,
      "z": 4,
      "name": "Rock_Stone"
    },
    {
      "x": 5,
      "y": -1,
      "z": 5,
      "name": "Rock_Stone_Mossy"
    },
    {
      "x": 5,
      "y": 0,
      "z": 5,
      "name": "Rock_Stone"
    },
    {
      "x": 5,
      "y": 1,
      "z": 5,
      "name": "Rock_Stone"
    },
    {
      "x": 5,
      "y": 2,
      "z": 5,
      "name": "Rock_Stone"
    },
    {
      "x": 5,
      "y": 3,
      "z": 5,
      "name": "Rock_Stone"
    }
  ],
  "fluids": [
    {
      "x": 0,
      "y": 0,
      "z": -1,
      "name": "Water_Source",
      "level": 1
    },
    {
      "x": 0,
      "y": 0,
      "z": 0,
      "name": "Water_Source",
      "level": 1
    },
    {
      "x": 0,
      "y": 0,
      "z": 1,
      "name": "Water_Source",
      "level": 1
    },
    {
      "x": 1,
      "y": 0,
      "z": -1,
      "name": "Water_Source",
      "level": 1
    },
    {
      "x": 1,
      "y": 0,
      "z": 0,
      "name": "Water_Source",
      "level": 1
    },
    {
      "x": 1,
      "y": 0,
      "z": 1,
      "name": "Water_Source",
      "level": 1
    },
    {
      "x": 2,
      "y": 0,
      "z": -1,
      "name": "Water_Source",
      "level": 1
    },
    {
      "x": 2,
      "y": 0,
      "z": 0,
      "name": "Water_Source",
      "level": 1
    },
    {
      "x": 2,
      "y": 0,
      "z": 1,
      "name": "Water_Source",
      "level": 1
    },
    {
      "x": 3,
      "y": 0,
      "z": -1,
      "name": "Water_Source",
      "level": 1
    },
    {
      "x": 3,
      "y": 0,
      "z": 0,
      "name": "Water_Source",
      "level": 1
    },
    {
      "x": 3,
      "y": 0,
      "z": 1,
      "name": "Water_Source",
      "level": 1
    },
    {
      "x": 4,
      "y": 0,
      "z": -1,
      "name": "Water_Source",
      "level": 1
    },
    {
      "x": 4,
      "y": 0,
      "z": 0,
      "name": "Water_Source",
      "level": 1
    },
    {
      "x": 4,
      "y": 0,
      "z": 1,
      "name": "Water_Source",
      "level": 1
    }
  ]
}