{
  "version": 8,
  "blockIdVersion": 11,
  "anchorX": 0,
  "anchorY": 0,
  "anchorZ": 0,
  "blocks": [
    {
      "x": -21,
      "y": 3,
      "z": 5,
      "name": "Furniture_Jungle_Platform",
      "rotation": 1
    },
    {
      "x": -21,
      "y": 4,
      "z": 5,
      "name": "Wood_Tropicalwood_Planks_Half",
      "rotation": 6
    },
    {
      "x": -21,
      "y": 3,
      "z": 6,
      "name": "Wood_Goldenwood_Planks_Half",
      "rotation": 8
    },
    {
      "x": -21,
      "y": 3,
      "z": 7,
      "name": "Wood_Goldenwood_Planks_Half",
      "rotation": 8
    },
    {
      "x": -21,
      "y": 3,
      "z": 8,
      "name": "Wood_Goldenwood_Planks_Half",
      "rotation": 8
    },
    {
      "x": -21,
      "y": 4,
      "z": 8,
      "name": "Wood_Tropicalwood_Fence",
      "rotation": 3
    },
    {
      "x": -21,
      "y": 5,
      "z": 8,
      "name": "Wood_Bamboo_Branch_Long_Deco"
    },
    {
      "x": -21,
      "y": 6,
      "z": 8,
      "name": "Wood_Tropicalwood_Roof",
      "rotation": 3
    },
    {
      "x": -21,
      "y": 3,
      "z": 9,
      "name": "Wood_Goldenwood_Planks_Half",
      "rotation": 8
    },
    {
      "x": -21,
      "y": 4,
      "z": 9,
      "name": "Wood_Tropicalwood_Fence",
      "rotation": 3
    },
    {
      "x": -21,
      "y": 6,
      "z": 9,
      "name": "Wood_Tropicalwood_Roof",
      "rotation": 3
    },
    {
      "x": -21,
      "y": 3,
      "z": 10,
      "name": "Furniture_Jungle_Platform"
    },
    {
      "x": -21,
      "y": 4,
      "z": 10,
      "name": "Wood_Tropicalwood_Fence",
      "rotation": 3
    },
    {
      "x": -21,
      "y": 6,
      "z": 10,
      "name": "Wood_Tropicalwood_Roof",
      "rotation": 3
    },
    {
      "x": -21,
      "y": 3,
      "z": 11,
      "name": "Furniture_Jungle_Platform"
    },
    {
      "x": -21,
      "y": 4,
      "z": 11,
      "name": "Wood_Tropicalwood_Fence",
      "rotation": 3
    },
    {
      "x": -21,
      "y": 5,
      "z": 11,
      "name": "Wood_Bamboo_Branch_Long_Deco"
    },
    {
      "x": -21,
      "y": 6,
      "z": 11,
      "name": "Wood_Tropicalwood_Roof",
      "rotation": 3
    },
    {
      "x": -21,
      "y": 5,
      "z": 12,
      "name": "Wood_Bamboo_Trunk_Deco",
      "rotation": 5
    },
    {
      "x": -21,
      "y": 6,
      "z": 12,
      "name": "Wood_Bamboo_Trunk_Deco"
    },
    {
      "x": -21,
      "y": 7,
      "z": 12,
      "name": "Furniture_Jungle_Candle"
    },
    {
      "x": -21,
      "y": 5,
      "z": 13,
      "name": "Wood_Goldenwood_Planks"
    },
    {
      "x": -21,
      "y": 5,
      "z": 14,
      "name": "Wood_Goldenwood_Planks"
    },
    {
      "x": -21,
      "y": 5,
      "z": 15,
      "name": "Wood_Goldenwood_Planks"
    },
    {
      "x": -21,
      "y": 5,
      "z": 16,
      "name": "Wood_Bamboo_Trunk_Deco",
      "rotation": 5
    },
    {
      "x": -21,
      "y": 6,
      "z": 16,
      "name": "Wood_Bamboo_Trunk_Deco"
    },
    {
      "x": -21,
      "y": 7,
      "z": 16,
      "name": "Furniture_Jungle_Candle"
    },
    {
      "x": -21,
      "y": 3,
      "z": 20,
      "name": "Plant_Moss_Rug_Green"
    },
    {
      "x": -20,
      "y": 3,
      "z": 5,
      "name": "Furniture_Jungle_Platform",
      "rotation": 1
    },
    {
      "x": -20,
      "y": 4,
      "z": 5,
      "name": "Wood_Tropicalwood_Planks_Half",
      "rotation": 6
    },
    {
      "x": -20,
      "y": 3,
      "z": 6,
      "name": "Wood_Goldenwood_Planks_Half",
      "rotation": 8
    },
    {
      "x": -20,
      "y": 4,
      "z": 6,
      "name": "Furniture_Jungle_Chair",
      "rotation": 3
    },
    {
      "x": -20,
      "y": 5,
      "z": 6,
      "name": "Furniture_Jungle_Chair",
      "filler": 1024,
      "rotation": 3
    },
    {
      "x": -20,
      "y": 3,
      "z": 7,
      "name": "Wood_Goldenwood_Planks_Half",
      "rotation": 8
    },
    {
      "x": -20,
      "y": 7,
      "z": 7,
      "name": "Plant_Vine_Hanging"
    },
    {
      "x": -20,
      "y": 8,
      "z": 7,
      "name": "*Wood_Tropicalwood_Roof_State_Definitions_Corner_Right",
      "rotation": 3
    },
    {
      "x": -20,
      "y": 9,
      "z": 7,
      "name": "Wood_Goldenwood_Planks_Half",
      "rotation": 8
    },
    {
      "x": -20,
      "y": 10,
      "z": 7,
      "name": "Wood_Goldenwood_Planks_Half"
    },
    {
      "x": -20,
      "y": -4,
      "z": 8,
      "name": "Wood_Bamboo_Trunk_Deco",
      "rotation": 5
    },
    {
      "x": -20,
      "y": 3,
      "z": 8,
      "name": "Wood_Goldenwood_Planks_Half",
      "rotation": 8
    },
    {
      "x": -20,
      "y": 5,
      "z": 8,
      "name": "Plant_Moss_Wall_Green",
      "rotation": 3
    },
    {
      "x": -20,
      "y": 6,
      "z": 8,
      "name": "Wood_Goldenwood_Stairs",
      "rotation": 11
    },
    {
      "x": -20,
      "y": 7,
      "z": 8,
      "name": "Wood_Tropicalwood_Roof",
      "rotation": 3
    },
    {
      "x": -20,
      "y": 8,
      "z": 8,
      "name": "Wood_Tropicalwood_Roof",
      "rotation": 3
    },
    {
      "x": -20,
      "y": 9,
      "z": 8,
      "name": "Wood_Goldenwood_Planks"
    },
    {
      "x": -20,
      "y": 3,
      "z": 9,
      "name": "Wood_Goldenwood_Planks_Half",
      "rotation": 8
    },
    {
      "x": -20,
      "y": 6,
      "z": 9,
      "name": "Wood_Goldenwood_Stairs",
      "rotation": 11
    },
    {
      "x": -20,
      "y": 7,
      "z": 9,
      "name": "Wood_Tropicalwood_Roof",
      "rotation": 3
    },
    {
      "x": -20,
      "y": 8,
      "z": 9,
      "name": "Wood_Tropicalwood_Roof",
      "rotation": 3
    },
    {
      "x": -20,
      "y": 9,
      "z": 9,
      "name": "Wood_Goldenwood_Planks"
    },
    {
      "x": -20,
      "y": 3,
      "z": 10,
      "name": "Wood_Goldenwood_Planks_Half",
      "rotation": 8
    },
    {
      "x": -20,
      "y": 6,
      "z": 10,
      "name": "Wood_Goldenwood_Stairs",
      "rotation": 11
    },
    {
      "x": -20,
      "y": 7,
      "z": 10,
      "name": "Wood_Tropicalwood_Roof",
      "rotation": 3
    },
    {
      "x": -20,
      "y": 9,
      "z": 10,
      "name": "Wood_Goldenwood_Planks_Half"
    },
    {
      "x": -20,
      "y": 3,
      "z": 11,
      "name": "Furniture_Jungle_Platform"
    },
    {
      "x": -20,
      "y": 6,
      "z": 11,
      "name": "Wood_Goldenwood_Stairs",
      "rotation": 11
    },
    {
      "x": -20,
      "y": 7,
      "z": 11,
      "name": "Wood_Tropicalwood_Roof",
      "rotation": 3
    },
    {
      "x": -20,
      "y": 9,
      "z": 11,
      "name": "Wood_Goldenwood_Planks_Half"
    },
    {
      "x": -20,
      "y": 3,
      "z": 12,
      "name": "Plant_Moss_Rug_Green"
    },
    {
      "x": -20,
      "y": 5,
      "z": 12,
      "name": "Wood_Bamboo_Trunk_Deco",
      "rotation": 5
    },
    {
      "x": -20,
      "y": 6,
      "z": 12,
      "name": "Deco_Rope",
      "rotation": 5
    },
    {
      "x": -20,
      "y": 7,
      "z": 12,
      "name": "Plant_Moss_Wall_Green",
      "rotation": 3
    },
    {
      "x": -20,
      "y": 8,
      "z": 12,
      "name": "Plant_Vine_Jungle",
      "components": {
        "Components": {
          "FarmingBlock": {}
        }
      },
      "rotation": 3
    },
    {
      "x": -20,
      "y": 9,
      "z": 12,
      "name": "Wood_Goldenwood_Planks"
    },
    {
      "x": -20,
      "y": 3,
      "z": 13,
      "name": "Plant_Flower_Water_Blue"
    },
    {
      "x": -20,
      "y": 5,
      "z": 13,
      "name": "Wood_Goldenwood_Planks"
    },
    {
      "x": -20,
      "y": 9,
      "z": 13,
      "name": "Wood_Goldenwood_Planks_Half",
      "rotation": 8
    },
    {
      "x": -20,
      "y": 10,
      "z": 13,
      "name": "Wood_Goldenwood_Planks_Half"
    },
    {
      "x": -20,
      "y": 5,
      "z": 14,
      "name": "Wood_Goldenwood_Planks"
    },
    {
      "x": -20,
      "y": 10,
      "z": 14,
      "name": "Wood_Goldenwood_Planks"
    },
    {
      "x": -20,
      "y": 5,
      "z": 15,
      "name": "Wood_Goldenwood_Planks"
    },
    {
      "x": -20,
      "y": 9,
      "z": 15,
      "name": "Wood_Goldenwood_Planks_Half",
      "rotation": 8
    },
    {
      "x": -20,
      "y": 10,
      "z": 15,
      "name": "Wood_Goldenwood_Planks_Half"
    },
    {
      "x": -20,
      "y": 5,
      "z": 16,
      "name": "Wood_Bamboo_Trunk_Deco",
      "rotation": 5
    },
    {
      "x": -20,
      "y": 6,
      "z": 16,
      "name": "Deco_Rope",
      "rotation": 5
    },
    {
      "x": -20,
      "y": 8,
      "z": 16,
      "name": "Plant_Moss_Wall_Green",
      "rotation": 3
    },
    {
      "x": -20,
      "y": 9,
      "z": 16,
      "name": "Wood_Goldenwood_Planks"
    },
    {
      "x": -20,
      "y": 8,
      "z": 17,
      "name": "Plant_Moss_Cave_Green",
      "rotation": 8
    },
    {
      "x": -20,
      "y": 9,
      "z": 17,
      "name": "Wood_Goldenwood_Planks_Half"
    },
    {
      "x": -20,
      "y": 9,
      "z": 18,
      "name": "Wood_Goldenwood_Planks_Half"
    },
    {
      "x": -20,
      "y": 9,
      "z": 19,
      "name": "Wood_Goldenwood_Planks"
    },
    {
      "x": -20,
      "y": -4,
      "z": 20,
      "name": "Wood_Bamboo_Trunk_Deco",
      "rotation": 5
    },
    {
      "x": -20,
      "y": 3,
      "z": 20,
      "name": "Plant_Moss_Rug_Green"
    },
    {
      "x": -20,
      "y": 7,
      "z": 20,
      "name": "Plant_Moss_Wall_Green",
      "rotation": 3
    },
    {
      "x": -20,
      "y": 8,
      "z": 20,
      "name": "Plant_Vine_Jungle",
      "components": {
        "Components": {
          "FarmingBlock": {}
        }
      },
      "rotation": 3
    },
    {
      "x": -20,
      "y": 9,
      "z": 20,
      "name": "Wood_Goldenwood_Planks"
    },
    {
      "x": -20,
      "y": 3,
      "z": 21,
      "name": "Plant_Moss_Rug_Green"
    },
    {
      "x": -20,
      "y": 9,
      "z": 21,
      "name": "Wood_Goldenwood_Planks_Half",
      "rotation": 8
    },
    {
      "x": -20,
      "y": 10,
      "z": 21,
      "name": "Wood_Goldenwood_Planks_Half"
    },
    {
      "x": -20,
      "y": 3,
      "z": 22,
      "name": "Plant_Moss_Rug_Green"
    },
    {
      "x": -19,
      "y": 3,
      "z": 5,
      "name": "Furniture_Jungle_Platform",
      "rotation": 1
    },
    {
      "x": -19,
      "y": 4,
      "z": 5,
      "name": "Wood_Tropicalwood_Planks_Half",
      "rotation": 6
    },
    {
      "x": -19,
      "y": 3,
      "z": 6,
      "name": "Furniture_Jungle_Platform",
      "rotation": 1
    },
    {
      "x": -19,
      "y": 4,
      "z": 6,
      "name": "Wood_Tropicalwood_Planks_Half",
      "rotation": 5
    },
    {
      "x": -19,
      "y": 3,
      "z": 7,
      "name": "Wood_Goldenwood_Planks_Half",
      "rotation": 8
    },
    {
      "x": -19,
      "y": 4,
      "z": 7,
      "name": "Wood_Goldenwood_Stairs",
      "rotation": 3
    },
    {
      "x": -19,
      "y": 5,
      "z": 7,
      "name": "Plant_Vine_Jungle",
      "components": {
        "Components": {
          "FarmingBlock": {}
        }
      },
      "rotation": 2
    },
    {
      "x": -19,
      "y": 6,
      "z": 7,
      "name": "Plant_Vine_Jungle",
      "components": {
        "Components": {
          "FarmingBlock": {}
        }
      },
      "rotation": 2
    },
    {
      "x": -19,
      "y": 7,
      "z": 7,
      "name": "Plant_Moss_Wall_Green",
      "rotation": 2
    },
    {
      "x": -19,
      "y": 8,
      "z": 7,
      "name": "Wood_Tropicalwood_Roof",
      "rotation": 2
    },
    {
      "x": -19,
      "y": 9,
      "z": 7,
      "name": "Wood_Goldenwood_Planks"
    },
    {
      "x": -19,
      "y": 10,
      "z": 7,
      "name": "Plant_Moss_Rug_Green"
    },
    {
      "x": -19,
      "y": -33,
      "z": 8,
      "name": "Wood_Bamboo_Branch_Long_Deco"
    },
    {
      "x": -19,
      "y": -32,
      "z": 8,
      "name": "Wood_Bamboo_Branch_Long_Deco"
    },
    {
      "x": -19,
      "y": -31,
      "z": 8,
      "name": "Wood_Bamboo_Branch_Long_Deco"
    },
    {
      "x": -19,
      "y": -30,
      "z": 8,
      "name": "Wood_Bamboo_Branch_Long_Deco"
    },
    {
      "x": -19,
      "y": -29,
      "z": 8,
      "name": "Wood_Bamboo_Branch_Long_Deco"
    },
    {
      "x": -19,
      "y": -28,
      "z": 8,
      "name": "Wood_Bamboo_Branch_Long_Deco"
    },
    {
      "x": -19,
      "y": -27,
      "z": 8,
      "name": "Wood_Bamboo_Branch_Long_Deco"
    },
    {
      "x": -19,
      "y": -26,
      "z": 8,
      "name": "Wood_Bamboo_Branch_Long_Deco"
    },
    {
      "x": -19,
      "y": -25,
      "z": 8,
      "name": "Wood_Bamboo_Branch_Long_Deco"
    },
    {
      "x": -19,
      "y": -24,
      "z": 8,
      "name": "Wood_Bamboo_Branch_Long_Deco"
    },
    {
      "x": -19,
      "y": -23,
      "z": 8,
      "name": "Wood_Bamboo_Branch_Long_Deco"
    },
    {
      "x": -19,
      "y": -22,
      "z": 8,
      "name": "Wood_Bamboo_Branch_Long_Deco"
    },
    {
      "x": -19,
      "y": -21,
      "z": 8,
      "name": "Wood_Bamboo_Branch_Long_Deco"
    },
    {
      "x": -19,
      "y": -20,
      "z": 8,
      "name": "Wood_Bamboo_Branch_Long_Deco"
    },
    {
      "x": -19,
      "y": -19,
      "z": 8,
      "name": "Wood_Bamboo_Branch_Long_Deco"
    },
    {
      "x": -19,
      "y": -18,
      "z": 8,
      "name": "Wood_Bamboo_Branch_Long_Deco"
    },
    {
      "x": -19,
      "y": -17,
      "z": 8,
      "name": "Wood_Bamboo_Branch_Long_Deco"
    },
    {
      "x": -19,
      "y": -16,
      "z": 8,
      "name": "Wood_Bamboo_Branch_Long_Deco"
    },
    {
      "x": -19,
      "y": -15,
      "z": 8,
      "name": "Wood_Bamboo_Branch_Long_Deco"
    },
    {
      "x": -19,
      "y": -14,
      "z": 8,
      "name": "Wood_Bamboo_Branch_Long_Deco"
    },
    {
      "x": -19,
      "y": -13,
      "z": 8,
      "name": "Wood_Bamboo_Branch_Long_Deco"
    },
    {
      "x": -19,
      "y": -12,
      "z": 8,
      "name": "Wood_Bamboo_Branch_Long_Deco"
    },
    {
      "x": -19,
      "y": -11,
      "z": 8,
      "name": "Wood_Bamboo_Branch_Long_Deco"
    },
    {
      "x": -19,
      "y": -10,
      "z": 8,
      "name": "Wood_Bamboo_Branch_Long_Deco"
    },
    {
      "x": -19,
      "y": -9,
      "z": 8,
      "name": "Wood_Bamboo_Branch_Long_Deco"
    },
    {
      "x": -19,
      "y": -8,
      "z": 8,
      "name": "Wood_Bamboo_Branch_Long_Deco"
    },
    {
      "x": -19,
      "y": -7,
      "z": 8,
      "name": "Wood_Bamboo_Branch_Long_Deco"
    },
    {
      "x": -19,
      "y": -6,
      "z": 8,
      "name": "Wood_Bamboo_Branch_Long_Deco"
    },
    {
      "x": -19,
      "y": -5,
      "z": 8,
      "name": "Wood_Bamboo_Branch_Long_Deco"
    },
    {
      "x": -19,
      "y": -4,
      "z": 8,
      "name": "Wood_Bamboo_Trunk_Deco",
      "rotation": 5
    },
    {
      "x": -19,
      "y": -3,
      "z": 8,
      "name": "Wood_Bamboo_Trunk_Deco"
    },
    {
      "x": -19,
      "y": -2,
      "z": 8,
      "name": "Wood_Bamboo_Trunk_Deco"
    },
    {
      "x": -19,
      "y": -1,
      "z": 8,
      "name": "Wood_Bamboo_Trunk_Deco"
    },
    {
      "x": -19,
      "y": 0,
      "z": 8,
      "name": "Wood_Bamboo_Trunk_Deco"
    },
    {
      "x": -19,
      "y": 1,
      "z": 8,
      "name": "Wood_Bamboo_Trunk_Deco"
    },
    {
      "x": -19,
      "y": 2,
      "z": 8,
      "name": "Wood_Bamboo_Trunk_Deco"
    },
    {
      "x": -19,
      "y": 3,
      "z": 8,
      "name": "Wood_Bamboo_Trunk_Deco"
    },
    {
      "x": -19,
      "y": 4,
      "z": 8,
      "name": "Wood_Bamboo_Trunk_Deco"
    },
    {
      "x": -19,
      "y": 5,
      "z": 8,
      "name": "Wood_Bamboo_Trunk_Deco"
    },
    {
      "x": -19,
      "y": 6,
      "z": 8,
      "name": "Wood_Bamboo_Trunk_Deco"
    },
    {
      "x": -19,
      "y": 7,
      "z": 8,
      "name": "Wood_Bamboo_Trunk_Deco"
    },
    {
      "x": -19,
      "y": 8,
      "z": 8,
      "name": "Wood_Bamboo_Trunk_Deco"
    },
    {
      "x": -19,
      "y": 9,
      "z": 8,
      "name": "Wood_Goldenwood_Planks"
    },
    {
      "x": -19,
      "y": 10,
      "z": 8,
      "name": "Wood_Goldenwood_Planks_Half"
    },
    {
      "x": -19,
      "y": -4,
      "z": 9,
      "name": "Wood_Bamboo_Trunk_Deco",
      "rotation": 4
    },
    {
      "x": -19,
      "y": 3,
      "z": 9,
      "name": "Plant_Moss_Rug_Green"
    },
    {
      "x": -19,
      "y": 4,
      "z": 9,
      "name": "Wood_Bamboo_Trunk_Deco",
      "rotation": 5
    },
    {
      "x": -19,
      "y": 5,
      "z": 9,
      "name": "Wood_Goldenwood_Planks"
    },
    {
      "x": -19,
      "y": 6,
      "z": 9,
      "name": "Wood_Tropicalwood_Planks_Half",
      "rotation": 7
    },
    {
      "x": -19,
      "y": 7,
      "z": 9,
      "name": "Wood_Tropicalwood_Planks_Half",
      "rotation": 7
    },
    {
      "x": -19,
      "y": 8,
      "z": 9,
      "name": "Wood_Tropicalwood_Stairs",
      "rotation": 9
    },
    {
      "x": -19,
      "y": 9,
      "z": 9,
      "name": "Wood_Tropicalwood_Roof",
      "rotation": 3
    },
    {
      "x": -19,
      "y": -4,
      "z": 10,
      "name": "Wood_Bamboo_Trunk_Deco",
      "rotation": 4
    },
    {
      "x": -19,
      "y": 3,
      "z": 10,
      "name": "Plant_Moss_Rug_Green"
    },
    {
      "x": -19,
      "y": 4,
      "z": 10,
      "name": "Wood_Bamboo_Branch_Long_Deco",
      "rotation": 4
    },
    {
      "x": -19,
      "y": 5,
      "z": 10,
      "name": "Wood_Goldenwood_Planks"
    },
    {
      "x": -19,
      "y": 6,
      "z": 10,
      "name": "Wood_Tropicalwood_Planks_Half",
      "rotation": 7
    },
    {
      "x": -19,
      "y": 7,
      "z": 10,
      "name": "Wood_Tropicalwood_Planks_Half",
      "rotation": 7
    },
    {
      "x": -19,
      "y": 8,
      "z": 10,
      "name": "Wood_Tropicalwood_Stairs",
      "rotation": 9
    },
    {
      "x": -19,
      "y": 9,
      "z": 10,
      "name": "Wood_Tropicalwood_Roof",
      "rotation": 3
    },
    {
      "x": -19,
      "y": -4,
      "z": 11,
      "name": "Wood_Bamboo_Trunk_Deco",
      "rotation": 4
    },
    {
      "x": -19,
      "y": 3,
      "z": 11,
      "name": "Plant_Moss_Rug_Green"
    },
    {
      "x": -19,
      "y": 4,
      "z": 11,
      "name": "Wood_Bamboo_Branch_Long_Deco",
      "rotation": 4
    },
    {
      "x": -19,
      "y": 5,
      "z": 11,
      "name": "Wood_Goldenwood_Planks"
    },
    {
      "x": -19,
      "y": 6,
      "z": 11,
      "name": "Wood_Tropicalwood_Planks_Half",
      "rotation": 7
    },
    {
      "x": -19,
      "y": 7,
      "z": 11,
      "name": "Wood_Tropicalwood_Planks_Half",
      "rotation": 7
    },
    {
      "x": -19,
      "y": 8,
      "z": 11,
      "name": "Wood_Tropicalwood_Stairs",
      "rotation": 9
    },
    {
      "x": -19,
      "y": 9,
      "z": 11,
      "name": "Wood_Tropicalwood_Roof",
      "rotation": 3
    },
    {
      "x": -19,
      "y": -4,
      "z": 12,
      "name": "Wood_Bamboo_Trunk_Deco",
      "rotation": 4
    },
    {
      "x": -19,
      "y": 3,
      "z": 12,
      "name": "Plant_Moss_Rug_Green"
    },
    {
      "x": -19,
      "y": 4,
      "z": 12,
      "name": "Wood_Bamboo_Branch_Long_Deco",
      "rotation": 4
    },
    {
      "x": -19,
      "y": 5,
      "z": 12,
      "name": "Wood_Bamboo_Trunk_Deco",
      "rotation": 5
    },
    {
      "x": -19,
      "y": 6,
      "z": 12,
      "name": "Wood_Bamboo_Trunk_Deco"
    },
    {
      "x": -19,
      "y": 7,
      "z": 12,
      "name": "Wood_Bamboo_Trunk_Deco"
    },
    {
      "x": -19,
      "y": 8,
      "z": 12,
      "name": "Wood_Bamboo_Trunk_Deco"
    },
    {
      "x": -19,
      "y": 9,
      "z": 12,
      "name": "Wood_Goldenwood_Planks"
    },
    {
      "x": -19,
      "y": -4,
      "z": 13,
      "name": "Wood_Bamboo_Trunk_Deco",
      "rotation": 4
    },
    {
      "x": -19,
      "y": 3,
      "z": 13,
      "name": "Plant_Moss_Rug_Green"
    },
    {
      "x": -19,
      "y": 4,
      "z": 13,
      "name": "Wood_Bamboo_Branch_Long_Deco",
      "rotation": 4
    },
    {
      "x": -19,
      "y": 5,
      "z": 13,
      "name": "Wood_Goldenwood_Planks"
    },
    {
      "x": -19,
      "y": 6,
      "z": 13,
      "name": "Wood_Goldenwood_Stairs"
    },
    {
      "x": -19,
      "y": 7,
      "z": 13,
      "name": "Empty"
    },
    {
      "x": -19,
      "y": 8,
      "z": 13,
      "name": "Plant_Moss_Wall_Green"
    },
    {
      "x": -19,
      "y": 9,
      "z": 13,
      "name": "Wood_Goldenwood_Stairs",
      "rotation": 10
    },
    {
      "x": -19,
      "y": 10,
      "z": 13,
      "name": "Wood_Goldenwood_Planks_Half"
    },
    {
      "x": -19,
      "y": -4,
      "z": 14,
      "name": "Wood_Bamboo_Trunk_Deco",
      "rotation": 4
    },
    {
      "x": -19,
      "y": 4,
      "z": 14,
      "name": "Wood_Bamboo_Branch_Long_Deco",
      "rotation": 4
    },
    {
      "x": -19,
      "y": 5,
      "z": 14,
      "name": "Wood_Goldenwood_Planks"
    },
    {
      "x": -19,
      "y": 6,
      "z": 14,
      "name": "Empty"
    },
    {
      "x": -19,
      "y": 7,
      "z": 14,
      "name": "Empty"
    },
    {
      "x": -19,
      "y": 8,
      "z": 14,
      "name": "Empty"
    },
    {
      "x": -19,
      "y": 9,
      "z": 14,
      "name": "Empty"
    },
    {
      "x": -19,
      "y": 10,
      "z": 14,
      "name": "Wood_Goldenwood_Planks"
    },
    {
      "x": -19,
      "y": -4,
      "z": 15,
      "name": "Wood_Bamboo_Trunk_Deco",
      "rotation": 4
    },
    {
      "x": -19,
      "y": 4,
      "z": 15,
      "name": "Wood_Bamboo_Branch_Long_Deco",
      "rotation": 4
    },
    {
      "x": -19,
      "y": 5,
      "z": 15,
      "name": "Wood_Goldenwood_Planks"
    },
    {
      "x": -19,
      "y": 6,
      "z": 15,
      "name": "Wood_Goldenwood_Stairs",
      "rotation": 2
    },
    {
      "x": -19,
      "y": 7,
      "z": 15,
      "name": "Empty"
    },
    {
      "x": -19,
      "y": 8,
      "z": 15,
      "name": "Empty"
    },
    {
      "x": -19,
      "y": 9,
      "z": 15,
      "name": "Wood_Goldenwood_Stairs",
      "rotation": 8
    },
    {
      "x": -19,
      "y": 10,
      "z": 15,
      "name": "Wood_Goldenwood_Planks_Half"
    },
    {
      "x": -19,
      "y": -4,
      "z": 16,
      "name": "Wood_Bamboo_Trunk_Deco",
      "rotation": 4
    },
    {
      "x": -19,
      "y": 4,
      "z": 16,
      "name": "Wood_Bamboo_Branch_Long_Deco",
      "rotation": 4
    },
    {
      "x": -19,
      "y": 5,
      "z": 16,
      "name": "Wood_Bamboo_Trunk_Deco",
      "rotation": 5
    },
    {
      "x": -19,
      "y": 6,
      "z": 16,
      "name": "Wood_Bamboo_Trunk_Deco"
    },
    {
      "x": -19,
      "y": 7,
      "z": 16,
      "name": "Wood_Bamboo_Trunk_Deco"
    },
    {
      "x": -19,
      "y": 8,
      "z": 16,
      "name": "Wood_Bamboo_Trunk_Deco"
    },
    {
      "x": -19,
      "y": 9,
      "z": 16,
      "name": "Wood_Goldenwood_Planks"
    },
    {
      "x": -19,
      "y": -4,
      "z": 17,
      "name": "Wood_Bamboo_Trunk_Deco",
      "rotation": 4
    },
    {
      "x": -19,
      "y": 4,
      "z": 17,
      "name": "Wood_Bamboo_Branch_Long_Deco",
      "rotation": 4
    },
    {
      "x": -19,
      "y": 5,
      "z": 17,
      "name": "Wood_Goldenwood_Planks"
    },
    {
      "x": -19,
      "y": 6,
      "z": 17,
      "name": "Wood_Tropicalwood_Planks_Half",
      "rotation": 7
    },
    {
      "x": -19,
      "y": 7,
      "z": 17,
      "name": "Wood_Tropicalwood_Planks_Half",
      "rotation": 7
    },
    {
      "x": -19,
      "y": 8,
      "z": 17,
      "name": "Wood_Tropicalwood_Stairs",
      "rotation": 9
    },
    {
      "x": -19,
      "y": 9,
      "z": 17,
      "name": "Wood_Tropicalwood_Roof",
      "rotation": 3
    },
    {
      "x": -19,
      "y": -4,
      "z": 18,
      "name": "Wood_Bamboo_Trunk_Deco",
      "rotation": 4
    },
    {
      "x": -19,
      "y": 4,
      "z": 18,
      "name": "Wood_Bamboo_Branch_Long_Deco",
      "rotation": 4
    },
    {
      "x": -19,
      "y": 5,
      "z": 18,
      "name": "Wood_Goldenwood_Planks"
    },
    {
      "x": -19,
      "y": 6,
      "z": 18,
      "name": "Wood_Tropicalwood_Planks_Half",
      "rotation": 7
    },
    {
      "x": -19,
      "y": 7,
      "z": 18,
      "name": "Wood_Tropicalwood_Planks_Half",
      "rotation": 7
    },
    {
      "x": -19,
      "y": 8,
      "z": 18,
      "name": "Wood_Tropicalwood_Stairs",
      "rotation": 9
    },
    {
      "x": -19,
      "y": 9,
      "z": 18,
      "name": "Wood_Tropicalwood_Roof",
      "rotation": 3
    },
    {
      "x": -19,
      "y": -4,
      "z": 19,
      "name": "Wood_Bamboo_Trunk_Deco",
      "rotation": 4
    },
    {
      "x": -19,
      "y": 4,
      "z": 19,
      "name": "Wood_Bamboo_Trunk_Deco",
      "rotation": 5
    },
    {
      "x": -19,
      "y": 5,
      "z": 19,
      "name": "Wood_Goldenwood_Planks"
    },
    {
      "x": -19,
      "y": 6,
      "z": 19,
      "name": "Wood_Tropicalwood_Planks_Half",
      "rotation": 7
    },
    {
      "x": -19,
      "y": 7,
      "z": 19,
      "name": "Wood_Tropicalwood_Planks_Half",
      "rotation": 7
    },
    {
      "x": -19,
      "y": 8,
      "z": 19,
      "name": "Wood_Tropicalwood_Stairs",
      "rotation": 9
    },
    {
      "x": -19,
      "y": 9,
      "z": 19,
      "name": "Wood_Tropicalwood_Roof",
      "rotation": 3
    },
    {
      "x": -19,
      "y": -33,
      "z": 20,
      "name": "Wood_Bamboo_Branch_Long_Deco"
    },
    {
      "x": -19,
      "y": -32,
      "z": 20,
      "name": "Wood_Bamboo_Branch_Long_Deco"
    },
    {
      "x": -19,
      "y": -31,
      "z": 20,
      "name": "Wood_Bamboo_Branch_Long_Deco"
    },
    {
      "x": -19,
      "y": -30,
      "z": 20,
      "name": "Wood_Bamboo_Branch_Long_Deco"
    },
    {
      "x": -19,
      "y": -29,
      "z": 20,
      "name": "Wood_Bamboo_Branch_Long_Deco"
    },
    {
      "x": -19,
      "y": -28,
      "z": 20,
      "name": "Wood_Bamboo_Branch_Long_Deco"
    },
    {
      "x": -19,
      "y": -27,
      "z": 20,
      "name": "Wood_Bamboo_Branch_Long_Deco"
    },
    {
      "x": -19,
      "y": -26,
      "z": 20,
      "name": "Wood_Bamboo_Branch_Long_Deco"
    },
    {
      "x": -19,
      "y": -25,
      "z": 20,
      "name": "Wood_Bamboo_Branch_Long_Deco"
    },
    {
      "x": -19,
      "y": -24,
      "z": 20,
      "name": "Wood_Bamboo_Branch_Long_Deco"
    },
    {
      "x": -19,
      "y": -23,
      "z": 20,
      "name": "Wood_Bamboo_Branch_Long_Deco"
    },
    {
      "x": -19,
      "y": -22,
      "z": 20,
      "name": "Wood_Bamboo_Branch_Long_Deco"
    },
    {
      "x": -19,
      "y": -21,
      "z": 20,
      "name": "Wood_Bamboo_Branch_Long_Deco"
    },
    {
      "x": -19,
      "y": -20,
      "z": 20,
      "name": "Wood_Bamboo_Branch_Long_Deco"
    },
    {
      "x": -19,
      "y": -19,
      "z": 20,
      "name": "Wood_Bamboo_Branch_Long_Deco"
    },
    {
      "x": -19,
      "y": -18,
      "z": 20,
      "name": "Wood_Bamboo_Branch_Long_Deco"
    },
    {
      "x": -19,
      "y": -17,
      "z": 20,
      "name": "Wood_Bamboo_Branch_Long_Deco"
    },
    {
      "x": -19,
      "y": -16,
      "z": 20,
      "name": "Wood_Bamboo_Branch_Long_Deco"
    },
    {
      "x": -19,
      "y": -15,
      "z": 20,
      "name": "Wood_Bamboo_Branch_Long_Deco"
    },
    {
      "x": -19,
      "y": -14,
      "z": 20,
      "name": "Wood_Bamboo_Branch_Long_Deco"
    },
    {
      "x": -19,
      "y": -13,
      "z": 20,
      "name": "Wood_Bamboo_Branch_Long_Deco"
    },
    {
      "x": -19,
      "y": -12,
      "z": 20,
      "name": "Wood_Bamboo_Branch_Long_Deco"
    },
    {
      "x": -19,
      "y": -11,
      "z": 20,
      "name": "Wood_Bamboo_Branch_Long_Deco"
    },
    {
      "x": -19,
      "y": -10,
      "z": 20,
      "name": "Wood_Bamboo_Branch_Long_Deco"
    },
    {
      "x": -19,
      "y": -9,
      "z": 20,
      "name": "Wood_Bamboo_Branch_Long_Deco"
    },
    {
      "x": -19,
      "y": -8,
      "z": 20,
      "name": "Wood_Bamboo_Branch_Long_Deco"
    },
    {
      "x": -19,
      "y": -7,
      "z": 20,
      "name": "Wood_Bamboo_Branch_Long_Deco"
    },
    {
      "x": -19,
      "y": -6,
      "z": 20,
      "name": "Wood_Bamboo_Branch_Long_Deco"
    },
    {
      "x": -19,
      "y": -5,
      "z": 20,
      "name": "Wood_Bamboo_Branch_Long_Deco"
    },
    {
      "x": -19,
      "y": -4,
      "z": 20,
      "name": "Wood_Bamboo_Trunk_Deco",
      "rotation": 5
    },
    {
      "x": -19,
      "y": -3,
      "z": 20,
      "name": "Wood_Bamboo_Trunk_Deco"
    },
    {
      "x": -19,
      "y": -2,
      "z": 20,
      "name": "Wood_Bamboo_Trunk_Deco"
    },
    {
      "x": -19,
      "y": -1,
      "z": 20,
      "name": "Wood_Bamboo_Trunk_Deco"
    },
    {
      "x": -19,
      "y": 0,
      "z": 20,
      "name": "Wood_Bamboo_Trunk_Deco"
    },
    {
      "x": -19,
      "y": 1,
      "z": 20,
      "name": "Wood_Bamboo_Trunk_Deco"
    },
    {
      "x": -19,
      "y": 2,
      "z": 20,
      "name": "Wood_Bamboo_Trunk_Deco"
    },
    {
      "x": -19,
      "y": 3,
      "z": 20,
      "name": "Wood_Bamboo_Trunk_Deco"
    },
    {
      "x": -19,
      "y": 4,
      "z": 20,
      "name": "Wood_Bamboo_Trunk_Deco"
    },
    {
      "x": -19,
      "y": 5,
      "z": 20,
      "name": "Wood_Bamboo_Trunk_Deco"
    },
    {
      "x": -19,
      "y": 6,
      "z": 20,
      "name": "Wood_Bamboo_Trunk_Deco"
    },
    {
      "x": -19,
      "y": 7,
      "z": 20,
      "name": "Wood_Bamboo_Trunk_Deco"
    },
    {
      "x": -19,
      "y": 8,
      "z": 20,
      "name": "Wood_Bamboo_Trunk_Deco"
    },
    {
      "x": -19,
      "y": 9,
      "z": 20,
      "name": "Wood_Goldenwood_Planks"
    },
    {
      "x": -19,
      "y": 10,
      "z": 20,
      "name": "Wood_Goldenwood_Planks_Half"
    },
    {
      "x": -19,
      "y": 3,
      "z": 21,
      "name": "Plant_Moss_Rug_Green"
    },
    {
      "x": -19,
      "y": 5,
      "z": 21,
      "name": "Furniture_Jungle_Platform",
      "rotation": 1
    },
    {
      "x": -19,
      "y": 6,
      "z": 21,
      "name": "Wood_Tropicalwood_Planks_Half",
      "rotation": 7
    },
    {
      "x": -19,
      "y": 7,
      "z": 21,
      "name": "Plant_Moss_Cave_Green",
      "rotation": 8
    },
    {
      "x": -19,
      "y": 8,
      "z": 21,
      "name": "Wood_Tropicalwood_Roof"
    },
    {
      "x": -19,
      "y": 9,
      "z": 21,
      "name": "Wood_Goldenwood_Planks"
    },
    {
      "x": -19,
      "y": 10,
      "z": 21,
      "name": "Plant_Moss_Rug_Green"
    },
    {
      "x": -19,
      "y": 3,
      "z": 22,
      "name": "Plant_Flower_Water_Blue"
    },
    {
      "x": -19,
      "y": 5,
      "z": 22,
      "name": "Furniture_Jungle_Platform",
      "rotation": 1
    },
    {
      "x": -19,
      "y": 6,
      "z": 22,
      "name": "Wood_Tropicalwood_Planks_Half",
      "rotation": 4
    },
    {
      "x": -19,
      "y": 7,
      "z": 22,
      "name": "Wood_Bamboo_Branch_Long_Deco"
    },
    {
      "x": -19,
      "y": 8,
      "z": 22,
      "name": "Wood_Tropicalwood_Roof_Flat"
    },
    {
      "x": -18,
      "y": 3,
      "z": -1,
      "name": "Plant_Flower_Water_Green"
    },
    {
      "x": -18,
      "y": 9,
      "z": -1,
      "name": "Wood_Greenwood_Roof_Hollow",
      "rotation": 2
    },
    {
      "x": -18,
      "y": 3,
      "z": 0,
      "name": "Plant_Moss_Rug_Green"
    },
    {
      "x": -18,
      "y": 10,
      "z": 0,
      "name": "Wood_Greenwood_Roof_Flat"
    },
    {
      "x": -18,
      "y": 9,
      "z": 1,
      "name": "Wood_Greenwood_Roof_Hollow"
    },
    {
      "x": -18,
      "y": 5,
      "z": 6,
      "name": "Wood_Goldenwood_Planks_Half",
      "rotation": 8
    },
    {
      "x": -18,
      "y": 6,
      "z": 6,
      "name": "Wood_Tropicalwood_Fence",
      "rotation": 2
    },
    {
      "x": -18,
      "y": 8,
      "z": 6,
      "name": "Wood_Tropicalwood_Roof",
      "rotation": 2
    },
    {
      "x": -18,
      "y": 4,
      "z": 7,
      "name": "Wood_Goldenwood_Stairs",
      "rotation": 11
    },
    {
      "x": -18,
      "y": 5,
      "z": 7,
      "name": "Wood_Goldenwood_Stairs",
      "rotation": 3
    },
    {
      "x": -18,
      "y": 8,
      "z": 7,
      "name": "Wood_Goldenwood_Stairs",
      "rotation": 11
    },
    {
      "x": -18,
      "y": 9,
      "z": 7,
      "name": "Wood_Goldenwood_Planks"
    },
    {
      "x": -18,
      "y": -4,
      "z": 8,
      "name": "Wood_Bamboo_Trunk_Deco",
      "rotation": 5
    },
    {
      "x": -18,
      "y": 1,
      "z": 8,
      "name": "Wood_Bamboo_Branch_Long_Deco",
      "rotation": 5
    },
    {
      "x": -18,
      "y": 5,
      "z": 8,
      "name": "Wood_Goldenwood_Planks"
    },
    {
      "x": -18,
      "y": 6,
      "z": 8,
      "name": "Wood_Tropicalwood_Planks_Half",
      "rotation": 6
    },
    {
      "x": -18,
      "y": 7,
      "z": 8,
      "name": "Wood_Tropicalwood_Planks_Half",
      "rotation": 6
    },
    {
      "x": -18,
      "y": 8,
      "z": 8,
      "name": "Wood_Tropicalwood_Stairs",
      "rotation": 8
    },
    {
      "x": -18,
      "y": 9,
      "z": 8,
      "name": "Wood_Tropicalwood_Roof",
      "rotation": 2
    },
    {
      "x": -18,
      "y": 3,
      "z": 9,
      "name": "Plant_Moss_Rug_Green"
    },
    {
      "x": -18,
      "y": 4,
      "z": 9,
      "name": "Wood_Bamboo_Trunk_Deco",
      "rotation": 5
    },
    {
      "x": -18,
      "y": 5,
      "z": 9,
      "name": "Wood_Goldenwood_Planks"
    },
    {
      "x": -18,
      "y": 6,
      "z": 9,
      "name": "Empty"
    },
    {
      "x": -18,
      "y": 7,
      "z": 9,
      "name": "Empty"
    },
    {
      "x": -18,
      "y": 8,
      "z": 9,
      "name": "Empty"
    },
    {
      "x": -18,
      "y": 9,
      "z": 9,
      "name": "Wood_Goldenwood_Planks"
    },
    {
      "x": -18,
      "y": 10,
      "z": 9,
      "name": "Wood_Goldenwood_Decorative"
    },
    {
      "x": -18,
      "y": 11,
      "z": 9,
      "name": "Wood_Goldenwood_Planks_Half"
    },
    {
      "x": -18,
      "y": 3,
      "z": 10,
      "name": "Plant_Moss_Rug_Green"
    },
    {
      "x": -18,
      "y": 5,
      "z": 10,
      "name": "Wood_Goldenwood_Planks"
    },
    {
      "x": -18,
      "y": 6,
      "z": 10,
      "name": "Empty"
    },
    {
      "x": -18,
      "y": 7,
      "z": 10,
      "name": "Empty"
    },
    {
      "x": -18,
      "y": 8,
      "z": 10,
      "name": "Empty"
    },
    {
      "x": -18,
      "y": 9,
      "z": 10,
      "name": "Wood_Goldenwood_Planks"
    },
    {
      "x": -18,
      "y": 10,
      "z": 10,
      "name": "Wood_Goldenwood_Decorative"
    },
    {
      "x": -18,
      "y": 11,
      "z": 10,
      "name": "Wood_Goldenwood_Planks"
    },
    {
      "x": -18,
      "y": 5,
      "z": 11,
      "name": "Wood_Goldenwood_Planks"
    },
    {
      "x": -18,
      "y": 6,
      "z": 11,
      "name": "Empty"
    },
    {
      "x": -18,
      "y": 7,
      "z": 11,
      "name": "Empty"
    },
    {
      "x": -18,
      "y": 8,
      "z": 11,
      "name": "Empty"
    },
    {
      "x": -18,
      "y": 9,
      "z": 11,
      "name": "Wood_Goldenwood_Planks"
    },
    {
      "x": -18,
      "y": 10,
      "z": 11,
      "name": "Wood_Goldenwood_Decorative"
    },
    {
      "x": -18,
      "y": 11,
      "z": 11,
      "name": "Wood_Goldenwood_Planks_Half",
      "rotation": 8
    },
    {
      "x": -18,
      "y": 12,
      "z": 11,
      "name": "Wood_Goldenwood_Planks_Half"
    },
    {
      "x": -18,
      "y": 5,
      "z": 12,
      "name": "Wood_Goldenwood_Planks"
    },
    {
      "x": -18,
      "y": 6,
      "z": 12,
      "name": "Empty"
    },
    {
      "x": -18,
      "y": 7,
      "z": 12,
      "name": "Empty"
    },
    {
      "x": -18,
      "y": 8,
      "z": 12,
      "name": "Empty"
    },
    {
      "x": -18,
      "y": 9,
      "z": 12,
      "name": "Wood_Goldenwood_Planks"
    },
    {
      "x": -18,
      "y": 10,
      "z": 12,
      "name": "Wood_Goldenwood_Decorative"
    },
    {
      "x": -18,
      "y": 12,
      "z": 12,
      "name": "Wood_Goldenwood_Planks"
    },
    {
      "x": -18,
      "y": 5,
      "z": 13,
      "name": "Wood_Goldenwood_Planks"
    },
    {
      "x": -18,
      "y": 6,
      "z": 13,
      "name": "Empty"
    },
    {
      "x": -18,
      "y": 7,
      "z": 13,
      "name": "Empty"
    },
    {
      "x": -18,
      "y": 8,
      "z": 13,
      "name": "Empty"
    },
    {
      "x": -18,
      "y": 9,
      "z": 13,
      "name": "Wood_Goldenwood_Planks_Half",
      "rotation": 8
    },
    {
      "x": -18,
      "y": 10,
      "z": 13,
      "name": "Wood_Goldenwood_Decorative"
    },
    {
      "x": -18,
      "y": 12,
      "z": 13,
      "name": "Wood_Goldenwood_Planks_Half",
      "rotation": 8
    },
    {
      "x": -18,
      "y": 13,
      "z": 13,
      "name": "Wood_Goldenwood_Stairs",
      "rotation": 2
    },
    {
      "x": -18,
      "y": 5,
      "z": 14,
      "name": "Wood_Goldenwood_Planks"
    },
    {
      "x": -18,
      "y": 6,
      "z": 14,
      "name": "Empty"
    },
    {
      "x": -18,
      "y": 7,
      "z": 14,
      "name": "Empty"
    },
    {
      "x": -18,
      "y": 8,
      "z": 14,
      "name": "Empty"
    },
    {
      "x": -18,
      "y": 9,
      "z": 14,
      "name": "Empty"
    },
    {
      "x": -18,
      "y": 10,
      "z": 14,
      "name": "Wood_Goldenwood_Decorative"
    },
    {
      "x": -18,
      "y": 13,
      "z": 14,
      "name": "Wood_Goldenwood_Planks"
    },
    {
      "x": -18,
      "y": 14,
      "z": 14,
      "name": "Wood_Goldenwood_Planks_Half"
    },
    {
      "x": -18,
      "y": 5,
      "z": 15,
      "name": "Wood_Goldenwood_Planks"
    },
    {
      "x": -18,
      "y": 6,
      "z": 15,
      "name": "Empty"
    },
    {
      "x": -18,
      "y": 7,
      "z": 15,
      "name": "Empty"
    },
    {
      "x": -18,
      "y": 8,
      "z": 15,
      "name": "Empty"
    },
    {
      "x": -18,
      "y": 9,
      "z": 15,
      "name": "Wood_Goldenwood_Planks_Half",
      "rotation": 8
    },
    {
      "x": -18,
      "y": 10,
      "z": 15,
      "name": "Wood_Goldenwood_Decorative"
    },
    {
      "x": -18,
      "y": 12,
      "z": 15,
      "name": "Wood_Goldenwood_Planks_Half",
      "rotation": 8
    },
    {
      "x": -18,
      "y": 13,
      "z": 15,
      "name": "Wood_Goldenwood_Stairs"
    },
    {
      "x": -18,
      "y": 5,
      "z": 16,
      "name": "Wood_Goldenwood_Planks"
    },
    {
      "x": -18,
      "y": 6,
      "z": 16,
      "name": "Empty"
    },
    {
      "x": -18,
      "y": 7,
      "z": 16,
      "name": "Empty"
    },
    {
      "x": -18,
      "y": 8,
      "z": 16,
      "name": "Empty"
    },
    {
      "x": -18,
      "y": 9,
      "z": 16,
      "name": "Wood_Goldenwood_Planks"
    },
    {
      "x": -18,
      "y": 10,
      "z": 16,
      "name": "Wood_Goldenwood_Decorative"
    },
    {
      "x": -18,
      "y": 12,
      "z": 16,
      "name": "Wood_Goldenwood_Planks"
    },
    {
      "x": -18,
      "y": 5,
      "z": 17,
      "name": "Wood_Goldenwood_Planks"
    },
    {
      "x": -18,
      "y": 6,
      "z": 17,
      "name": "Empty"
    },
    {
      "x": -18,
      "y": 7,
      "z": 17,
      "name": "Empty"
    },
    {
      "x": -18,
      "y": 8,
      "z": 17,
      "name": "Empty"
    },
    {
      "x": -18,
      "y": 9,
      "z": 17,
      "name": "Wood_Goldenwood_Planks"
    },
    {
      "x": -18,
      "y": 10,
      "z": 17,
      "name": "Wood_Goldenwood_Decorative"
    },
    {
      "x": -18,
      "y": 11,
      "z": 17,
      "name": "Wood_Goldenwood_Planks_Half",
      "rotation": 8
    },
    {
      "x": -18,
      "y": 12,
      "z": 17,
      "name": "Wood_Goldenwood_Planks_Half"
    },
    {
      "x": -18,
      "y": 5,
      "z": 18,
      "name": "Wood_Goldenwood_Planks"
    },
    {
      "x": -18,
      "y": 6,
      "z": 18,
      "name": "Empty"
    },
    {
      "x": -18,
      "y": 7,
      "z": 18,
      "name": "Empty"
    },
    {
      "x": -18,
      "y": 8,
      "z": 18,
      "name": "Empty"
    },
    {
      "x": -18,
      "y": 9,
      "z": 18,
      "name": "Wood_Goldenwood_Planks"
    },
    {
      "x": -18,
      "y": 10,
      "z": 18,
      "name": "Wood_Goldenwood_Decorative"
    },
    {
      "x": -18,
      "y": 11,
      "z": 18,
      "name": "Wood_Goldenwood_Planks"
    },
    {
      "x": -18,
      "y": 4,
      "z": 19,
      "name": "Wood_Bamboo_Trunk_Deco",
      "rotation": 5
    },
    {
      "x": -18,
      "y": 5,
      "z": 19,
      "name": "Wood_Goldenwood_Planks"
    },
    {
      "x": -18,
      "y": 6,
      "z": 19,
      "name": "Empty"
    },
    {
      "x": -18,
      "y": 7,
      "z": 19,
      "name": "Empty"
    },
    {
      "x": -18,
      "y": 8,
      "z": 19,
      "name": "Empty"
    },
    {
      "x": -18,
      "y": 9,
      "z": 19,
      "name": "Wood_Goldenwood_Planks"
    },
    {
      "x": -18,
      "y": 10,
      "z": 19,
      "name": "Wood_Goldenwood_Decorative"
    },
    {
      "x": -18,
      "y": 11,
      "z": 19,
      "name": "Wood_Goldenwood_Planks_Half"
    },
    {
      "x": -18,
      "y": -4,
      "z": 20,
      "name": "Wood_Bamboo_Trunk_Deco",
      "rotation": 5
    },
    {
      "x": -18,
      "y": 3,
      "z": 20,
      "name": "Plant_Moss_Rug_Green"
    },
    {
      "x": -18,
      "y": 5,
      "z": 20,
      "name": "Wood_Goldenwood_Planks"
    },
    {
      "x": -18,
      "y": 6,
      "z": 20,
      "name": "Wood_Tropicalwood_Planks_Half",
      "rotation": 4
    },
    {
      "x": -18,
      "y": 7,
      "z": 20,
      "name": "Wood_Tropicalwood_Planks_Half",
      "rotation": 4
    },
    {
      "x": -18,
      "y": 8,
      "z": 20,
      "name": "Wood_Tropicalwood_Stairs",
      "rotation": 10
    },
    {
      "x": -18,
      "y": 9,
      "z": 20,
      "name": "Wood_Tropicalwood_Roof"
    },
    {
      "x": -18,
      "y": 5,
      "z": 21,
      "name": "Wood_Goldenwood_Planks_Half",
      "rotation": 8
    },
    {
      "x": -18,
      "y": 8,
      "z": 21,
      "name": "Wood_Tropicalwood_Roof"
    },
    {
      "x": -18,
      "y": 9,
      "z": 21,
      "name": "Wood_Goldenwood_Planks"
    },
    {
      "x": -18,
      "y": 10,
      "z": 21,
      "name": "Plant_Moss_Rug_Green"
    },
    {
      "x": -18,
      "y": 5,
      "z": 22,
      "name": "Furniture_Jungle_Platform",
      "rotation": 1
    },
    {
      "x": -18,
      "y": 6,
      "z": 22,
      "name": "Wood_Bamboo_Branch_Long_Deco",
      "rotation": 5
    },
    {
      "x": -18,
      "y": 8,
      "z": 22,
      "name": "Wood_Tropicalwood_Roof_Flat"
    },
    {
      "x": -17,
      "y": 3,
      "z": -2,
      "name": "Plant_Moss_Rug_Green"
    },
    {
      "x": -17,
      "y": 3,
      "z": -1,
      "name": "Plant_Moss_Rug_Green"
    },
    {
      "x": -17,
      "y": 8,
      "z": -1,
      "name": "Wood_Goldenwood_Planks_Half",
      "rotation": 6
    },
    {
      "x": -17,
      "y": 9,
      "z": -1,
      "name": "Wood_Greenwood_Roof",
      "rotation": 2
    },
    {
      "x": -17,
      "y": -33,
      "z": 0,
      "name": "Wood_Bamboo_Branch_Long_Deco"
    },
    {
      "x": -17,
      "y": -32,
      "z": 0,
      "name": "Wood_Bamboo_Branch_Long_Deco"
    },
    {
      "x": -17,
      "y": -31,
      "z": 0,
      "name": "Wood_Bamboo_Branch_Long_Deco"
    },
    {
      "x": -17,
      "y": -30,
      "z": 0,
      "name": "Wood_Bamboo_Branch_Long_Deco"
    },
    {
      "x": -17,
      "y": -29,
      "z": 0,
      "name": "Wood_Bamboo_Branch_Long_Deco"
    },
    {
      "x": -17,
      "y": -28,
      "z": 0,
      "name": "Wood_Bamboo_Branch_Long_Deco"
    },
    {
      "x": -17,
      "y": -27,
      "z": 0,
      "name": "Wood_Bamboo_Branch_Long_Deco"
    },
    {
      "x": -17,
      "y": -26,
      "z": 0,
      "name": "Wood_Bamboo_Branch_Long_Deco"
    },
    {
      "x": -17,
      "y": -25,
      "z": 0,
      "name": "Wood_Bamboo_Branch_Long_Deco"
    },
    {
      "x": -17,
      "y": -24,
      "z": 0,
      "name": "Wood_Bamboo_Branch_Long_Deco"
    },
    {
      "x": -17,
      "y": -23,
      "z": 0,
      "name": "Wood_Bamboo_Branch_Long_Deco"
    },
    {
      "x": -17,
      "y": -22,
      "z": 0,
      "name": "Wood_Bamboo_Branch_Long_Deco"
    },
    {
      "x": -17,
      "y": -21,
      "z": 0,
      "name": "Wood_Bamboo_Branch_Long_Deco"
    },
    {
      "x": -17,
      "y": -20,
      "z": 0,
      "name": "Wood_Bamboo_Branch_Long_Deco"
    },
    {
      "x": -17,
      "y": -19,
      "z": 0,
      "name": "Wood_Bamboo_Branch_Long_Deco"
    },
    {
      "x": -17,
      "y": -18,
      "z": 0,
      "name": "Wood_Bamboo_Branch_Long_Deco"
    },
    {
      "x": -17,
      "y": -17,
      "z": 0,
      "name": "Wood_Bamboo_Branch_Long_Deco"
    },
    {
      "x": -17,
      "y": -16,
      "z": 0,
      "name": "Wood_Bamboo_Branch_Long_Deco"
    },
    {
      "x": -17,
      "y": -15,
      "z": 0,
      "name": "Wood_Bamboo_Branch_Long_Deco"
    },
    {
      "x": -17,
      "y": -14,
      "z": 0,
      "name": "Wood_Bamboo_Branch_Long_Deco"
    },
    {
      "x": -17,
      "y": -13,
      "z": 0,
      "name": "Wood_Bamboo_Branch_Long_Deco"
    },
    {
      "x": -17,
      "y": -12,
      "z": 0,
      "name": "Wood_Bamboo_Branch_Long_Deco"
    },
    {
      "x": -17,
      "y": -11,
      "z": 0,
      "name": "Wood_Bamboo_Branch_Long_Deco"
    },
    {
      "x": -17,
      "y": -10,
      "z": 0,
      "name": "Wood_Bamboo_Branch_Long_Deco"
    },
    {
      "x": -17,
      "y": -9,
      "z": 0,
      "name": "Wood_Bamboo_Branch_Long_Deco"
    },
    {
      "x": -17,
      "y": -8,
      "z": 0,
      "name": "Wood_Bamboo_Branch_Long_Deco"
    },
    {
      "x": -17,
      "y": -7,
      "z": 0,
      "name": "Wood_Bamboo_Branch_Long_Deco"
    },
    {
      "x": -17,
      "y": -6,
      "z": 0,
      "name": "Wood_Bamboo_Branch_Long_Deco"
    },
    {
      "x": -17,
      "y": -5,
      "z": 0,
      "name": "Wood_Bamboo_Branch_Long_Deco"
    },
    {
      "x": -17,
      "y": -4,
      "z": 0,
      "name": "Wood_Bamboo_Trunk_Deco"
    },
    {
      "x": -17,
      "y": -3,
      "z": 0,
      "name": "Wood_Bamboo_Trunk_Deco"
    },
    {
      "x": -17,
      "y": -2,
      "z": 0,
      "name": "Wood_Bamboo_Trunk_Deco"
    },
    {
      "x": -17,
      "y": -1,
      "z": 0,
      "name": "Wood_Bamboo_Trunk_Deco"
    },
    {
      "x": -17,
      "y": 0,
      "z": 0,
      "name": "Wood_Bamboo_Trunk_Deco"
    },
    {
      "x": -17,
      "y": 1,
      "z": 0,
      "name": "Wood_Bamboo_Trunk_Deco"
    },
    {
      "x": -17,
      "y": 2,
      "z": 0,
      "name": "Furniture_Jungle_Planter"
    },
    {
      "x": -17,
      "y": 3,
      "z": 0,
      "name": "Furniture_Jungle_Planter"
    },
    {
      "x": -17,
      "y": 4,
      "z": 0,
      "name": "Wood_Bamboo_Branch_Long_Deco"
    },
    {
      "x": -17,
      "y": 5,
      "z": 0,
      "name": "Wood_Bamboo_Branch_Long_Deco"
    },
    {
      "x": -17,
      "y": 6,
      "z": 0,
      "name": "Wood_Bamboo_Branch_Long_Deco"
    },
    {
      "x": -17,
      "y": 7,
      "z": 0,
      "name": "Wood_Tropicalwood_Ornate"
    },
    {
      "x": -17,
      "y": 8,
      "z": 0,
      "name": "Wood_Goldenwood_Ornate"
    },
    {
      "x": -17,
      "y": 9,
      "z": 0,
      "name": "Furniture_Kweebec_Lantern"
    },
    {
      "x": -17,
      "y": 10,
      "z": 0,
      "name": "Wood_Greenwood_Roof_Flat"
    },
    {
      "x": -17,
      "y": 8,
      "z": 1,
      "name": "Wood_Goldenwood_Planks_Half",
      "rotation": 4
    },
    {
      "x": -17,
      "y": 9,
      "z": 1,
      "name": "Wood_Greenwood_Roof"
    },
    {
      "x": -17,
      "y": 5,
      "z": 6,
      "name": "Wood_Goldenwood_Planks_Half",
      "rotation": 8
    },
    {
      "x": -17,
      "y": 6,
      "z": 6,
      "name": "Wood_Tropicalwood_Fence",
      "rotation": 2
    },
    {
      "x": -17,
      "y": 8,
      "z": 6,
      "name": "Wood_Tropicalwood_Roof",
      "rotation": 2
    },
    {
      "x": -17,
      "y": 5,
      "z": 7,
      "name": "Wood_Goldenwood_Stairs",
      "rotation": 11
    },
    {
      "x": -17,
      "y": 8,
      "z": 7,
      "name": "Wood_Goldenwood_Planks_Half",
      "rotation": 8
    },
    {
      "x": -17,
      "y": 9,
      "z": 7,
      "name": "Wood_Tropicalwood_Roof_Flat",
      "rotation": 2
    },
    {
      "x": -17,
      "y": -4,
      "z": 8,
      "name": "Wood_Bamboo_Trunk_Deco",
      "rotation": 5
    },
    {
      "x": -17,
      "y": 1,
      "z": 8,
      "name": "Wood_Bamboo_Branch_Long_Deco",
      "rotation": 5
    },
    {
      "x": -17,
      "y": 5,
      "z": 8,
      "name": "Wood_Goldenwood_Planks"
    },
    {
      "x": -17,
      "y": 6,
      "z": 8,
      "name": "Wood_Tropicalwood_Planks_Half",
      "rotation": 6
    },
    {
      "x": -17,
      "y": 7,
      "z": 8,
      "name": "Furniture_Jungle_Window"
    },
    {
      "x": -17,
      "y": 8,
      "z": 8,
      "name": "Wood_Tropicalwood_Stairs",
      "rotation": 8
    },
    {
      "x": -17,
      "y": 9,
      "z": 8,
      "name": "Wood_Tropicalwood_Roof",
      "rotation": 2
    },
    {
      "x": -17,
      "y": 4,
      "z": 9,
      "name": "Wood_Bamboo_Trunk_Deco",
      "rotation": 5
    },
    {
      "x": -17,
      "y": 5,
      "z": 9,
      "name": "Wood_Goldenwood_Planks"
    },
    {
      "x": -17,
      "y": 6,
      "z": 9,
      "name": "Empty"
    },
    {
      "x": -17,
      "y": 7,
      "z": 9,
      "name": "Empty"
    },
    {
      "x": -17,
      "y": 8,
      "z": 9,
      "name": "Empty"
    },
    {
      "x": -17,
      "y": 9,
      "z": 9,
      "name": "Wood_Goldenwood_Planks"
    },
    {
      "x": -17,
      "y": 10,
      "z": 9,
      "name": "Wood_Goldenwood_Decorative"
    },
    {
      "x": -17,
      "y": 11,
      "z": 9,
      "name": "Wood_Goldenwood_Planks"
    },
    {
      "x": -17,
      "y": 12,
      "z": 9,
      "name": "Plant_Moss_Rug_Green"
    },
    {
      "x": -17,
      "y": 3,
      "z": 10,
      "name": "Plant_Flower_Water_Green"
    },
    {
      "x": -17,
      "y": 5,
      "z": 10,
      "name": "Wood_Goldenwood_Planks"
    },
    {
      "x": -17,
      "y": 6,
      "z": 10,
      "name": "Empty"
    },
    {
      "x": -17,
      "y": 7,
      "z": 10,
      "name": "Empty"
    },
    {
      "x": -17,
      "y": 8,
      "z": 10,
      "name": "Empty"
    },
    {
      "x": -17,
      "y": 9,
      "z": 10,
      "name": "Empty"
    },
    {
      "x": -17,
      "y": 10,
      "z": 10,
      "name": "Wood_Goldenwood_Planks"
    },
    {
      "x": -17,
      "y": 11,
      "z": 10,
      "name": "Wood_Goldenwood_Planks"
    },
    {
      "x": -17,
      "y": 5,
      "z": 11,
      "name": "Wood_Goldenwood_Planks"
    },
    {
      "x": -17,
      "y": 6,
      "z": 11,
      "name": "Empty"
    },
    {
      "x": -17,
      "y": 7,
      "z": 11,
      "name": "Empty"
    },
    {
      "x": -17,
      "y": 8,
      "z": 11,
      "name": "Empty"
    },
    {
      "x": -17,
      "y": 9,
      "z": 11,
      "name": "Empty"
    },
    {
      "x": -17,
      "y": 10,
      "z": 11,
      "name": "Wood_Goldenwood_Planks"
    },
    {
      "x": -17,
      "y": 11,
      "z": 11,
      "name": "Wood_Goldenwood_Planks"
    },
    {
      "x": -17,
      "y": 12,
      "z": 11,
      "name": "Soil_Clay_Ocean_Brick_Half"
    },
    {
      "x": -17,
      "y": 5,
      "z": 12,
      "name": "Wood_Goldenwood_Planks"
    },
    {
      "x": -17,
      "y": 6,
      "z": 12,
      "name": "Empty"
    },
    {
      "x": -17,
      "y": 7,
      "z": 12,
      "name": "Empty"
    },
    {
      "x": -17,
      "y": 8,
      "z": 12,
      "name": "Empty"
    },
    {
      "x": -17,
      "y": 9,
      "z": 12,
      "name": "Empty"
    },
    {
      "x": -17,
      "y": 10,
      "z": 12,
      "name": "Wood_Goldenwood_Planks"
    },
    {
      "x": -17,
      "y": 11,
      "z": 12,
      "name": "Wood_Goldenwood_Planks"
    },
    {
      "x": -17,
      "y": 12,
      "z": 12,
      "name": "Soil_Clay_Ocean_Brick_Stairs",
      "rotation": 2
    },
    {
      "x": -17,
      "y": 5,
      "z": 13,
      "name": "Wood_Goldenwood_Planks"
    },
    {
      "x": -17,
      "y": 6,
      "z": 13,
      "name": "Empty"
    },
    {
      "x": -17,
      "y": 7,
      "z": 13,
      "name": "Empty"
    },
    {
      "x": -17,
      "y": 8,
      "z": 13,
      "name": "Empty"
    },
    {
      "x": -17,
      "y": 9,
      "z": 13,
      "name": "Empty"
    },
    {
      "x": -17,
      "y": 10,
      "z": 13,
      "name": "Wood_Goldenwood_Planks"
    },
    {
      "x": -17,
      "y": 11,
      "z": 13,
      "name": "Wood_Goldenwood_Planks"
    },
    {
      "x": -17,
      "y": 12,
      "z": 13,
      "name": "Wood_Greenwood_Planks"
    },
    {
      "x": -17,
      "y": 13,
      "z": 13,
      "name": "Soil_Clay_Ocean_Brick_Stairs",
      "rotation": 2
    },
    {
      "x": -17,
      "y": 5,
      "z": 14,
      "name": "Wood_Goldenwood_Planks"
    },
    {
      "x": -17,
      "y": 6,
      "z": 14,
      "name": "Empty"
    },
    {
      "x": -17,
      "y": 7,
      "z": 14,
      "name": "Empty"
    },
    {
      "x": -17,
      "y": 8,
      "z": 14,
      "name": "Empty"
    },
    {
      "x": -17,
      "y": 9,
      "z": 14,
      "name": "Empty"
    },
    {
      "x": -17,
      "y": 10,
      "z": 14,
      "name": "Wood_Goldenwood_Planks"
    },
    {
      "x": -17,
      "y": 11,
      "z": 14,
      "name": "Wood_Goldenwood_Planks"
    },
    {
      "x": -17,
      "y": 12,
      "z": 14,
      "name": "Wood_Greenwood_Fence",
      "rotation": 3
    },
    {
      "x": -17,
      "y": 13,
      "z": 14,
      "name": "Wood_Bamboo_Trunk_Deco",
      "rotation": 5
    },
    {
      "x": -17,
      "y": 14,
      "z": 14,
      "name": "Plant_Moss_Rug_Green"
    },
    {
      "x": -17,
      "y": 5,
      "z": 15,
      "name": "Wood_Goldenwood_Planks"
    },
    {
      "x": -17,
      "y": 6,
      "z": 15,
      "name": "Empty"
    },
    {
      "x": -17,
      "y": 7,
      "z": 15,
      "name": "Empty"
    },
    {
      "x": -17,
      "y": 8,
      "z": 15,
      "name": "Empty"
    },
    {
      "x": -17,
      "y": 9,
      "z": 15,
      "name": "Empty"
    },
    {
      "x": -17,
      "y": 10,
      "z": 15,
      "name": "Wood_Goldenwood_Planks"
    },
    {
      "x": -17,
      "y": 11,
      "z": 15,
      "name": "Wood_Goldenwood_Planks"
    },
    {
      "x": -17,
      "y": 12,
      "z": 15,
      "name": "Wood_Greenwood_Planks"
    },
    {
      "x": -17,
      "y": 13,
      "z": 15,
      "name": "Soil_Clay_Ocean_Brick_Stairs"
    },
    {
      "x": -17,
      "y": 5,
      "z": 16,
      "name": "Wood_Goldenwood_Planks"
    },
    {
      "x": -17,
      "y": 6,
      "z": 16,
      "name": "Empty"
    },
    {
      "x": -17,
      "y": 7,
      "z": 16,
      "name": "Empty"
    },
    {
      "x": -17,
      "y": 8,
      "z": 16,
      "name": "Empty"
    },
    {
      "x": -17,
      "y": 9,
      "z": 16,
      "name": "Empty"
    },
    {
      "x": -17,
      "y": 10,
      "z": 16,
      "name": "Wood_Goldenwood_Planks"
    },
    {
      "x": -17,
      "y": 11,
      "z": 16,
      "name": "Wood_Goldenwood_Planks"
    },
    {
      "x": -17,
      "y": 12,
      "z": 16,
      "name": "Soil_Clay_Ocean_Brick_Stairs"
    },
    {
      "x": -17,
      "y": 5,
      "z": 17,
      "name": "Wood_Goldenwood_Planks"
    },
    {
      "x": -17,
      "y": 6,
      "z": 17,
      "name": "Empty"
    },
    {
      "x": -17,
      "y": 7,
      "z": 17,
      "name": "Empty"
    },
    {
      "x": -17,
      "y": 8,
      "z": 17,
      "name": "Empty"
    },
    {
      "x": -17,
      "y": 9,
      "z": 17,
      "name": "Empty"
    },
    {
      "x": -17,
      "y": 10,
      "z": 17,
      "name": "Wood_Goldenwood_Planks"
    },
    {
      "x": -17,
      "y": 11,
      "z": 17,
      "name": "Wood_Goldenwood_Planks"
    },
    {
      "x": -17,
      "y": 12,
      "z": 17,
      "name": "Soil_Clay_Ocean_Brick_Half"
    },
    {
      "x": -17,
      "y": 5,
      "z": 18,
      "name": "Wood_Goldenwood_Planks"
    },
    {
      "x": -17,
      "y": 6,
      "z": 18,
      "name": "Empty"
    },
    {
      "x": -17,
      "y": 7,
      "z": 18,
      "name": "Empty"
    },
    {
      "x": -17,
      "y": 8,
      "z": 18,
      "name": "Empty"
    },
    {
      "x": -17,
      "y": 9,
      "z": 18,
      "name": "Empty"
    },
    {
      "x": -17,
      "y": 10,
      "z": 18,
      "name": "Wood_Goldenwood_Planks"
    },
    {
      "x": -17,
      "y": 11,
      "z": 18,
      "name": "Wood_Goldenwood_Planks"
    },
    {
      "x": -17,
      "y": 12,
      "z": 18,
      "name": "Plant_Moss_Rug_Green"
    },
    {
      "x": -17,
      "y": 4,
      "z": 19,
      "name": "Wood_Bamboo_Trunk_Deco",
      "rotation": 5
    },
    {
      "x": -17,
      "y": 5,
      "z": 19,
      "name": "Wood_Goldenwood_Planks"
    },
    {
      "x": -17,
      "y": 6,
      "z": 19,
      "name": "Empty"
    },
    {
      "x": -17,
      "y": 7,
      "z": 19,
      "name": "Empty"
    },
    {
      "x": -17,
      "y": 8,
      "z": 19,
      "name": "Empty"
    },
    {
      "x": -17,
      "y": 9,
      "z": 19,
      "name": "Wood_Goldenwood_Planks"
    },
    {
      "x": -17,
      "y": 10,
      "z": 19,
      "name": "Wood_Goldenwood_Decorative"
    },
    {
      "x": -17,
      "y": 11,
      "z": 19,
      "name": "Wood_Goldenwood_Planks"
    },
    {
      "x": -17,
      "y": 12,
      "z": 19,
      "name": "Plant_Moss_Rug_Green"
    },
    {
      "x": -17,
      "y": -4,
      "z": 20,
      "name": "Wood_Bamboo_Trunk_Deco",
      "rotation": 5
    },
    {
      "x": -17,
      "y": 5,
      "z": 20,
      "name": "Wood_Goldenwood_Planks"
    },
    {
      "x": -17,
      "y": 6,
      "z": 20,
      "name": "Empty"
    },
    {
      "x": -17,
      "y": 7,
      "z": 20,
      "name": "Empty"
    },
    {
      "x": -17,
      "y": 8,
      "z": 20,
      "name": "Wood_Tropicalwood_Stairs",
      "rotation": 10
    },
    {
      "x": -17,
      "y": 9,
      "z": 20,
      "name": "Wood_Tropicalwood_Roof"
    },
    {
      "x": -17,
      "y": 10,
      "z": 20,
      "name": "Plant_Moss_Wall_Green"
    },
    {
      "x": -17,
      "y": 5,
      "z": 21,
      "name": "Wood_Goldenwood_Planks_Half",
      "rotation": 8
    },
    {
      "x": -17,
      "y": 8,
      "z": 21,
      "name": "Wood_Tropicalwood_Roof"
    },
    {
      "x": -17,
      "y": 9,
      "z": 21,
      "name": "Wood_Tropicalwood_Roof_Flat"
    },
    {
      "x": -17,
      "y": 5,
      "z": 22,
      "name": "Wood_Goldenwood_Planks_Half",
      "rotation": 8
    },
    {
      "x": -17,
      "y": 6,
      "z": 22,
      "name": "Wood_Bamboo_Branch_Long_Deco",
      "rotation": 5
    },
    {
      "x": -17,
      "y": 8,
      "z": 22,
      "name": "Wood_Tropicalwood_Roof_Flat"
    },
    {
      "x": -16,
      "y": 3,
      "z": -3,
      "name": "Plant_Flower_Water_Blue"
    },
    {
      "x": -16,
      "y": 3,
      "z": -2,
      "name": "Plant_Moss_Rug_Green"
    },
    {
      "x": -16,
      "y": 3,
      "z": -1,
      "name": "Plant_Moss_Rug_Green"
    },
    {
      "x": -16,
      "y": 9,
      "z": -1,
      "name": "Wood_Greenwood_Roof_Hollow",
      "rotation": 2
    },
    {
      "x": -16,
      "y": 3,
      "z": 0,
      "name": "Plant_Moss_Rug_Green"
    },
    {
      "x": -16,
      "y": 10,
      "z": 0,
      "name": "Wood_Greenwood_Roof_Flat"
    },
    {
      "x": -16,
      "y": 9,
      "z": 1,
      "name": "Wood_Greenwood_Roof_Hollow"
    },
    {
      "x": -16,
      "y": 5,
      "z": 6,
      "name": "Wood_Goldenwood_Planks_Half",
      "rotation": 8
    },
    {
      "x": -16,
      "y": 6,
      "z": 6,
      "name": "Wood_Tropicalwood_Planks_Half",
      "rotation": 4
    },
    {
      "x": -16,
      "y": 8,
      "z": 6,
      "name": "Wood_Tropicalwood_Roof",
      "rotation": 2
    },
    {
      "x": -16,
      "y": 5,
      "z": 7,
      "name": "Wood_Goldenwood_Planks_Half",
      "rotation": 8
    },
    {
      "x": -16,
      "y": 8,
      "z": 7,
      "name": "Wood_Goldenwood_Planks_Half",
      "rotation": 8
    },
    {
      "x": -16,
      "y": 9,
      "z": 7,
      "name": "Wood_Tropicalwood_Roof_Flat",
      "rotation": 2
    },
    {
      "x": -16,
      "y": -4,
      "z": 8,
      "name": "Wood_Bamboo_Trunk_Deco",
      "rotation": 5
    },
    {
      "x": -16,
      "y": 1,
      "z": 8,
      "name": "Wood_Bamboo_Branch_Long_Deco",
      "rotation": 5
    },
    {
      "x": -16,
      "y": 5,
      "z": 8,
      "name": "Wood_Goldenwood_Planks"
    },
    {
      "x": -16,
      "y": 6,
      "z": 8,
      "name": "Wood_Tropicalwood_Planks_Half",
      "rotation": 6
    },
    {
      "x": -16,
      "y": 7,
      "z": 8,
      "name": "Furniture_Jungle_Window"
    },
    {
      "x": -16,
      "y": 8,
      "z": 8,
      "name": "Wood_Tropicalwood_Stairs",
      "rotation": 8
    },
    {
      "x": -16,
      "y": 9,
      "z": 8,
      "name": "Wood_Tropicalwood_Roof",
      "rotation": 2
    },
    {
      "x": -16,
      "y": 4,
      "z": 9,
      "name": "Wood_Bamboo_Trunk_Deco",
      "rotation": 5
    },
    {
      "x": -16,
      "y": 5,
      "z": 9,
      "name": "Wood_Goldenwood_Planks"
    },
    {
      "x": -16,
      "y": 6,
      "z": 9,
      "name": "Empty"
    },
    {
      "x": -16,
      "y": 7,
      "z": 9,
      "name": "Empty"
    },
    {
      "x": -16,
      "y": 8,
      "z": 9,
      "name": "Empty"
    },
    {
      "x": -16,
      "y": 9,
      "z": 9,
      "name": "Wood_Goldenwood_Planks"
    },
    {
      "x": -16,
      "y": 10,
      "z": 9,
      "name": "Wood_Goldenwood_Decorative"
    },
    {
      "x": -16,
      "y": 11,
      "z": 9,
      "name": "Wood_Goldenwood_Planks_Half",
      "rotation": 8
    },
    {
      "x": -16,
      "y": 12,
      "z": 9,
      "name": "Wood_Goldenwood_Planks_Half"
    },
    {
      "x": -16,
      "y": 5,
      "z": 10,
      "name": "Wood_Goldenwood_Planks"
    },
    {
      "x": -16,
      "y": 6,
      "z": 10,
      "name": "Empty"
    },
    {
      "x": -16,
      "y": 7,
      "z": 10,
      "name": "Empty"
    },
    {
      "x": -16,
      "y": 8,
      "z": 10,
      "name": "Empty"
    },
    {
      "x": -16,
      "y": 9,
      "z": 10,
      "name": "Empty"
    },
    {
      "x": -16,
      "y": 10,
      "z": 10,
      "name": "Wood_Goldenwood_Planks"
    },
    {
      "x": -16,
      "y": 11,
      "z": 10,
      "name": "Wood_Goldenwood_Planks"
    },
    {
      "x": -16,
      "y": 12,
      "z": 10,
      "name": "Soil_Clay_Ocean_Brick_Half"
    },
    {
      "x": -16,
      "y": 5,
      "z": 11,
      "name": "Wood_Goldenwood_Planks"
    },
    {
      "x": -16,
      "y": 6,
      "z": 11,
      "name": "Empty"
    },
    {
      "x": -16,
      "y": 7,
      "z": 11,
      "name": "Empty"
    },
    {
      "x": -16,
      "y": 8,
      "z": 11,
      "name": "Empty"
    },
    {
      "x": -16,
      "y": 9,
      "z": 11,
      "name": "Empty"
    },
    {
      "x": -16,
      "y": 12,
      "z": 11,
      "name": "Soil_Clay_Ocean_Brick_Half"
    },
    {
      "x": -16,
      "y": 5,
      "z": 12,
      "name": "Wood_Goldenwood_Planks"
    },
    {
      "x": -16,
      "y": 6,
      "z": 12,
      "name": "Empty"
    },
    {
      "x": -16,
      "y": 7,
      "z": 12,
      "name": "Empty"
    },
    {
      "x": -16,
      "y": 8,
      "z": 12,
      "name": "Empty"
    },
    {
      "x": -16,
      "y": 9,
      "z": 12,
      "name": "Empty"
    },
    {
      "x": -16,
      "y": 12,
      "z": 12,
      "name": "Soil_Clay_Ocean_Brick_Stairs",
      "rotation": 2
    },
    {
      "x": -16,
      "y": 5,
      "z": 13,
      "name": "Wood_Goldenwood_Planks"
    },
    {
      "x": -16,
      "y": 6,
      "z": 13,
      "name": "Empty"
    },
    {
      "x": -16,
      "y": 7,
      "z": 13,
      "name": "Empty"
    },
    {
      "x": -16,
      "y": 8,
      "z": 13,
      "name": "Empty"
    },
    {
      "x": -16,
      "y": 9,
      "z": 13,
      "name": "Empty"
    },
    {
      "x": -16,
      "y": 13,
      "z": 13,
      "name": "Soil_Clay_Ocean_Brick_Stairs",
      "rotation": 2
    },
    {
      "x": -16,
      "y": 5,
      "z": 14,
      "name": "Wood_Goldenwood_Planks"
    },
    {
      "x": -16,
      "y": 6,
      "z": 14,
      "name": "Empty"
    },
    {
      "x": -16,
      "y": 7,
      "z": 14,
      "name": "Empty"
    },
    {
      "x": -16,
      "y": 8,
      "z": 14,
      "name": "Empty"
    },
    {
      "x": -16,
      "y": 9,
      "z": 14,
      "name": "Empty"
    },
    {
      "x": -16,
      "y": 13,
      "z": 14,
      "name": "Wood_Bamboo_Trunk_Deco",
      "rotation": 5
    },
    {
      "x": -16,
      "y": 14,
      "z": 14,
      "name": "Plant_Moss_Rug_Green"
    },
    {
      "x": -16,
      "y": 5,
      "z": 15,
      "name": "Wood_Goldenwood_Planks"
    },
    {
      "x": -16,
      "y": 6,
      "z": 15,
      "name": "Empty"
    },
    {
      "x": -16,
      "y": 7,
      "z": 15,
      "name": "Empty"
    },
    {
      "x": -16,
      "y": 8,
      "z": 15,
      "name": "Empty"
    },
    {
      "x": -16,
      "y": 9,
      "z": 15,
      "name": "Empty"
    },
    {
      "x": -16,
      "y": 13,
      "z": 15,
      "name": "Soil_Clay_Ocean_Brick_Stairs"
    },
    {
      "x": -16,
      "y": 5,
      "z": 16,
      "name": "Wood_Goldenwood_Planks"
    },
    {
      "x": -16,
      "y": 6,
      "z": 16,
      "name": "Empty"
    },
    {
      "x": -16,
      "y": 7,
      "z": 16,
      "name": "Empty"
    },
    {
      "x": -16,
      "y": 8,
      "z": 16,
      "name": "Empty"
    },
    {
      "x": -16,
      "y": 9,
      "z": 16,
      "name": "Empty"
    },
    {
      "x": -16,
      "y": 12,
      "z": 16,
      "name": "Soil_Clay_Ocean_Brick_Stairs"
    },
    {
      "x": -16,
      "y": 5,
      "z": 17,
      "name": "Wood_Goldenwood_Planks"
    },
    {
      "x": -16,
      "y": 6,
      "z": 17,
      "name": "Empty"
    },
    {
      "x": -16,
      "y": 7,
      "z": 17,
      "name": "Empty"
    },
    {
      "x": -16,
      "y": 8,
      "z": 17,
      "name": "Empty"
    },
    {
      "x": -16,
      "y": 9,
      "z": 17,
      "name": "Empty"
    },
    {
      "x": -16,
      "y": 12,
      "z": 17,
      "name": "Soil_Clay_Ocean_Brick_Half"
    },
    {
      "x": -16,
      "y": 5,
      "z": 18,
      "name": "Wood_Goldenwood_Planks"
    },
    {
      "x": -16,
      "y": 6,
      "z": 18,
      "name": "Empty"
    },
    {
      "x": -16,
      "y": 7,
      "z": 18,
      "name": "Empty"
    },
    {
      "x": -16,
      "y": 8,
      "z": 18,
      "name": "Empty"
    },
    {
      "x": -16,
      "y": 9,
      "z": 18,
      "name": "Empty"
    },
    {
      "x": -16,
      "y": 10,
      "z": 18,
      "name": "Wood_Goldenwood_Planks"
    },
    {
      "x": -16,
      "y": 11,
      "z": 18,
      "name": "Wood_Goldenwood_Planks"
    },
    {
      "x": -16,
      "y": 12,
      "z": 18,
      "name": "Soil_Clay_Ocean_Brick_Half"
    },
    {
      "x": -16,
      "y": 4,
      "z": 19,
      "name": "Wood_Bamboo_Trunk_Deco",
      "rotation": 5
    },
    {
      "x": -16,
      "y": 5,
      "z": 19,
      "name": "Wood_Goldenwood_Planks"
    },
    {
      "x": -16,
      "y": 6,
      "z": 19,
      "name": "Empty"
    },
    {
      "x": -16,
      "y": 7,
      "z": 19,
      "name": "Empty"
    },
    {
      "x": -16,
      "y": 8,
      "z": 19,
      "name": "Empty"
    },
    {
      "x": -16,
      "y": 9,
      "z": 19,
      "name": "Wood_Goldenwood_Planks"
    },
    {
      "x": -16,
      "y": 10,
      "z": 19,
      "name": "Wood_Goldenwood_Decorative"
    },
    {
      "x": -16,
      "y": 11,
      "z": 19,
      "name": "Wood_Goldenwood_Planks_Half",
      "rotation": 8
    },
    {
      "x": -16,
      "y": 12,
      "z": 19,
      "name": "Wood_Goldenwood_Planks_Half"
    },
    {
      "x": -16,
      "y": -4,
      "z": 20,
      "name": "Wood_Bamboo_Trunk_Deco",
      "rotation": 5
    },
    {
      "x": -16,
      "y": 4,
      "z": 20,
      "name": "Plant_Vine_Hanging"
    },
    {
      "x": -16,
      "y": 5,
      "z": 20,
      "name": "Wood_Goldenwood_Planks"
    },
    {
      "x": -16,
      "y": 6,
      "z": 20,
      "name": "Empty"
    },
    {
      "x": -16,
      "y": 7,
      "z": 20,
      "name": "Empty"
    },
    {
      "x": -16,
      "y": 8,
      "z": 20,
      "name": "Wood_Tropicalwood_Stairs",
      "rotation": 10
    },
    {
      "x": -16,
      "y": 9,
      "z": 20,
      "name": "Wood_Tropicalwood_Roof"
    },
    {
      "x": -16,
      "y": 10,
      "z": 20,
      "name": "Plant_Vine_Jungle",
      "components": {
        "Components": {
          "FarmingBlock": {}
        }
      }
    },
    {
      "x": -16,
      "y": 5,
      "z": 21,
      "name": "Wood_Goldenwood_Planks_Half",
      "rotation": 8
    },
    {
      "x": -16,
      "y": 8,
      "z": 21,
      "name": "Wood_Tropicalwood_Roof"
    },
    {
      "x": -16,
      "y": 9,
      "z": 21,
      "name": "Wood_Tropicalwood_Roof_Flat"
    },
    {
      "x": -16,
      "y": 5,
      "z": 22,
      "name": "Wood_Goldenwood_Planks_Half",
      "rotation": 8
    },
    {
      "x": -16,
      "y": 6,
      "z": 22,
      "name": "Wood_Tropicalwood_Planks_Half",
      "rotation": 4
    },
    {
      "x": -16,
      "y": 8,
      "z": 22,
      "name": "Wood_Tropicalwood_Roof_Flat"
    },
    {
      "x": -15,
      "y": 3,
      "z": -4,
      "name": "Plant_Moss_Rug_Green"
    },
    {
      "x": -15,
      "y": 3,
      "z": -3,
      "name": "Plant_Moss_Rug_Green"
    },
    {
      "x": -15,
      "y": 3,
      "z": -2,
      "name": "Plant_Moss_Rug_Green"
    },
    {
      "x": -15,
      "y": 3,
      "z": -1,
      "name": "Plant_Moss_Rug_Green"
    },
    {
      "x": -15,
      "y": 3,
      "z": 0,
      "name": "Plant_Flower_Water_Green"
    },
    {
      "x": -15,
      "y": 4,
      "z": 2,
      "name": "Plant_Moss_Wall_Green",
      "rotation": 3
    },
    {
      "x": -15,
      "y": 5,
      "z": 2,
      "name": "Plant_Vine_Jungle",
      "components": {
        "Components": {
          "FarmingBlock": {}
        }
      },
      "rotation": 3
    },
    {
      "x": -15,
      "y": 5,
      "z": 6,
      "name": "Wood_Goldenwood_Planks_Half",
      "rotation": 8
    },
    {
      "x": -15,
      "y": 6,
      "z": 6,
      "name": "Wood_Tropicalwood_Planks_Half",
      "rotation": 4
    },
    {
      "x": -15,
      "y": 7,
      "z": 6,
      "name": "Wood_Bamboo_Branch_Long_Deco"
    },
    {
      "x": -15,
      "y": 8,
      "z": 6,
      "name": "Wood_Tropicalwood_Roof",
      "rotation": 2
    },
    {
      "x": -15,
      "y": 3,
      "z": 7,
      "name": "Plant_Moss_Rug_Green"
    },
    {
      "x": -15,
      "y": 5,
      "z": 7,
      "name": "Wood_Goldenwood_Planks_Half",
      "rotation": 8
    },
    {
      "x": -15,
      "y": 8,
      "z": 7,
      "name": "Wood_Goldenwood_Planks_Half",
      "rotation": 8
    },
    {
      "x": -15,
      "y": 9,
      "z": 7,
      "name": "Wood_Goldenwood_Planks_Half"
    },
    {
      "x": -15,
      "y": -4,
      "z": 8,
      "name": "Wood_Bamboo_Trunk_Deco",
      "rotation": 5
    },
    {
      "x": -15,
      "y": 1,
      "z": 8,
      "name": "Wood_Bamboo_Trunk_Deco",
      "rotation": 5
    },
    {
      "x": -15,
      "y": 3,
      "z": 8,
      "name": "Plant_Moss_Rug_Green"
    },
    {
      "x": -15,
      "y": 4,
      "z": 8,
      "name": "Plant_Moss_Wall_Green",
      "rotation": 3
    },
    {
      "x": -15,
      "y": 5,
      "z": 8,
      "name": "Wood_Goldenwood_Planks"
    },
    {
      "x": -15,
      "y": 6,
      "z": 8,
      "name": "Wood_Tropicalwood_Planks_Half",
      "rotation": 6
    },
    {
      "x": -15,
      "y": 7,
      "z": 8,
      "name": "Wood_Tropicalwood_Planks_Half",
      "rotation": 6
    },
    {
      "x": -15,
      "y": 8,
      "z": 8,
      "name": "Wood_Tropicalwood_Stairs",
      "rotation": 8
    },
    {
      "x": -15,
      "y": 9,
      "z": 8,
      "name": "Wood_Tropicalwood_Roof",
      "rotation": 2
    },
    {
      "x": -15,
      "y": 10,
      "z": 8,
      "name": "Plant_Moss_Wall_Green",
      "rotation": 2
    },
    {
      "x": -15,
      "y": -4,
      "z": 9,
      "name": "Wood_Bamboo_Trunk_Deco",
      "rotation": 4
    },
    {
      "x": -15,
      "y": 4,
      "z": 9,
      "name": "Wood_Bamboo_Trunk_Deco",
      "rotation": 5
    },
    {
      "x": -15,
      "y": 5,
      "z": 9,
      "name": "Wood_Goldenwood_Planks"
    },
    {
      "x": -15,
      "y": 6,
      "z": 9,
      "name": "Empty"
    },
    {
      "x": -15,
      "y": 7,
      "z": 9,
      "name": "Empty"
    },
    {
      "x": -15,
      "y": 8,
      "z": 9,
      "name": "Empty"
    },
    {
      "x": -15,
      "y": 9,
      "z": 9,
      "name": "Wood_Goldenwood_Planks"
    },
    {
      "x": -15,
      "y": 10,
      "z": 9,
      "name": "Wood_Goldenwood_Decorative"
    },
    {
      "x": -15,
      "y": 11,
      "z": 9,
      "name": "Plant_Moss_Rug_Green"
    },
    {
      "x": -15,
      "y": 12,
      "z": 9,
      "name": "Wood_Goldenwood_Planks"
    },
    {
      "x": -15,
      "y": -4,
      "z": 10,
      "name": "Wood_Bamboo_Trunk_Deco",
      "rotation": 4
    },
    {
      "x": -15,
      "y": 5,
      "z": 10,
      "name": "Wood_Goldenwood_Planks"
    },
    {
      "x": -15,
      "y": 6,
      "z": 10,
      "name": "Empty"
    },
    {
      "x": -15,
      "y": 7,
      "z": 10,
      "name": "Empty"
    },
    {
      "x": -15,
      "y": 8,
      "z": 10,
      "name": "Empty"
    },
    {
      "x": -15,
      "y": 9,
      "z": 10,
      "name": "Empty"
    },
    {
      "x": -15,
      "y": 10,
      "z": 10,
      "name": "Wood_Goldenwood_Planks"
    },
    {
      "x": -15,
      "y": 11,
      "z": 10,
      "name": "Wood_Goldenwood_Planks"
    },
    {
      "x": -15,
      "y": 12,
      "z": 10,
      "name": "Soil_Clay_Ocean_Brick_Stairs",
      "rotation": 3
    },
    {
      "x": -15,
      "y": -4,
      "z": 11,
      "name": "Wood_Bamboo_Trunk_Deco",
      "rotation": 4
    },
    {
      "x": -15,
      "y": 5,
      "z": 11,
      "name": "Wood_Goldenwood_Planks"
    },
    {
      "x": -15,
      "y": 6,
      "z": 11,
      "name": "Empty"
    },
    {
      "x": -15,
      "y": 7,
      "z": 11,
      "name": "Empty"
    },
    {
      "x": -15,
      "y": 8,
      "z": 11,
      "name": "Empty"
    },
    {
      "x": -15,
      "y": 9,
      "z": 11,
      "name": "Empty"
    },
    {
      "x": -15,
      "y": 12,
      "z": 11,
      "name": "Soil_Clay_Ocean_Brick_Stairs",
      "rotation": 3
    },
    {
      "x": -15,
      "y": -4,
      "z": 12,
      "name": "Wood_Bamboo_Trunk_Deco",
      "rotation": 4
    },
    {
      "x": -15,
      "y": 5,
      "z": 12,
      "name": "Wood_Goldenwood_Planks"
    },
    {
      "x": -15,
      "y": 6,
      "z": 12,
      "name": "Empty"
    },
    {
      "x": -15,
      "y": 7,
      "z": 12,
      "name": "Empty"
    },
    {
      "x": -15,
      "y": 8,
      "z": 12,
      "name": "Empty"
    },
    {
      "x": -15,
      "y": 9,
      "z": 12,
      "name": "Empty"
    },
    {
      "x": -15,
      "y": 12,
      "z": 12,
      "name": "*Soil_Clay_Ocean_Brick_Stairs_State_Definitions_Inverted_Corner_Right",
      "rotation": 1
    },
    {
      "x": -15,
      "y": -4,
      "z": 13,
      "name": "Wood_Bamboo_Trunk_Deco",
      "rotation": 4
    },
    {
      "x": -15,
      "y": 5,
      "z": 13,
      "name": "Wood_Goldenwood_Planks"
    },
    {
      "x": -15,
      "y": 6,
      "z": 13,
      "name": "Empty"
    },
    {
      "x": -15,
      "y": 7,
      "z": 13,
      "name": "Empty"
    },
    {
      "x": -15,
      "y": 8,
      "z": 13,
      "name": "Empty"
    },
    {
      "x": -15,
      "y": 9,
      "z": 13,
      "name": "Empty"
    },
    {
      "x": -15,
      "y": 13,
      "z": 13,
      "name": "Soil_Clay_Ocean_Brick_Stairs",
      "rotation": 2
    },
    {
      "x": -15,
      "y": -4,
      "z": 14,
      "name": "Wood_Bamboo_Trunk_Deco",
      "rotation": 4
    },
    {
      "x": -15,
      "y": 5,
      "z": 14,
      "name": "Wood_Goldenwood_Planks"
    },
    {
      "x": -15,
      "y": 6,
      "z": 14,
      "name": "Empty"
    },
    {
      "x": -15,
      "y": 7,
      "z": 14,
      "name": "Empty"
    },
    {
      "x": -15,
      "y": 8,
      "z": 14,
      "name": "Empty"
    },
    {
      "x": -15,
      "y": 9,
      "z": 14,
      "name": "Empty"
    },
    {
      "x": -15,
      "y": 13,
      "z": 14,
      "name": "Wood_Bamboo_Trunk_Deco",
      "rotation": 5
    },
    {
      "x": -15,
      "y": 14,
      "z": 14,
      "name": "Soil_Clay_Ocean_Brick_Half"
    },
    {
      "x": -15,
      "y": -4,
      "z": 15,
      "name": "Wood_Bamboo_Trunk_Deco",
      "rotation": 4
    },
    {
      "x": -15,
      "y": 5,
      "z": 15,
      "name": "Wood_Goldenwood_Planks"
    },
    {
      "x": -15,
      "y": 6,
      "z": 15,
      "name": "Empty"
    },
    {
      "x": -15,
      "y": 7,
      "z": 15,
      "name": "Empty"
    },
    {
      "x": -15,
      "y": 8,
      "z": 15,
      "name": "Empty"
    },
    {
      "x": -15,
      "y": 9,
      "z": 15,
      "name": "Empty"
    },
    {
      "x": -15,
      "y": 13,
      "z": 15,
      "name": "Soil_Clay_Ocean_Brick_Stairs"
    },
    {
      "x": -15,
      "y": -4,
      "z": 16,
      "name": "Wood_Bamboo_Trunk_Deco",
      "rotation": 4
    },
    {
      "x": -15,
      "y": 5,
      "z": 16,
      "name": "Wood_Goldenwood_Planks"
    },
    {
      "x": -15,
      "y": 6,
      "z": 16,
      "name": "Empty"
    },
    {
      "x": -15,
      "y": 7,
      "z": 16,
      "name": "Empty"
    },
    {
      "x": -15,
      "y": 8,
      "z": 16,
      "name": "Empty"
    },
    {
      "x": -15,
      "y": 9,
      "z": 16,
      "name": "Empty"
    },
    {
      "x": -15,
      "y": 12,
      "z": 16,
      "name": "*Soil_Clay_Ocean_Brick_Stairs_State_Definitions_Inverted_Corner_Right",
      "rotation": 2
    },
    {
      "x": -15,
      "y": -4,
      "z": 17,
      "name": "Wood_Bamboo_Trunk_Deco",
      "rotation": 4
    },
    {
      "x": -15,
      "y": 5,
      "z": 17,
      "name": "Wood_Goldenwood_Planks"
    },
    {
      "x": -15,
      "y": 6,
      "z": 17,
      "name": "Empty"
    },
    {
      "x": -15,
      "y": 7,
      "z": 17,
      "name": "Empty"
    },
    {
      "x": -15,
      "y": 8,
      "z": 17,
      "name": "Empty"
    },
    {
      "x": -15,
      "y": 9,
      "z": 17,
      "name": "Empty"
    },
    {
      "x": -15,
      "y": 12,
      "z": 17,
      "name": "Soil_Clay_Ocean_Brick_Stairs",
      "rotation": 3
    },
    {
      "x": -15,
      "y": -4,
      "z": 18,
      "name": "Wood_Bamboo_Trunk_Deco",
      "rotation": 4
    },
    {
      "x": -15,
      "y": 5,
      "z": 18,
      "name": "Wood_Goldenwood_Planks"
    },
    {
      "x": -15,
      "y": 6,
      "z": 18,
      "name": "Empty"
    },
    {
      "x": -15,
      "y": 7,
      "z": 18,
      "name": "Empty"
    },
    {
      "x": -15,
      "y": 8,
      "z": 18,
      "name": "Empty"
    },
    {
      "x": -15,
      "y": 9,
      "z": 18,
      "name": "Empty"
    },
    {
      "x": -15,
      "y": 10,
      "z": 18,
      "name": "Wood_Goldenwood_Planks"
    },
    {
      "x": -15,
      "y": 11,
      "z": 18,
      "name": "Wood_Goldenwood_Planks"
    },
    {
      "x": -15,
      "y": 12,
      "z": 18,
      "name": "Soil_Clay_Ocean_Brick_Stairs",
      "rotation": 3
    },
    {
      "x": -15,
      "y": -4,
      "z": 19,
      "name": "Wood_Bamboo_Trunk_Deco",
      "rotation": 4
    },
    {
      "x": -15,
      "y": 3,
      "z": 19,
      "name": "Plant_Vine_Jungle",
      "components": {
        "Components": {
          "FarmingBlock": {}
        }
      },
      "rotation": 3
    },
    {
      "x": -15,
      "y": 4,
      "z": 19,
      "name": "Wood_Bamboo_Trunk_Deco",
      "rotation": 5
    },
    {
      "x": -15,
      "y": 5,
      "z": 19,
      "name": "Wood_Goldenwood_Planks"
    },
    {
      "x": -15,
      "y": 6,
      "z": 19,
      "name": "Empty"
    },
    {
      "x": -15,
      "y": 7,
      "z": 19,
      "name": "Empty"
    },
    {
      "x": -15,
      "y": 8,
      "z": 19,
      "name": "Empty"
    },
    {
      "x": -15,
      "y": 9,
      "z": 19,
      "name": "Wood_Goldenwood_Planks"
    },
    {
      "x": -15,
      "y": 10,
      "z": 19,
      "name": "Wood_Goldenwood_Decorative"
    },
    {
      "x": -15,
      "y": 11,
      "z": 19,
      "name": "Plant_Moss_Cave_Green",
      "rotation": 8
    },
    {
      "x": -15,
      "y": 12,
      "z": 19,
      "name": "Wood_Goldenwood_Planks"
    },
    {
      "x": -15,
      "y": -4,
      "z": 20,
      "name": "Wood_Bamboo_Trunk_Deco",
      "rotation": 5
    },
    {
      "x": -15,
      "y": 4,
      "z": 20,
      "name": "Plant_Moss_Wall_Green"
    },
    {
      "x": -15,
      "y": 5,
      "z": 20,
      "name": "Wood_Goldenwood_Planks"
    },
    {
      "x": -15,
      "y": 6,
      "z": 20,
      "name": "Wood_Tropicalwood_Planks_Half",
      "rotation": 4
    },
    {
      "x": -15,
      "y": 7,
      "z": 20,
      "name": "Wood_Tropicalwood_Planks_Half",
      "rotation": 4
    },
    {
      "x": -15,
      "y": 8,
      "z": 20,
      "name": "Wood_Tropicalwood_Stairs",
      "rotation": 10
    },
    {
      "x": -15,
      "y": 9,
      "z": 20,
      "name": "Wood_Tropicalwood_Roof"
    },
    {
      "x": -15,
      "y": 10,
      "z": 20,
      "name": "Plant_Vine_Jungle",
      "components": {
        "Components": {
          "FarmingBlock": {}
        }
      }
    },
    {
      "x": -15,
      "y": 5,
      "z": 21,
      "name": "Furniture_Jungle_Platform",
      "rotation": 1
    },
    {
      "x": -15,
      "y": 8,
      "z": 21,
      "name": "Wood_Tropicalwood_Roof"
    },
    {
      "x": -15,
      "y": 9,
      "z": 21,
      "name": "Wood_Goldenwood_Planks_Half"
    },
    {
      "x": -15,
      "y": 5,
      "z": 22,
      "name": "Wood_Goldenwood_Planks_Half",
      "rotation": 8
    },
    {
      "x": -15,
      "y": 6,
      "z": 22,
      "name": "Wood_Tropicalwood_Planks_Half",
      "rotation": 4
    },
    {
      "x": -15,
      "y": 8,
      "z": 22,
      "name": "Wood_Tropicalwood_Roof_Flat"
    },
    {
      "x": -14,
      "y": 3,
      "z": -11,
      "name": "Wood_Goldenwood_Planks_Half",
      "rotation": 8
    },
    {
      "x": -14,
      "y": 4,
      "z": -11,
      "name": "Plant_Moss_Rug_Green"
    },
    {
      "x": -14,
      "y": 3,
      "z": -10,
      "name": "Wood_Goldenwood_Stairs",
      "rotation": 3
    },
    {
      "x": -14,
      "y": 3,
      "z": -9,
      "name": "Wood_Goldenwood_Stairs",
      "rotation": 3
    },
    {
      "x": -14,
      "y": 3,
      "z": -8,
      "name": "Wood_Goldenwood_Stairs",
      "rotation": 3
    },
    {
      "x": -14,
      "y": 3,
      "z": -7,
      "name": "Wood_Goldenwood_Planks_Half",
      "rotation": 8
    },
    {
      "x": -14,
      "y": 3,
      "z": -6,
      "name": "Wood_Goldenwood_Planks_Half",
      "rotation": 8
    },
    {
      "x": -14,
      "y": 4,
      "z": -6,
      "name": "Furniture_Jungle_Torch"
    },
    {
      "x": -14,
      "y": 5,
      "z": -6,
      "name": "Empty"
    },
    {
      "x": -14,
      "y": 3,
      "z": -5,
      "name": "Wood_Goldenwood_Planks_Half",
      "rotation": 8
    },
    {
      "x": -14,
      "y": 3,
      "z": -4,
      "name": "Wood_Goldenwood_Planks_Half",
      "rotation": 8
    },
    {
      "x": -14,
      "y": 3,
      "z": -3,
      "name": "Wood_Goldenwood_Planks_Half",
      "rotation": 8
    },
    {
      "x": -14,
      "y": 4,
      "z": -3,
      "name": "Wood_Goldenwood_Stairs",
      "rotation": 2
    },
    {
      "x": -14,
      "y": 3,
      "z": -2,
      "name": "Plant_Moss_Rug_Green"
    },
    {
      "x": -14,
      "y": 4,
      "z": -2,
      "name": "Wood_Goldenwood_Stairs",
      "rotation": 10
    },
    {
      "x": -14,
      "y": 5,
      "z": -2,
      "name": "Wood_Goldenwood_Stairs",
      "rotation": 2
    },
    {
      "x": -14,
      "y": 3,
      "z": -1,
      "name": "Plant_Moss_Rug_Green"
    },
    {
      "x": -14,
      "y": 5,
      "z": -1,
      "name": "Wood_Goldenwood_Stairs",
      "rotation": 10
    },
    {
      "x": -14,
      "y": 5,
      "z": 0,
      "name": "Wood_Goldenwood_Planks_Half",
      "rotation": 8
    },
    {
      "x": -14,
      "y": 5,
      "z": 1,
      "name": "Wood_Goldenwood_Planks_Half",
      "rotation": 8
    },
    {
      "x": -14,
      "y": -33,
      "z": 2,
      "name": "Wood_Bamboo_Branch_Long_Deco"
    },
    {
      "x": -14,
      "y": -32,
      "z": 2,
      "name": "Wood_Bamboo_Branch_Long_Deco"
    },
    {
      "x": -14,
      "y": -31,
      "z": 2,
      "name": "Wood_Bamboo_Branch_Long_Deco"
    },
    {
      "x": -14,
      "y": -30,
      "z": 2,
      "name": "Wood_Bamboo_Branch_Long_Deco"
    },
    {
      "x": -14,
      "y": -29,
      "z": 2,
      "name": "Wood_Bamboo_Branch_Long_Deco"
    },
    {
      "x": -14,
      "y": -28,
      "z": 2,
      "name": "Wood_Bamboo_Branch_Long_Deco"
    },
    {
      "x": -14,
      "y": -27,
      "z": 2,
      "name": "Wood_Bamboo_Branch_Long_Deco"
    },
    {
      "x": -14,
      "y": -26,
      "z": 2,
      "name": "Wood_Bamboo_Branch_Long_Deco"
    },
    {
      "x": -14,
      "y": -25,
      "z": 2,
      "name": "Wood_Bamboo_Branch_Long_Deco"
    },
    {
      "x": -14,
      "y": -24,
      "z": 2,
      "name": "Wood_Bamboo_Branch_Long_Deco"
    },
    {
      "x": -14,
      "y": -23,
      "z": 2,
      "name": "Wood_Bamboo_Branch_Long_Deco"
    },
    {
      "x": -14,
      "y": -22,
      "z": 2,
      "name": "Wood_Bamboo_Branch_Long_Deco"
    },
    {
      "x": -14,
      "y": -21,
      "z": 2,
      "name": "Wood_Bamboo_Branch_Long_Deco"
    },
    {
      "x": -14,
      "y": -20,
      "z": 2,
      "name": "Wood_Bamboo_Branch_Long_Deco"
    },
    {
      "x": -14,
      "y": -19,
      "z": 2,
      "name": "Wood_Bamboo_Branch_Long_Deco"
    },
    {
      "x": -14,
      "y": -18,
      "z": 2,
      "name": "Wood_Bamboo_Branch_Long_Deco"
    },
    {
      "x": -14,
      "y": -17,
      "z": 2,
      "name": "Wood_Bamboo_Branch_Long_Deco"
    },
    {
      "x": -14,
      "y": -16,
      "z": 2,
      "name": "Wood_Bamboo_Branch_Long_Deco"
    },
    {
      "x": -14,
      "y": -15,
      "z": 2,
      "name": "Wood_Bamboo_Branch_Long_Deco"
    },
    {
      "x": -14,
      "y": -14,
      "z": 2,
      "name": "Wood_Bamboo_Branch_Long_Deco"
    },
    {
      "x": -14,
      "y": -13,
      "z": 2,
      "name": "Wood_Bamboo_Branch_Long_Deco"
    },
    {
      "x": -14,
      "y": -12,
      "z": 2,
      "name": "Wood_Bamboo_Branch_Long_Deco"
    },
    {
      "x": -14,
      "y": -11,
      "z": 2,
      "name": "Wood_Bamboo_Branch_Long_Deco"
    },
    {
      "x": -14,
      "y": -10,
      "z": 2,
      "name": "Wood_Bamboo_Branch_Long_Deco"
    },
    {
      "x": -14,
      "y": -9,
      "z": 2,
      "name": "Wood_Bamboo_Branch_Long_Deco"
    },
    {
      "x": -14,
      "y": -8,
      "z": 2,
      "name": "Wood_Bamboo_Branch_Long_Deco"
    },
    {
      "x": -14,
      "y": -7,
      "z": 2,
      "name": "Wood_Bamboo_Branch_Long_Deco"
    },
    {
      "x": -14,
      "y": -6,
      "z": 2,
      "name": "Wood_Bamboo_Branch_Long_Deco"
    },
    {
      "x": -14,
      "y": -5,
      "z": 2,
      "name": "Wood_Bamboo_Branch_Long_Deco"
    },
    {
      "x": -14,
      "y": -4,
      "z": 2,
      "name": "Wood_Bamboo_Trunk_Deco"
    },
    {
      "x": -14,
      "y": -3,
      "z": 2,
      "name": "Wood_Bamboo_Trunk_Deco"
    },
    {
      "x": -14,
      "y": -2,
      "z": 2,
      "name": "Wood_Bamboo_Trunk_Deco"
    },
    {
      "x": -14,
      "y": -1,
      "z": 2,
      "name": "Wood_Bamboo_Trunk_Deco"
    },
    {
      "x": -14,
      "y": 0,
      "z": 2,
      "name": "Wood_Bamboo_Trunk_Deco"
    },
    {
      "x": -14,
      "y": 1,
      "z": 2,
      "name": "Wood_Bamboo_Trunk_Deco"
    },
    {
      "x": -14,
      "y": 2,
      "z": 2,
      "name": "Wood_Bamboo_Trunk_Deco"
    },
    {
      "x": -14,
      "y": 3,
      "z": 2,
      "name": "Wood_Bamboo_Trunk_Deco"
    },
    {
      "x": -14,
      "y": 4,
      "z": 2,
      "name": "Wood_Bamboo_Trunk_Deco"
    },
    {
      "x": -14,
      "y": 5,
      "z": 2,
      "name": "Wood_Bamboo_Trunk_Deco"
    },
    {
      "x": -14,
      "y": 6,
      "z": 2,
      "name": "Wood_Bamboo_Trunk_Deco"
    },
    {
      "x": -14,
      "y": 4,
      "z": 3,
      "name": "Plant_Moss_Wall_Green"
    },
    {
      "x": -14,
      "y": 5,
      "z": 3,
      "name": "Wood_Bamboo_Branch_Long_Deco",
      "rotation": 4
    },
    {
      "x": -14,
      "y": 6,
      "z": 3,
      "name": "Deco_Rope",
      "rotation": 4
    },
    {
      "x": -14,
      "y": 5,
      "z": 4,
      "name": "Wood_Bamboo_Branch_Long_Deco",
      "rotation": 4
    },
    {
      "x": -14,
      "y": 6,
      "z": 4,
      "name": "Deco_Rope",
      "rotation": 4
    },
    {
      "x": -14,
      "y": -4,
      "z": 5,
      "name": "Wood_Bamboo_Trunk_Deco",
      "rotation": 4
    },
    {
      "x": -14,
      "y": -3,
      "z": 5,
      "name": "Wood_Bamboo_Branch_Long_Deco"
    },
    {
      "x": -14,
      "y": -2,
      "z": 5,
      "name": "Wood_Bamboo_Branch_Long_Deco"
    },
    {
      "x": -14,
      "y": -1,
      "z": 5,
      "name": "Wood_Bamboo_Branch_Long_Deco"
    },
    {
      "x": -14,
      "y": 0,
      "z": 5,
      "name": "Wood_Bamboo_Branch_Long_Deco"
    },
    {
      "x": -14,
      "y": 1,
      "z": 5,
      "name": "Wood_Bamboo_Branch_Long_Deco"
    },
    {
      "x": -14,
      "y": 2,
      "z": 5,
      "name": "Wood_Bamboo_Branch_Long_Deco"
    },
    {
      "x": -14,
      "y": 3,
      "z": 5,
      "name": "Wood_Bamboo_Branch_Long_Deco"
    },
    {
      "x": -14,
      "y": 4,
      "z": 5,
      "name": "Wood_Bamboo_Branch_Long_Deco"
    },
    {
      "x": -14,
      "y": 5,
      "z": 5,
      "name": "Wood_Bamboo_Trunk_Deco",
      "rotation": 4
    },
    {
      "x": -14,
      "y": 6,
      "z": 5,
      "name": "Wood_Bamboo_Trunk_Deco"
    },
    {
      "x": -14,
      "y": -4,
      "z": 6,
      "name": "Wood_Bamboo_Trunk_Deco",
      "rotation": 4
    },
    {
      "x": -14,
      "y": 4,
      "z": 6,
      "name": "Plant_Vine_Hanging"
    },
    {
      "x": -14,
      "y": 5,
      "z": 6,
      "name": "Wood_Bamboo_Trunk_Deco",
      "rotation": 4
    },
    {
      "x": -14,
      "y": 6,
      "z": 6,
      "name": "Wood_Tropicalwood_Planks_Half",
      "rotation": 4
    },
    {
      "x": -14,
      "y": -4,
      "z": 7,
      "name": "Wood_Bamboo_Trunk_Deco",
      "rotation": 4
    },
    {
      "x": -14,
      "y": 3,
      "z": 7,
      "name": "Plant_Vine_Jungle",
      "components": {
        "Components": {
          "FarmingBlock": {}
        }
      },
      "rotation": 2
    },
    {
      "x": -14,
      "y": 4,
      "z": 7,
      "name": "Plant_Moss_Cave_Green",
      "rotation": 8
    },
    {
      "x": -14,
      "y": 5,
      "z": 7,
      "name": "Wood_Bamboo_Trunk_Deco",
      "rotation": 4
    },
    {
      "x": -14,
      "y": 7,
      "z": 7,
      "name": "Plant_Moss_Wall_Green",
      "rotation": 2
    },
    {
      "x": -14,
      "y": 8,
      "z": 7,
      "name": "Plant_Moss_Cave_Green",
      "rotation": 8
    },
    {
      "x": -14,
      "y": 9,
      "z": 7,
      "name": "Wood_Goldenwood_Planks"
    },
    {
      "x": -14,
      "y": -33,
      "z": 8,
      "name": "Wood_Bamboo_Branch_Long_Deco"
    },
    {
      "x": -14,
      "y": -32,
      "z": 8,
      "name": "Wood_Bamboo_Branch_Long_Deco"
    },
    {
      "x": -14,
      "y": -31,
      "z": 8,
      "name": "Wood_Bamboo_Branch_Long_Deco"
    },
    {
      "x": -14,
      "y": -30,
      "z": 8,
      "name": "Wood_Bamboo_Branch_Long_Deco"
    },
    {
      "x": -14,
      "y": -29,
      "z": 8,
      "name": "Wood_Bamboo_Branch_Long_Deco"
    },
    {
      "x": -14,
      "y": -28,
      "z": 8,
      "name": "Wood_Bamboo_Branch_Long_Deco"
    },
    {
      "x": -14,
      "y": -27,
      "z": 8,
      "name": "Wood_Bamboo_Branch_Long_Deco"
    },
    {
      "x": -14,
      "y": -26,
      "z": 8,
      "name": "Wood_Bamboo_Branch_Long_Deco"
    },
    {
      "x": -14,
      "y": -25,
      "z": 8,
      "name": "Wood_Bamboo_Branch_Long_Deco"
    },
    {
      "x": -14,
      "y": -24,
      "z": 8,
      "name": "Wood_Bamboo_Branch_Long_Deco"
    },
    {
      "x": -14,
      "y": -23,
      "z": 8,
      "name": "Wood_Bamboo_Branch_Long_Deco"
    },
    {
      "x": -14,
      "y": -22,
      "z": 8,
      "name": "Wood_Bamboo_Branch_Long_Deco"
    },
    {
      "x": -14,
      "y": -21,
      "z": 8,
      "name": "Wood_Bamboo_Branch_Long_Deco"
    },
    {
      "x": -14,
      "y": -20,
      "z": 8,
      "name": "Wood_Bamboo_Branch_Long_Deco"
    },
    {
      "x": -14,
      "y": -19,
      "z": 8,
      "name": "Wood_Bamboo_Branch_Long_Deco"
    },
    {
      "x": -14,
      "y": -18,
      "z": 8,
      "name": "Wood_Bamboo_Branch_Long_Deco"
    },
    {
      "x": -14,
      "y": -17,
      "z": 8,
      "name": "Wood_Bamboo_Branch_Long_Deco"
    },
    {
      "x": -14,
      "y": -16,
      "z": 8,
      "name": "Wood_Bamboo_Branch_Long_Deco"
    },
    {
      "x": -14,
      "y": -15,
      "z": 8,
      "name": "Wood_Bamboo_Branch_Long_Deco"
    },
    {
      "x": -14,
      "y": -14,
      "z": 8,
      "name": "Wood_Bamboo_Branch_Long_Deco"
    },
    {
      "x": -14,
      "y": -13,
      "z": 8,
      "name": "Wood_Bamboo_Branch_Long_Deco"
    },
    {
      "x": -14,
      "y": -12,
      "z": 8,
      "name": "Wood_Bamboo_Branch_Long_Deco"
    },
    {
      "x": -14,
      "y": -11,
      "z": 8,
      "name": "Wood_Bamboo_Branch_Long_Deco"
    },
    {
      "x": -14,
      "y": -10,
      "z": 8,
      "name": "Wood_Bamboo_Branch_Long_Deco"
    },
    {
      "x": -14,
      "y": -9,
      "z": 8,
      "name": "Wood_Bamboo_Branch_Long_Deco"
    },
    {
      "x": -14,
      "y": -8,
      "z": 8,
      "name": "Wood_Bamboo_Branch_Long_Deco"
    },
    {
      "x": -14,
      "y": -7,
      "z": 8,
      "name": "Wood_Bamboo_Branch_Long_Deco"
    },
    {
      "x": -14,
      "y": -6,
      "z": 8,
      "name": "Wood_Bamboo_Branch_Long_Deco"
    },
    {
      "x": -14,
      "y": -5,
      "z": 8,
      "name": "Wood_Bamboo_Branch_Long_Deco"
    },
    {
      "x": -14,
      "y": -4,
      "z": 8,
      "name": "Wood_Bamboo_Trunk_Deco",
      "rotation": 5
    },
    {
      "x": -14,
      "y": -3,
      "z": 8,
      "name": "Wood_Bamboo_Branch_Long_Deco"
    },
    {
      "x": -14,
      "y": -2,
      "z": 8,
      "name": "Wood_Bamboo_Branch_Long_Deco"
    },
    {
      "x": -14,
      "y": -1,
      "z": 8,
      "name": "Wood_Bamboo_Branch_Long_Deco"
    },
    {
      "x": -14,
      "y": 0,
      "z": 8,
      "name": "Wood_Bamboo_Branch_Long_Deco"
    },
    {
      "x": -14,
      "y": 1,
      "z": 8,
      "name": "Wood_Bamboo_Trunk_Deco",
      "rotation": 5
    },
    {
      "x": -14,
      "y": 2,
      "z": 8,
      "name": "Wood_Bamboo_Trunk_Deco"
    },
    {
      "x": -14,
      "y": 3,
      "z": 8,
      "name": "Wood_Bamboo_Trunk_Deco"
    },
    {
      "x": -14,
      "y": 4,
      "z": 8,
      "name": "Wood_Bamboo_Trunk_Deco"
    },
    {
      "x": -14,
      "y": 5,
      "z": 8,
      "name": "Wood_Bamboo_Trunk_Deco"
    },
    {
      "x": -14,
      "y": 6,
      "z": 8,
      "name": "Wood_Bamboo_Trunk_Deco"
    },
    {
      "x": -14,
      "y": 7,
      "z": 8,
      "name": "Wood_Bamboo_Trunk_Deco"
    },
    {
      "x": -14,
      "y": 8,
      "z": 8,
      "name": "Wood_Bamboo_Trunk_Deco"
    },
    {
      "x": -14,
      "y": 9,
      "z": 8,
      "name": "Wood_Goldenwood_Planks"
    },
    {
      "x": -14,
      "y": 10,
      "z": 8,
      "name": "Plant_Vine_Jungle",
      "components": {
        "Components": {
          "FarmingBlock": {}
        }
      },
      "rotation": 2
    },
    {
      "x": -14,
      "y": 1,
      "z": 9,
      "name": "Wood_Bamboo_Branch_Long_Deco",
      "rotation": 4
    },
    {
      "x": -14,
      "y": 4,
      "z": 9,
      "name": "Wood_Bamboo_Trunk_Deco",
      "rotation": 5
    },
    {
      "x": -14,
      "y": 5,
      "z": 9,
      "name": "Wood_Goldenwood_Planks"
    },
    {
      "x": -14,
      "y": 6,
      "z": 9,
      "name": "Empty"
    },
    {
      "x": -14,
      "y": 7,
      "z": 9,
      "name": "Empty"
    },
    {
      "x": -14,
      "y": 8,
      "z": 9,
      "name": "Empty"
    },
    {
      "x": -14,
      "y": 9,
      "z": 9,
      "name": "Wood_Goldenwood_Planks"
    },
    {
      "x": -14,
      "y": 10,
      "z": 9,
      "name": "Wood_Goldenwood_Decorative"
    },
    {
      "x": -14,
      "y": 11,
      "z": 9,
      "name": "Plant_Moss_Rug_Green"
    },
    {
      "x": -14,
      "y": 12,
      "z": 9,
      "name": "Wood_Goldenwood_Planks_Half",
      "rotation": 8
    },
    {
      "x": -14,
      "y": 13,
      "z": 9,
      "name": "Wood_Goldenwood_Stairs",
      "rotation": 3
    },
    {
      "x": -14,
      "y": 1,
      "z": 10,
      "name": "Wood_Bamboo_Branch_Long_Deco",
      "rotation": 4
    },
    {
      "x": -14,
      "y": 4,
      "z": 10,
      "name": "Wood_Bamboo_Trunk_Deco",
      "rotation": 4
    },
    {
      "x": -14,
      "y": 5,
      "z": 10,
      "name": "Wood_Goldenwood_Planks"
    },
    {
      "x": -14,
      "y": 6,
      "z": 10,
      "name": "Empty"
    },
    {
      "x": -14,
      "y": 7,
      "z": 10,
      "name": "Empty"
    },
    {
      "x": -14,
      "y": 8,
      "z": 10,
      "name": "Empty"
    },
    {
      "x": -14,
      "y": 9,
      "z": 10,
      "name": "Empty"
    },
    {
      "x": -14,
      "y": 10,
      "z": 10,
      "name": "Wood_Goldenwood_Planks"
    },
    {
      "x": -14,
      "y": 11,
      "z": 10,
      "name": "Wood_Goldenwood_Planks"
    },
    {
      "x": -14,
      "y": 12,
      "z": 10,
      "name": "Wood_Greenwood_Planks"
    },
    {
      "x": -14,
      "y": 13,
      "z": 10,
      "name": "Soil_Clay_Ocean_Brick_Stairs",
      "rotation": 3
    },
    {
      "x": -14,
      "y": 1,
      "z": 11,
      "name": "Wood_Bamboo_Branch_Long_Deco",
