{
  "version": 8,
  "blockIdVersion": 11,
  "anchorX": 0,
  "anchorY": 0,
  "anchorZ": 9,
  "blocks": [
    {
      "x": -2,
      "y": -1,
      "z": 0,
      "name": "Soil_Grass"
    },
    {
      "x": -2,
      "y": -1,
      "z": 1,
      "name": "Soil_Grass"
    },
    {
      "x": -2,
      "y": -1,
      "z": 2,
      "name": "Soil_Grass"
    },
    {
      "x": -2,
      "y": 0,
      "z": 2,
      "name": "*Wood_Tropicalwood_Roof_Steep_State_Definitions_Corner_Left",
      "rotation": 2
    },
    {
      "x": -2,
      "y": 1,
      "z": 2,
      "name": "*Wood_Tropicalwood_Roof_Steep_State_Definitions_Corner_Left",
      "filler": 1024,
      "rotation": 2
    },
    {
      "x": -2,
      "y": -1,
      "z": 3,
      "name": "Soil_Grass"
    },
    {
      "x": -2,
      "y": 0,
      "z": 3,
      "name": "Wood_Tropicalwood_Roof_Steep",
      "rotation": 3
    },
    {
      "x": -2,
      "y": 1,
      "z": 3,
      "name": "Wood_Tropicalwood_Roof_Steep",
      "filler": 1024,
      "rotation": 3
    },
    {
      "x": -2,
      "y": -1,
      "z": 4,
      "name": "Soil_Grass"
    },
    {
      "x": -2,
      "y": 0,
      "z": 4,
      "name": "Wood_Tropicalwood_Roof_Steep",
      "rotation": 3
    },
    {
      "x": -2,
      "y": 1,
      "z": 4,
      "name": "Wood_Tropicalwood_Roof_Steep",
      "filler": 1024,
      "rotation": 3
    },
    {
      "x": -2,
      "y": -1,
      "z": 5,
      "name": "Soil_Grass"
    },
    {
      "x": -2,
      "y": 0,
      "z": 5,
      "name": "Wood_Tropicalwood_Roof_Steep",
      "rotation": 3
    },
    {
      "x": -2,
      "y": 1,
      "z": 5,
      "name": "Wood_Tropicalwood_Roof_Steep",
      "filler": 1024,
      "rotation": 3
    },
    {
      "x": -2,
      "y": -1,
      "z": 6,
      "name": "Soil_Grass"
    },
    {
      "x": -2,
      "y": 0,
      "z": 6,
      "name": "Wood_Tropicalwood_Roof_Steep",
      "rotation": 3
    },
    {
      "x": -2,
      "y": 1,
      "z": 6,
      "name": "Wood_Tropicalwood_Roof_Steep",
      "filler": 1024,
      "rotation": 3
    },
    {
      "x": -2,
      "y": -1,
      "z": 7,
      "name": "Soil_Grass"
    },
    {
      "x": -2,
      "y": 0,
      "z": 7,
      "name": "*Wood_Tropicalwood_Roof_Steep_State_Definitions_Corner_Right"
    },
    {
      "x": -2,
      "y": 1,
      "z": 7,
      "name": "*Wood_Tropicalwood_Roof_Steep_State_Definitions_Corner_Right",
      "filler": 1024
    },
    {
      "x": -2,
      "y": -1,
      "z": 8,
      "name": "Soil_Grass"
    },
    {
      "x": -2,
      "y": -1,
      "z": 9,
      "name": "Soil_Grass"
    },
    {
      "x": -2,
      "y": -1,
      "z": 10,
      "name": "Soil_Grass"
    },
    {
      "x": -2,
      "y": 0,
      "z": 10,
      "name": "Tinkering_Target_Dummy",
      "rotation": 1
    },
    {
      "x": -2,
      "y": 1,
      "z": 10,
      "name": "Tinkering_Target_Dummy",
      "filler": 1024,
      "rotation": 1
    },
    {
      "x": -1,
      "y": -1,
      "z": 0,
      "name": "Soil_Grass"
    },
    {
      "x": -1,
      "y": 0,
      "z": 0,
      "name": "Furniture_Crude_Brazier"
    },
    {
      "x": -1,
      "y": 1,
      "z": 0,
      "name": "Empty"
    },
    {
      "x": -1,
      "y": -1,
      "z": 1,
      "name": "Soil_Grass"
    },
    {
      "x": -1,
      "y": 0,
      "z": 1,
      "name": "Empty"
    },
    {
      "x": -1,
      "y": 1,
      "z": 1,
      "name": "Empty"
    },
    {
      "x": -1,
      "y": -1,
      "z": 2,
      "name": "Soil_Grass"
    },
    {
      "x": -1,
      "y": 0,
      "z": 2,
      "name": "Empty"
    },
    {
      "x": -1,
      "y": 1,
      "z": 2,
      "name": "Empty"
    },
    {
      "x": -1,
      "y": -1,
      "z": 3,
      "name": "Soil_Dirt"
    },
    {
      "x": -1,
      "y": 0,
      "z": 3,
      "name": "Wood_Greenwood_Beam"
    },
    {
      "x": -1,
      "y": 1,
      "z": 3,
      "name": "Wood_Greenwood_Beam"
    },
    {
      "x": -1,
      "y": 2,
      "z": 3,
      "name": "*Wood_Tropicalwood_Roof_State_Definitions_Corner_Left",
      "rotation": 2
    },
    {
      "x": -1,
      "y": -1,
      "z": 4,
      "name": "Soil_Dirt"
    },
    {
      "x": -1,
      "y": 0,
      "z": 4,
      "name": "Alchemy_Cauldron",
      "rotation": 1
    },
    {
      "x": -1,
      "y": 1,
      "z": 4,
      "name": "Empty"
    },
    {
      "x": -1,
      "y": 2,
      "z": 4,
      "name": "Wood_Tropicalwood_Roof_Hollow",
      "rotation": 3
    },
    {
      "x": -1,
      "y": -1,
      "z": 5,
      "name": "Soil_Dirt"
    },
    {
      "x": -1,
      "y": 0,
      "z": 5,
      "name": "Deco_Bucket"
    },
    {
      "x": -1,
      "y": 1,
      "z": 5,
      "name": "Empty"
    },
    {
      "x": -1,
      "y": 2,
      "z": 5,
      "name": "Wood_Tropicalwood_Roof_Hollow",
      "rotation": 3
    },
    {
      "x": -1,
      "y": -1,
      "z": 6,
      "name": "Soil_Dirt"
    },
    {
      "x": -1,
      "y": 0,
      "z": 6,
      "name": "Wood_Greenwood_Beam"
    },
    {
      "x": -1,
      "y": 1,
      "z": 6,
      "name": "Wood_Greenwood_Beam"
    },
    {
      "x": -1,
      "y": 2,
      "z": 6,
      "name": "*Wood_Tropicalwood_Roof_State_Definitions_Corner_Right"
    },
    {
      "x": -1,
      "y": -1,
      "z": 7,
      "name": "Soil_Dirt"
    },
    {
      "x": -1,
      "y": 0,
      "z": 7,
      "name": "Empty"
    },
    {
      "x": -1,
      "y": 1,
      "z": 7,
      "name": "Empty"
    },
    {
      "x": -1,
      "y": -1,
      "z": 8,
      "name": "Soil_Dirt"
    },
    {
      "x": -1,
      "y": -1,
      "z": 9,
      "name": "Soil_Dirt"
    },
    {
      "x": -1,
      "y": -1,
      "z": 10,
      "name": "Soil_Dirt"
    },
    {
      "x": 0,
      "y": -1,
      "z": 0,
      "name": "Soil_Grass"
    },
    {
      "x": 0,
      "y": 0,
      "z": 0,
      "name": "Empty"
    },
    {
      "x": 0,
      "y": -1,
      "z": 1,
      "name": "Soil_Dirt"
    },
    {
      "x": 0,
      "y": 0,
      "z": 1,
      "name": "Empty"
    },
    {
      "x": 0,
      "y": 1,
      "z": 1,
      "name": "Empty"
    },
    {
      "x": 0,
      "y": -1,
      "z": 2,
      "name": "Soil_Dirt"
    },
    {
      "x": 0,
      "y": 0,
      "z": 2,
      "name": "Empty"
    },
    {
      "x": 0,
      "y": -1,
      "z": 3,
      "name": "Soil_Dirt"
    },
    {
      "x": 0,
      "y": 0,
      "z": 3,
      "name": "Empty"
    },
    {
      "x": 0,
      "y": 1,
      "z": 3,
      "name": "Empty"
    },
    {
      "x": 0,
      "y": 2,
      "z": 3,
      "name": "Wood_Tropicalwood_Roof_Hollow",
      "rotation": 2
    },
    {
      "x": 0,
      "y": -1,
      "z": 4,
      "name": "Soil_Dirt"
    },
    {
      "x": 0,
      "y": 0,
      "z": 4,
      "name": "Empty"
    },
    {
      "x": 0,
      "y": 1,
      "z": 4,
      "name": "Empty"
    },
    {
      "x": 0,
      "y": 3,
      "z": 4,
      "name": "Wood_Tropicalwood_Roof_Flat"
    },
    {
      "x": 0,
      "y": -1,
      "z": 5,
      "name": "Soil_Dirt"
    },
    {
      "x": 0,
      "y": 0,
      "z": 5,
      "name": "Empty"
    },
    {
      "x": 0,
      "y": 3,
      "z": 5,
      "name": "Wood_Tropicalwood_Roof_Flat"
    },
    {
      "x": 0,
      "y": -1,
      "z": 6,
      "name": "Soil_Dirt"
    },
    {
      "x": 0,
      "y": 0,
      "z": 6,
      "name": "Empty"
    },
    {
      "x": 0,
      "y": 1,
      "z": 6,
      "name": "Empty"
    },
    {
      "x": 0,
      "y": 2,
      "z": 6,
      "name": "Wood_Tropicalwood_Roof_Hollow"
    },
    {
      "x": 0,
      "y": -1,
      "z": 7,
      "name": "Soil_Dirt"
    },
    {
      "x": 0,
      "y": 0,
      "z": 7,
      "name": "Empty"
    },
    {
      "x": 0,
      "y": 1,
      "z": 7,
      "name": "Empty"
    },
    {
      "x": 0,
      "y": -1,
      "z": 8,
      "name": "Soil_Dirt"
    },
    {
      "x": 0,
      "y": -1,
      "z": 9,
      "name": "Soil_Dirt"
    },
    {
      "x": 0,
      "y": -1,
      "z": 10,
      "name": "Soil_Grass"
    },
    {
      "x": 1,
      "y": -1,
      "z": 0,
      "name": "Soil_Dirt"
    },
    {
      "x": 1,
      "y": 0,
      "z": 0,
      "name": "Empty"
    },
    {
      "x": 1,
      "y": 1,
      "z": 0,
      "name": "Empty"
    },
    {
      "x": 1,
      "y": -1,
      "z": 1,
      "name": "Soil_Dirt"
    },
    {
      "x": 1,
      "y": 0,
      "z": 1,
      "name": "Empty"
    },
    {
      "x": 1,
      "y": 1,
      "z": 1,
      "name": "Empty"
    },
    {
      "x": 1,
      "y": -1,
      "z": 2,
      "name": "Soil_Grass"
    },
    {
      "x": 1,
      "y": 0,
      "z": 2,
      "name": "Empty"
    },
    {
      "x": 1,
      "y": 1,
      "z": 2,
      "name": "Empty"
    },
    {
      "x": 1,
      "y": -1,
      "z": 3,
      "name": "Soil_Dirt"
    },
    {
      "x": 1,
      "y": 0,
      "z": 3,
      "name": "Wood_Greenwood_Beam"
    },
    {
      "x": 1,
      "y": 1,
      "z": 3,
      "name": "Wood_Greenwood_Beam"
    },
    {
      "x": 1,
      "y": 2,
      "z": 3,
      "name": "*Wood_Tropicalwood_Roof_State_Definitions_Corner_Right",
      "rotation": 2
    },
    {
      "x": 1,
      "y": -1,
      "z": 4,
      "name": "Soil_Dirt"
    },
    {
      "x": 1,
      "y": 0,
      "z": 4,
      "name": "Deco_Iron_Stack",
      "support": 15
    },
    {
      "x": 1,
      "y": 1,
      "z": 4,
      "name": "Empty"
    },
    {
      "x": 1,
      "y": 2,
      "z": 4,
      "name": "Wood_Tropicalwood_Roof_Hollow",
      "rotation": 1
    },
    {
      "x": 1,
      "y": -1,
      "z": 5,
      "name": "Soil_Dirt"
    },
    {
      "x": 1,
      "y": 0,
      "z": 5,
      "name": "Deco_Iron_Stack",
      "support": 15,
      "rotation": 1
    },
    {
      "x": 1,
      "y": 1,
      "z": 5,
      "name": "Empty"
    },
    {
      "x": 1,
      "y": 2,
      "z": 5,
      "name": "Wood_Tropicalwood_Roof_Hollow",
      "rotation": 1
    },
    {
      "x": 1,
      "y": -1,
      "z": 6,
      "name": "Soil_Dirt"
    },
    {
      "x": 1,
      "y": 0,
      "z": 6,
      "name": "Wood_Greenwood_Beam"
    },
    {
      "x": 1,
      "y": 1,
      "z": 6,
      "name": "Wood_Greenwood_Beam"
    },
    {
      "x": 1,
      "y": 2,
      "z": 6,
      "name": "*Wood_Tropicalwood_Roof_State_Definitions_Corner_Left"
    },
    {
      "x": 1,
      "y": -1,
      "z": 7,
      "name": "Soil_Dirt"
    },
    {
      "x": 1,
      "y": 0,
      "z": 7,
      "name": "Empty"
    },
    {
      "x": 1,
      "y": 1,
      "z": 7,
      "name": "Empty"
    },
    {
      "x": 1,
      "y": -1,
      "z": 8,
      "name": "Soil_Grass"
    },
    {
      "x": 1,
      "y": -1,
      "z": 9,
      "name": "Soil_Grass"
    },
    {
      "x": 1,
      "y": -1,
      "z": 10,
      "name": "Soil_Grass"
    },
    {
      "x": 2,
      "y": -1,
      "z": 0,
      "name": "Soil_Grass"
    },
    {
      "x": 2,
      "y": -1,
      "z": 1,
      "name": "Soil_Grass"
    },
    {
      "x": 2,
      "y": -1,
      "z": 2,
      "name": "Soil_Grass"
    },
    {
      "x": 2,
      "y": 0,
      "z": 2,
      "name": "*Wood_Tropicalwood_Roof_Steep_State_Definitions_Corner_Right",
      "rotation": 2
    },
    {
      "x": 2,
      "y": 1,
      "z": 2,
      "name": "*Wood_Tropicalwood_Roof_Steep_State_Definitions_Corner_Right",
      "filler": 1024,
      "rotation": 2
    },
    {
      "x": 2,
      "y": -1,
      "z": 3,
      "name": "Soil_Grass"
    },
    {
      "x": 2,
      "y": 0,
      "z": 3,
      "name": "Wood_Tropicalwood_Roof_Steep",
      "rotation": 1
    },
    {
      "x": 2,
      "y": 1,
      "z": 3,
      "name": "Wood_Tropicalwood_Roof_Steep",
      "filler": 1024,
      "rotation": 1
    },
    {
      "x": 2,
      "y": -1,
      "z": 4,
      "name": "Soil_Grass"
    },
    {
      "x": 2,
      "y": 0,
      "z": 4,
      "name": "Wood_Tropicalwood_Roof_Steep",
      "rotation": 1
    },
    {
      "x": 2,
      "y": 1,
      "z": 4,
      "name": "Wood_Tropicalwood_Roof_Steep",
      "filler": 1024,
      "rotation": 1
    },
    {
      "x": 2,
      "y": -1,
      "z": 5,
      "name": "Soil_Grass"
    },
    {
      "x": 2,
      "y": 0,
      "z": 5,
      "name": "Wood_Tropicalwood_Roof_Steep",
      "rotation": 1
    },
    {
      "x": 2,
      "y": 1,
      "z": 5,
      "name": "Wood_Tropicalwood_Roof_Steep",
      "filler": 1024,
      "rotation": 1
    },
    {
      "x": 2,
      "y": -1,
      "z": 6,
      "name": "Soil_Grass"
    },
    {
      "x": 2,
      "y": 0,
      "z": 6,
      "name": "Wood_Tropicalwood_Roof_Steep",
      "rotation": 1
    },
    {
      "x": 2,
      "y": 1,
      "z": 6,
      "name": "Wood_Tropicalwood_Roof_Steep",
      "filler": 1024,
      "rotation": 1
    },
    {
      "x": 2,
      "y": -1,
      "z": 7,
      "name": "Soil_Grass"
    },
    {
      "x": 2,
      "y": 0,
      "z": 7,
      "name": "*Wood_Tropicalwood_Roof_Steep_State_Definitions_Corner_Left"
    },
    {
      "x": 2,
      "y": 1,
      "z": 7,
      "name": "*Wood_Tropicalwood_Roof_Steep_State_Definitions_Corner_Left",
      "filler": 1024
    },
    {
      "x": 2,
      "y": -1,
      "z": 8,
      "name": "Soil_Grass"
    },
    {
      "x": 2,
      "y": -1,
      "z": 9,
      "name": "Soil_Grass"
    },
    {
      "x": 2,
      "y": -1,
      "z": 10,
      "name": "Soil_Grass"
    }
  ],
  "entities": [
    {
      "Components": {
        "Prop": {},
        "Model": {
          "Model": {
            "Id": "Slothian_Villager",
            "Scale": 1.0,
            "Static": true
          }
        },
        "Transform": {
          "Position": {
            "X": -0.253781795501709,
            "Y": 0.056758880615234375,
            "Z": 1.8252595663070679
          },
          "Rotation": {
            "Pitch": 0.0,
            "Yaw": -6.864587783813477,
            "Roll": 0.0
          }
        },
        "UUID": {
          "UUID": {
            "$binary": "2nDhxBm5Mt2AVgwaYcvuZA==",
            "$type": "04"
          }
        },
        "PrefabCopyable": {},
        "HeadRotation": {
          "Rotation": {
            "Pitch": 0.0,
            "Yaw": -6.864586353302002,
            "Roll": 0.0
          }
        }
      }
    }
  ]
}