{
  "version": 8,
  "blockIdVersion": 11,
  "anchorX": 0,
  "anchorY": 0,
  "anchorZ": 0,
  "blocks": [
    {
      "x": -3,
      "y": 0,
      "z": -1,
      "name": "Rock_Stone"
    },
    {
      "x": -3,
      "y": 1,
      "z": -1,
      "name": "Rock_Stone"
    },
    {
      "x": -3,
      "y": 2,
      "z": -1,
      "name": "Rock_Stone"
    },
    {
      "x": -3,
      "y": 3,
      "z": -1,
      "name": "Soil_Grass"
    },
    {
      "x": -3,
      "y": 4,
      "z": -1,
      "name": "Plant_Moss_Rug_Green_Dark",
      "support": 15
    },
    {
      "x": -3,
      "y": 0,
      "z": 0,
      "name": "Rock_Stone"
    },
    {
      "x": -3,
      "y": 1,
      "z": 0,
      "name": "Rock_Stone"
    },
    {
      "x": -3,
      "y": 2,
      "z": 0,
      "name": "Rock_Stone"
    },
    {
      "x": -3,
      "y": 3,
      "z": 0,
      "name": "Soil_Grass"
    },
    {
      "x": -3,
      "y": 0,
      "z": 1,
      "name": "Rock_Stone"
    },
    {
      "x": -3,
      "y": 1,
      "z": 1,
      "name": "Rock_Stone"
    },
    {
      "x": -3,
      "y": 2,
      "z": 1,
      "name": "Rock_Stone"
    },
    {
      "x": -3,
      "y": 3,
      "z": 1,
      "name": "Plant_Moss_Rug_Green_Dark",
      "support": 15
    },
    {
      "x": -2,
      "y": 0,
      "z": -1,
      "name": "Rock_Stone"
    },
    {
      "x": -2,
      "y": 1,
      "z": -1,
      "name": "Rock_Stone"
    },
    {
      "x": -2,
      "y": 2,
      "z": -1,
      "name": "Rock_Stone"
    },
    {
      "x": -2,
      "y": 3,
      "z": -1,
      "name": "Soil_Grass"
    },
    {
      "x": -2,
      "y": 4,
      "z": -1,
      "name": "Plant_Crop_Mana1"
    },
    {
      "x": -2,
      "y": 0,
      "z": 0,
      "name": "Rock_Stone"
    },
    {
      "x": -2,
      "y": 1,
      "z": 0,
      "name": "Rock_Stone"
    },
    {
      "x": -2,
      "y": 2,
      "z": 0,
      "name": "Rock_Stone"
    },
    {
      "x": -2,
      "y": 3,
      "z": 0,
      "name": "Soil_Grass"
    },
    {
      "x": -2,
      "y": 0,
      "z": 1,
      "name": "Rock_Stone"
    },
    {
      "x": -2,
      "y": 1,
      "z": 1,
      "name": "Rock_Stone"
    },
    {
      "x": -2,
      "y": 2,
      "z": 1,
      "name": "Soil_Grass"
    },
    {
      "x": -2,
      "y": 0,
      "z": 2,
      "name": "Rock_Stone"
    },
    {
      "x": -2,
      "y": 1,
      "z": 2,
      "name": "Plant_Moss_Rug_Green_Dark",
      "support": 15
    },
    {
      "x": -1,
      "y": 0,
      "z": 0,
      "name": "Rock_Stone"
    },
    {
      "x": -1,
      "y": 1,
      "z": 0,
      "name": "Rock_Stone"
    },
    {
      "x": -1,
      "y": 2,
      "z": 0,
      "name": "Plant_Moss_Rug_Green_Dark",
      "support": 15
    },
    {
      "x": -1,
      "y": 0,
      "z": 1,
      "name": "Rock_Stone"
    },
    {
      "x": -1,
      "y": 1,
      "z": 1,
      "name": "Soil_Grass"
    },
    {
      "x": -1,
      "y": 2,
      "z": 1,
      "name": "Plant_Crop_Mana2"
    },
    {
      "x": -1,
      "y": 0,
      "z": 2,
      "name": "Rock_Stone"
    },
    {
      "x": 0,
      "y": 0,
      "z": 1,
      "name": "Rock_Stone"
    },
    {
      "x": 0,
      "y": 0,
      "z": 2,
      "name": "Rock_Stone"
    },
    {
      "x": 0,
      "y": 1,
      "z": 2,
      "name": "Plant_Moss_Rug_Green_Dark",
      "support": 15
    }
  ]
}